Workbook
Name Departements: établissements!$B$8:$B$103
Name ListeDepartements: établissements!$A$8:$B$103

Sheet Sommaire
A5: EQUIPEMENT ET RESULTATS DES DEPARTEMENTS
A8: Mis à jour le 22 septembre 2025
B10: Définitions et sources
B11: Fiche récapitulative
A13: Ensemble du parc
B14: Etablissements
B15: Ecrans
B16: Fauteuils
B17: Multiplexes (établissements de 8 écrans et plus)
B18: Séances
B19: Entrées
B20: Recettes
B21: Recette moyenne par entrée
B22: Indice de fréquentation
B23: Taux moyen d'occupation des fauteuils
A25: Etablissements Art et Essai
B26: Etablissements
B27: Ecrans
B28: Fauteuils
B29: Séances
B30: Entrées
B31: Recettes
B32: Recette moyenne par entrée
B33: Indice de fréquentation
B34: Taux moyen d'occupation des fauteuils
A36: Etablissements de la petite exploitation
B37: Etablissements
B38: Ecrans
B39: Fauteuils
B40: Séances
B41: Entrées
B42: Recettes
B43: Recette moyenne par entrée
B44: Indice de fréquentation
B45: Taux moyen d'occupation des fauteuils
A47: Etablissements de la moyenne exploitation
B48: Etablissements
B49: Ecrans
B50: Fauteuils
B51: Séances
...

Sheet Définitions
A2: Retour au menu "Départements"
A5: Réglementation
A24: Définitions
A40: Sources

Sheet Fiche
A2: Retour au menu "Départements"
A5: Rechercher le département dans la liste suivante | E5: AIN
A8: DEPARTEMENT | B8: =E5 -> AIN
A10: Résultats totaux
B11: 2 | C11: 3 | D11: 4 | E11: 5 | F11: 6 | G11: 7 | H11: 8 | I11: 9 | J11: 10 | K11: 11 | L11: 12 | M11: 13 | N11: 14 | O11: 15 | P11: 16 | Q11: 17 | R11: 18 | S11: 19 | T11: 20 | U11: 21 | V11: 22 | W11: 23 | X11: 24 | Y11: 25 | Z11: 26 | AA11: 27
B12: 1966 | C12: 1967 | D12: 1968 | E12: 1969 | F12: 1970 | G12: 1971 | H12: 1972 | I12: 1973 | J12: 1974 | K12: 1975 | L12: 1976 | M12: 1977 | N12: 1978 | O12: 1979 | P12: 1980 | Q12: 1981 | R12: 1982 | S12: 1983 | T12: 1984 | U12: 1985 | V12: 1986 | W12: 1987 | X12: 1988 | Y12: 1989 | Z12: 1990 | AA12: 1991
A13: écrans | B13: =IF(VLOOKUP($B$8,écrans!$B:$DE,B$11,0)=0,"-",VLOOKUP($B$8,écrans!$B:$DE,B$11,0)) -> 35 | C13: =IF(VLOOKUP($B$8,écrans!$B:$DE,C$11,0)=0,"-",VLOOKUP($B$8,écrans!$B:$DE,C$11,0)) -> 34 | D13: =IF(VLOOKUP($B$8,écrans!$B:$DE,D$11,0)=0,"-",VLOOKUP($B$8,écrans!$B:$DE,D$11,0)) -> 33 | E13: =IF(VLOOKUP($B$8,écrans!$B:$DE,E$11,0)=0,"-",VLOOKUP($B$8,écrans!$B:$DE,E$11,0)) -> 32 | F13: =IF(VLOOKUP($B$8,écrans!$B:$DE,F$11,0)=0,"-",VLOOKUP($B$8,écrans!$B:$DE,F$11,0)) -> 28 | G13: =IF(VLOOKUP($B$8,écrans!$B:$DE,G$11,0)=0,"-",VLOOKUP($B$8,écrans!$B:$DE,G$11,0)) -> 27 | H13: =IF(VLOOKUP($B$8,écrans!$B:$DE,H$11,0)=0,"-",VLOOKUP($B$8,écrans!$B:$DE,H$11,0)) -> 26 | I13: =IF(VLOOKUP($B$8,écrans!$B:$DE,I$11,0)=0,"-",VLOOKUP($B$8,écrans!$B:$DE,I$11,0)) -> 25 | ... AA13: =IF(VLOOKUP($B$8,écrans!$B:$DE,AA$11,0)=0,"-",VLOOKUP($B$8,écrans!$B:$DE,AA$11,0)) -> 37
A14: fauteuils | B14: =IF(VLOOKUP($B$8,fauteuils!$B:$DF,B$11,0)=0,"-",VLOOKUP($B$8,fauteuils!$B:$DF,B$11,0)) -> 12962 | C14: =IF(VLOOKUP($B$8,fauteuils!$B:$DF,C$11,0)=0,"-",VLOOKUP($B$8,fauteuils!$B:$DF,C$11,0)) -> 12754 | D14: =IF(VLOOKUP($B$8,fauteuils!$B:$DF,D$11,0)=0,"-",VLOOKUP($B$8,fauteuils!$B:$DF,D$11,0)) -> 12256 | E14: =IF(VLOOKUP($B$8,fauteuils!$B:$DF,E$11,0)=0,"-",VLOOKUP($B$8,fauteuils!$B:$DF,E$11,0)) -> 11677 | F14: =IF(VLOOKUP($B$8,fauteuils!$B:$DF,F$11,0)=0,"-",VLOOKUP($B$8,fauteuils!$B:$DF,F$11,0)) -> 10703 | G14: =IF(VLOOKUP($B$8,fauteuils!$B:$DF,G$11,0)=0,"-",VLOOKUP($B$8,fauteuils!$B:$DF,G$11,0)) -> 10313 | H14: =IF(VLOOKUP($B$8,fauteuils!$B:$DF,H$11,0)=0,"-",VLOOKUP($B$8,fauteuils!$B:$DF,H$11,0)) -> 9913 | I14: =IF(VLOOKUP($B$8,fauteuils!$B:$DF,I$11,0)=0,"-",VLOOKUP($B$8,fauteuils!$B:$DF,I$11,0)) -> 9631 | ... AA14: =IF(VLOOKUP($B$8,fauteuils!$B:$DF,AA$11,0)=0,"-",VLOOKUP($B$8,fauteuils!$B:$DF,AA$11,0)) -> 7331
A15: entrées (millions) | B15: =IF(VLOOKUP($B$8,entrées!$B:$DE,B$11,0)=0,"-",VLOOKUP($B$8,entrées!$B:$DE,B$11,0)) -> 802733 | C15: =IF(VLOOKUP($B$8,entrées!$B:$DE,C$11,0)=0,"-",VLOOKUP($B$8,entrées!$B:$DE,C$11,0)) -> 731594 | D15: =IF(VLOOKUP($B$8,entrées!$B:$DE,D$11,0)=0,"-",VLOOKUP($B$8,entrées!$B:$DE,D$11,0)) -> 711298 | E15: =IF(VLOOKUP($B$8,entrées!$B:$DE,E$11,0)=0,"-",VLOOKUP($B$8,entrées!$B:$DE,E$11,0)) -> 617923 | F15: =IF(VLOOKUP($B$8,entrées!$B:$DE,F$11,0)=0,"-",VLOOKUP($B$8,entrées!$B:$DE,F$11,0)) -> 632750 | G15: =IF(VLOOKUP($B$8,entrées!$B:$DE,G$11,0)=0,"-",VLOOKUP($B$8,entrées!$B:$DE,G$11,0)) -> 598529 | H15: =IF(VLOOKUP($B$8,entrées!$B:$DE,H$11,0)=0,"-",VLOOKUP($B$8,entrées!$B:$DE,H$11,0)) -> 614866 | I15: =IF(VLOOKUP($B$8,entrées!$B:$DE,I$11,0)=0,"-",VLOOKUP($B$8,entrées!$B:$DE,I$11,0)) -> 557997 | ... AA15: =IF(VLOOKUP($B$8,entrées!$B:$DE,AA$11,0)=0,"-",VLOOKUP($B$8,entrées!$B:$DE,AA$11,0)) -> 623640.93
A16: recettes (M€) | B16: =IF(VLOOKUP($B$8,recettes!$B:$DE,B$11,0)=0,"-",VLOOKUP($B$8,recettes!$B:$DE,B$11,0)) -> 313857.77 | C16: =IF(VLOOKUP($B$8,recettes!$B:$DE,C$11,0)=0,"-",VLOOKUP($B$8,recettes!$B:$DE,C$11,0)) -> 314581.75 | D16: =IF(VLOOKUP($B$8,recettes!$B:$DE,D$11,0)=0,"-",VLOOKUP($B$8,recettes!$B:$DE,D$11,0)) -> 331288.03 | E16: =IF(VLOOKUP($B$8,recettes!$B:$DE,E$11,0)=0,"-",VLOOKUP($B$8,recettes!$B:$DE,E$11,0)) -> 326184.34 | F16: =IF(VLOOKUP($B$8,recettes!$B:$DE,F$11,0)=0,"-",VLOOKUP($B$8,recettes!$B:$DE,F$11,0)) -> 354021.53 | G16: =IF(VLOOKUP($B$8,recettes!$B:$DE,G$11,0)=0,"-",VLOOKUP($B$8,recettes!$B:$DE,G$11,0)) -> 366313.49 | H16: =IF(VLOOKUP($B$8,recettes!$B:$DE,H$11,0)=0,"-",VLOOKUP($B$8,recettes!$B:$DE,H$11,0)) -> 421091.02 | I16: =IF(VLOOKUP($B$8,recettes!$B:$DE,I$11,0)=0,"-",VLOOKUP($B$8,recettes!$B:$DE,I$11,0)) -> 465940.76 | ... AA16: =IF(VLOOKUP($B$8,recettes!$B:$DE,AA$11,0)=0,"-",VLOOKUP($B$8,recettes!$B:$DE,AA$11,0)) -> 2821877.9
A17: RME (€) | B17: =IF(VLOOKUP($B$8,RME!$B:$DE,B$11,0)=0,"-",VLOOKUP($B$8,RME!$B:$DE,B$11,0)) -> 0.3909865 | C17: =IF(VLOOKUP($B$8,RME!$B:$DE,C$11,0)=0,"-",VLOOKUP($B$8,RME!$B:$DE,C$11,0)) -> 0.42999498 | D17: =IF(VLOOKUP($B$8,RME!$B:$DE,D$11,0)=0,"-",VLOOKUP($B$8,RME!$B:$DE,D$11,0)) -> 0.46575138 | E17: =IF(VLOOKUP($B$8,RME!$B:$DE,E$11,0)=0,"-",VLOOKUP($B$8,RME!$B:$DE,E$11,0)) -> 0.52787214 | F17: =IF(VLOOKUP($B$8,RME!$B:$DE,F$11,0)=0,"-",VLOOKUP($B$8,RME!$B:$DE,F$11,0)) -> 0.55949669 | G17: =IF(VLOOKUP($B$8,RME!$B:$DE,G$11,0)=0,"-",VLOOKUP($B$8,RME!$B:$DE,G$11,0)) -> 0.61202296 | H17: =IF(VLOOKUP($B$8,RME!$B:$DE,H$11,0)=0,"-",VLOOKUP($B$8,RME!$B:$DE,H$11,0)) -> 0.68485006 | I17: =IF(VLOOKUP($B$8,RME!$B:$DE,I$11,0)=0,"-",VLOOKUP($B$8,RME!$B:$DE,I$11,0)) -> 0.83502376 | ... AA17: =IF(VLOOKUP($B$8,RME!$B:$DE,AA$11,0)=0,"-",VLOOKUP($B$8,RME!$B:$DE,AA$11,0)) -> 4.5248441
A18: indice de fréquentation | B18: =IF(VLOOKUP($B$8,'indice de fréquentation'!$B:$DE,B$11,0)=0,"-",VLOOKUP($B$8,'indice de fréquentation'!$B:$DE,B$11,0)) -> 2.3661153 | C18: =IF(VLOOKUP($B$8,'indice de fréquentation'!$B:$DE,C$11,0)=0,"-",VLOOKUP($B$8,'indice de fréquentation'!$B:$DE,C$11,0)) -> 2.1564278 | D18: =IF(VLOOKUP($B$8,'indice de fréquentation'!$B:$DE,D$11,0)=0,"-",VLOOKUP($B$8,'indice de fréquentation'!$B:$DE,D$11,0)) -> 2.0966038 | E18: =IF(VLOOKUP($B$8,'indice de fréquentation'!$B:$DE,E$11,0)=0,"-",VLOOKUP($B$8,'indice de fréquentation'!$B:$DE,E$11,0)) -> 1.821374 | F18: =IF(VLOOKUP($B$8,'indice de fréquentation'!$B:$DE,F$11,0)=0,"-",VLOOKUP($B$8,'indice de fréquentation'!$B:$DE,F$11,0)) -> 1.8650777 | G18: =IF(VLOOKUP($B$8,'indice de fréquentation'!$B:$DE,G$11,0)=0,"-",VLOOKUP($B$8,'indice de fréquentation'!$B:$DE,G$11,0)) -> 1.7642088 | H18: =IF(VLOOKUP($B$8,'indice de fréquentation'!$B:$DE,H$11,0)=0,"-",VLOOKUP($B$8,'indice de fréquentation'!$B:$DE,H$11,0)) -> 1.63321 | I18: =IF(VLOOKUP($B$8,'indice de fréquentation'!$B:$DE,I$11,0)=0,"-",VLOOKUP($B$8,'indice de fréquentation'!$B:$DE,I$11,0)) -> 1.4821543 | ... AA18: =IF(VLOOKUP($B$8,'indice de fréquentation'!$B:$DE,AA$11,0)=0,"-",VLOOKUP($B$8,'indice de fréquentation'!$B:$DE,AA$11,0)) -> 1.324025
B19: 28 | C19: 29 | D19: 30 | E19: 31 | F19: 32 | G19: 33 | H19: 34 | I19: 35 | J19: 36 | K19: 37 | L19: 38 | M19: 39 | N19: 40 | O19: 41 | P19: 42 | Q19: 43 | R19: 44 | S19: 45 | T19: 46 | U19: 47 | V19: 48 | W19: 49 | X19: 50 | Y19: 51 | Z19: 52 | AA19: 53 | AB19: 54 | AC19: 55 | AD19: 56 | AE19: 57 | AF19: 58 | AG19: 59 | AH19: 60
B20: 1992 | C20: 1993 | D20: 1994 | E20: 1995 | F20: 1996 | G20: 1997 | H20: 1998 | I20: 1999 | J20: 2000 | K20: 2001 | L20: 2002 | M20: 2003 | N20: 2004 | O20: 2005 | P20: 2006 | Q20: 2007 | R20: 2008 | S20: 2009 | T20: 2010 | U20: 2011 | V20: 2012 | W20: 2013 | X20: 2014 | Y20: 2015 | Z20: 2016 | AA20: 2017 | AB20: 2018 | AC20: 2019 | AD20: 2020 | AE20: 2021 | AF20: 2022 | AG20: 2023 | AH20: 2024
A21: établissements | B21: =IF(VLOOKUP($B$8,établissements!$B:$DE,B$19,0)=0,"-",VLOOKUP($B$8,établissements!$B:$DE,B$19,0)) -> 20 | C21: =IF(VLOOKUP($B$8,établissements!$B:$DE,C$19,0)=0,"-",VLOOKUP($B$8,établissements!$B:$DE,C$19,0)) -> 19 | D21: =IF(VLOOKUP($B$8,établissements!$B:$DE,D$19,0)=0,"-",VLOOKUP($B$8,établissements!$B:$DE,D$19,0)) -> 17 | E21: =IF(VLOOKUP($B$8,établissements!$B:$DE,E$19,0)=0,"-",VLOOKUP($B$8,établissements!$B:$DE,E$19,0)) -> 18 | F21: =IF(VLOOKUP($B$8,établissements!$B:$DE,F$19,0)=0,"-",VLOOKUP($B$8,établissements!$B:$DE,F$19,0)) -> 19 | G21: =IF(VLOOKUP($B$8,établissements!$B:$DE,G$19,0)=0,"-",VLOOKUP($B$8,établissements!$B:$DE,G$19,0)) -> 19 | H21: =IF(VLOOKUP($B$8,établissements!$B:$DE,H$19,0)=0,"-",VLOOKUP($B$8,établissements!$B:$DE,H$19,0)) -> 19 | I21: =IF(VLOOKUP($B$8,établissements!$B:$DE,I$19,0)=0,"-",VLOOKUP($B$8,établissements!$B:$DE,I$19,0)) -> 21 | ... AH21: =IF(VLOOKUP($B$8,établissements!$B:$DE,AH$19,0)=0,"-",VLOOKUP($B$8,établissements!$B:$DE,AH$19,0)) -> 20
A22: écrans | B22: =IF(VLOOKUP($B$8,écrans!$B:$DE,B$19,0)=0,"-",VLOOKUP($B$8,écrans!$B:$DE,B$19,0)) -> 36 | C22: =IF(VLOOKUP($B$8,écrans!$B:$DE,C$19,0)=0,"-",VLOOKUP($B$8,écrans!$B:$DE,C$19,0)) -> 35 | D22: =IF(VLOOKUP($B$8,écrans!$B:$DE,D$19,0)=0,"-",VLOOKUP($B$8,écrans!$B:$DE,D$19,0)) -> 33 | E22: =IF(VLOOKUP($B$8,écrans!$B:$DE,E$19,0)=0,"-",VLOOKUP($B$8,écrans!$B:$DE,E$19,0)) -> 34 | F22: =IF(VLOOKUP($B$8,écrans!$B:$DE,F$19,0)=0,"-",VLOOKUP($B$8,écrans!$B:$DE,F$19,0)) -> 35 | G22: =IF(VLOOKUP($B$8,écrans!$B:$DE,G$19,0)=0,"-",VLOOKUP($B$8,écrans!$B:$DE,G$19,0)) -> 35 | H22: =IF(VLOOKUP($B$8,écrans!$B:$DE,H$19,0)=0,"-",VLOOKUP($B$8,écrans!$B:$DE,H$19,0)) -> 35 | I22: =IF(VLOOKUP($B$8,écrans!$B:$DE,I$19,0)=0,"-",VLOOKUP($B$8,écrans!$B:$DE,I$19,0)) -> 39 | ... AH22: =IF(VLOOKUP($B$8,écrans!$B:$DE,AH$19,0)=0,"-",VLOOKUP($B$8,écrans!$B:$DE,AH$19,0)) -> 40
A23: fauteuils | B23: =IF(VLOOKUP($B$8,fauteuils!$B:$DF,B$19,0)=0,"-",VLOOKUP($B$8,fauteuils!$B:$DF,B$19,0)) -> 6901 | C23: =IF(VLOOKUP($B$8,fauteuils!$B:$DF,C$19,0)=0,"-",VLOOKUP($B$8,fauteuils!$B:$DF,C$19,0)) -> 6761 | D23: =IF(VLOOKUP($B$8,fauteuils!$B:$DF,D$19,0)=0,"-",VLOOKUP($B$8,fauteuils!$B:$DF,D$19,0)) -> 6299 | E23: =IF(VLOOKUP($B$8,fauteuils!$B:$DF,E$19,0)=0,"-",VLOOKUP($B$8,fauteuils!$B:$DF,E$19,0)) -> 6296 | F23: =IF(VLOOKUP($B$8,fauteuils!$B:$DF,F$19,0)=0,"-",VLOOKUP($B$8,fauteuils!$B:$DF,F$19,0)) -> 5786 | G23: =IF(VLOOKUP($B$8,fauteuils!$B:$DF,G$19,0)=0,"-",VLOOKUP($B$8,fauteuils!$B:$DF,G$19,0)) -> 5777 | H23: =IF(VLOOKUP($B$8,fauteuils!$B:$DF,H$19,0)=0,"-",VLOOKUP($B$8,fauteuils!$B:$DF,H$19,0)) -> 5741 | I23: =IF(VLOOKUP($B$8,fauteuils!$B:$DF,I$19,0)=0,"-",VLOOKUP($B$8,fauteuils!$B:$DF,I$19,0)) -> 6199 | ... AH23: =IF(VLOOKUP($B$8,fauteuils!$B:$DF,AH$19,0)=0,"-",VLOOKUP($B$8,fauteuils!$B:$DF,AH$19,0)) -> 6691
A24: multiplexes (8 écrans et plus) | B24: =IF(VLOOKUP($B$8,multiplexes!$B:$DE,B$19,0)=0,"-",VLOOKUP($B$8,multiplexes!$B:$DE,B$19,0)) | C24: =IF(VLOOKUP($B$8,multiplexes!$B:$DE,C$19,0)=0,"-",VLOOKUP($B$8,multiplexes!$B:$DE,C$19,0)) | D24: =IF(VLOOKUP($B$8,multiplexes!$B:$DE,D$19,0)=0,"-",VLOOKUP($B$8,multiplexes!$B:$DE,D$19,0)) | E24: =IF(VLOOKUP($B$8,multiplexes!$B:$DE,E$19,0)=0,"-",VLOOKUP($B$8,multiplexes!$B:$DE,E$19,0)) | F24: =IF(VLOOKUP($B$8,multiplexes!$B:$DE,F$19,0)=0,"-",VLOOKUP($B$8,multiplexes!$B:$DE,F$19,0)) | G24: =IF(VLOOKUP($B$8,multiplexes!$B:$DE,G$19,0)=0,"-",VLOOKUP($B$8,multiplexes!$B:$DE,G$19,0)) | H24: =IF(VLOOKUP($B$8,multiplexes!$B:$DE,H$19,0)=0,"-",VLOOKUP($B$8,multiplexes!$B:$DE,H$19,0)) | I24: =IF(VLOOKUP($B$8,multiplexes!$B:$DE,I$19,0)=0,"-",VLOOKUP($B$8,multiplexes!$B:$DE,I$19,0)) | ... AH24: =IF(VLOOKUP($B$8,multiplexes!$B:$DE,AH$19,0)=0,"-",VLOOKUP($B$8,multiplexes!$B:$DE,AH$19,0)) -> 1
A25: séances (milliers) | B25: =IF(VLOOKUP($B$8,séances!$B:$DE,B$19,0)=0,"-",VLOOKUP($B$8,séances!$B:$DE,B$19,0)) -> 21626 | C25: =IF(VLOOKUP($B$8,séances!$B:$DE,C$19,0)=0,"-",VLOOKUP($B$8,séances!$B:$DE,C$19,0)) -> 20270 | D25: =IF(VLOOKUP($B$8,séances!$B:$DE,D$19,0)=0,"-",VLOOKUP($B$8,séances!$B:$DE,D$19,0)) -> 20472 | E25: =IF(VLOOKUP($B$8,séances!$B:$DE,E$19,0)=0,"-",VLOOKUP($B$8,séances!$B:$DE,E$19,0)) -> 21408 | F25: =IF(VLOOKUP($B$8,séances!$B:$DE,F$19,0)=0,"-",VLOOKUP($B$8,séances!$B:$DE,F$19,0)) -> 23063 | G25: =IF(VLOOKUP($B$8,séances!$B:$DE,G$19,0)=0,"-",VLOOKUP($B$8,séances!$B:$DE,G$19,0)) -> 23780 | H25: =IF(VLOOKUP($B$8,séances!$B:$DE,H$19,0)=0,"-",VLOOKUP($B$8,séances!$B:$DE,H$19,0)) -> 24774 | I25: =IF(VLOOKUP($B$8,séances!$B:$DE,I$19,0)=0,"-",VLOOKUP($B$8,séances!$B:$DE,I$19,0)) -> 23822 | ... AH25: =IF(VLOOKUP($B$8,séances!$B:$DE,AH$19,0)=0,"-",VLOOKUP($B$8,séances!$B:$DE,AH$19,0)) -> 35835
A26: entrées (millions) | B26: =IF(VLOOKUP($B$8,entrées!$B:$DE,B$19,0)=0,"-",VLOOKUP($B$8,entrées!$B:$DE,B$19,0)) -> 600483 | C26: =IF(VLOOKUP($B$8,entrées!$B:$DE,C$19,0)=0,"-",VLOOKUP($B$8,entrées!$B:$DE,C$19,0)) -> 704773 | D26: =IF(VLOOKUP($B$8,entrées!$B:$DE,D$19,0)=0,"-",VLOOKUP($B$8,entrées!$B:$DE,D$19,0)) -> 560305 | E26: =IF(VLOOKUP($B$8,entrées!$B:$DE,E$19,0)=0,"-",VLOOKUP($B$8,entrées!$B:$DE,E$19,0)) -> 612447 | F26: =IF(VLOOKUP($B$8,entrées!$B:$DE,F$19,0)=0,"-",VLOOKUP($B$8,entrées!$B:$DE,F$19,0)) -> 632894 | G26: =IF(VLOOKUP($B$8,entrées!$B:$DE,G$19,0)=0,"-",VLOOKUP($B$8,entrées!$B:$DE,G$19,0)) -> 681540 | H26: =IF(VLOOKUP($B$8,entrées!$B:$DE,H$19,0)=0,"-",VLOOKUP($B$8,entrées!$B:$DE,H$19,0)) -> 784805 | I26: =IF(VLOOKUP($B$8,entrées!$B:$DE,I$19,0)=0,"-",VLOOKUP($B$8,entrées!$B:$DE,I$19,0)) -> 656386 | ... AH26: =IF(VLOOKUP($B$8,entrées!$B:$DE,AH$19,0)=0,"-",VLOOKUP($B$8,entrées!$B:$DE,AH$19,0)) -> 953825
A27: recettes (M€) | B27: =IF(VLOOKUP($B$8,recettes!$B:$DE,B$19,0)=0,"-",VLOOKUP($B$8,recettes!$B:$DE,B$19,0)) -> 2785150.8 | C27: =IF(VLOOKUP($B$8,recettes!$B:$DE,C$19,0)=0,"-",VLOOKUP($B$8,recettes!$B:$DE,C$19,0)) -> 3135869.5 | D27: =IF(VLOOKUP($B$8,recettes!$B:$DE,D$19,0)=0,"-",VLOOKUP($B$8,recettes!$B:$DE,D$19,0)) -> 2731117.9 | E27: =IF(VLOOKUP($B$8,recettes!$B:$DE,E$19,0)=0,"-",VLOOKUP($B$8,recettes!$B:$DE,E$19,0)) -> 3056042.4 | F27: =IF(VLOOKUP($B$8,recettes!$B:$DE,F$19,0)=0,"-",VLOOKUP($B$8,recettes!$B:$DE,F$19,0)) -> 3177956.6 | G27: =IF(VLOOKUP($B$8,recettes!$B:$DE,G$19,0)=0,"-",VLOOKUP($B$8,recettes!$B:$DE,G$19,0)) -> 3434167.9 | H27: =IF(VLOOKUP($B$8,recettes!$B:$DE,H$19,0)=0,"-",VLOOKUP($B$8,recettes!$B:$DE,H$19,0)) -> 4124588 | I27: =IF(VLOOKUP($B$8,recettes!$B:$DE,I$19,0)=0,"-",VLOOKUP($B$8,recettes!$B:$DE,I$19,0)) -> 3386132.2 | ... AH27: =IF(VLOOKUP($B$8,recettes!$B:$DE,AH$19,0)=0,"-",VLOOKUP($B$8,recettes!$B:$DE,AH$19,0)) -> 6263096.5
A28: RME (€) | B28: =IF(VLOOKUP($B$8,RME!$B:$DE,B$19,0)=0,"-",VLOOKUP($B$8,RME!$B:$DE,B$19,0)) -> 4.6381842 | C28: =IF(VLOOKUP($B$8,RME!$B:$DE,C$19,0)=0,"-",VLOOKUP($B$8,RME!$B:$DE,C$19,0)) -> 4.4494746 | D28: =IF(VLOOKUP($B$8,RME!$B:$DE,D$19,0)=0,"-",VLOOKUP($B$8,RME!$B:$DE,D$19,0)) -> 4.8743415 | E28: =IF(VLOOKUP($B$8,RME!$B:$DE,E$19,0)=0,"-",VLOOKUP($B$8,RME!$B:$DE,E$19,0)) -> 4.9898888 | F28: =IF(VLOOKUP($B$8,RME!$B:$DE,F$19,0)=0,"-",VLOOKUP($B$8,RME!$B:$DE,F$19,0)) -> 5.0213095 | G28: =IF(VLOOKUP($B$8,RME!$B:$DE,G$19,0)=0,"-",VLOOKUP($B$8,RME!$B:$DE,G$19,0)) -> 5.0388354 | H28: =IF(VLOOKUP($B$8,RME!$B:$DE,H$19,0)=0,"-",VLOOKUP($B$8,RME!$B:$DE,H$19,0)) -> 5.2555578 | I28: =IF(VLOOKUP($B$8,RME!$B:$DE,I$19,0)=0,"-",VLOOKUP($B$8,RME!$B:$DE,I$19,0)) -> 5.1587515 | ... AH28: =IF(VLOOKUP($B$8,RME!$B:$DE,AH$19,0)=0,"-",VLOOKUP($B$8,RME!$B:$DE,AH$19,0)) -> 6.5662952
A29: indice de fréquentation | B29: =IF(VLOOKUP($B$8,'indice de fréquentation'!$B:$DE,B$19,0)=0,"-",VLOOKUP($B$8,'indice de fréquentation'!$B:$DE,B$19,0)) -> 1.2748594 | C29: =IF(VLOOKUP($B$8,'indice de fréquentation'!$B:$DE,C$19,0)=0,"-",VLOOKUP($B$8,'indice de fréquentation'!$B:$DE,C$19,0)) -> 1.496273 | D29: =IF(VLOOKUP($B$8,'indice de fréquentation'!$B:$DE,D$19,0)=0,"-",VLOOKUP($B$8,'indice de fréquentation'!$B:$DE,D$19,0)) -> 1.1895592 | E29: =IF(VLOOKUP($B$8,'indice de fréquentation'!$B:$DE,E$19,0)=0,"-",VLOOKUP($B$8,'indice de fréquentation'!$B:$DE,E$19,0)) -> 1.1885943 | F29: =IF(VLOOKUP($B$8,'indice de fréquentation'!$B:$DE,F$19,0)=0,"-",VLOOKUP($B$8,'indice de fréquentation'!$B:$DE,F$19,0)) -> 1.2282764 | G29: =IF(VLOOKUP($B$8,'indice de fréquentation'!$B:$DE,G$19,0)=0,"-",VLOOKUP($B$8,'indice de fréquentation'!$B:$DE,G$19,0)) -> 1.3226852 | H29: =IF(VLOOKUP($B$8,'indice de fréquentation'!$B:$DE,H$19,0)=0,"-",VLOOKUP($B$8,'indice de fréquentation'!$B:$DE,H$19,0)) -> 1.5230947 | I29: =IF(VLOOKUP($B$8,'indice de fréquentation'!$B:$DE,I$19,0)=0,"-",VLOOKUP($B$8,'indice de fréquentation'!$B:$DE,I$19,0)) -> 1.2738681 | ... AH29: =IF(VLOOKUP($B$8,'indice de fréquentation'!$B:$DE,AH$19,0)=0,"-",VLOOKUP($B$8,'indice de fréquentation'!$B:$DE,AH$19,0)) -> 1.4155886
A30: taux d'occupation des fauteuils (%) | B30: =IF(VLOOKUP($B$8,'taux d''occupation des fauteuils'!$B:$DE,B$19,0)=0,"-",VLOOKUP($B$8,'taux d''occupation des fauteuils'!$B:$DE,B$19,0)) -> 14.780407 | C30: =IF(VLOOKUP($B$8,'taux d''occupation des fauteuils'!$B:$DE,C$19,0)=0,"-",VLOOKUP($B$8,'taux d''occupation des fauteuils'!$B:$DE,C$19,0)) -> 18.1546 | D30: =IF(VLOOKUP($B$8,'taux d''occupation des fauteuils'!$B:$DE,D$19,0)=0,"-",VLOOKUP($B$8,'taux d''occupation des fauteuils'!$B:$DE,D$19,0)) -> 14.814649 | E30: =IF(VLOOKUP($B$8,'taux d''occupation des fauteuils'!$B:$DE,E$19,0)=0,"-",VLOOKUP($B$8,'taux d''occupation des fauteuils'!$B:$DE,E$19,0)) -> 15.674402 | F30: =IF(VLOOKUP($B$8,'taux d''occupation des fauteuils'!$B:$DE,F$19,0)=0,"-",VLOOKUP($B$8,'taux d''occupation des fauteuils'!$B:$DE,F$19,0)) -> 14.63536 | G30: =IF(VLOOKUP($B$8,'taux d''occupation des fauteuils'!$B:$DE,G$19,0)=0,"-",VLOOKUP($B$8,'taux d''occupation des fauteuils'!$B:$DE,G$19,0)) -> 15.327157 | H30: =IF(VLOOKUP($B$8,'taux d''occupation des fauteuils'!$B:$DE,H$19,0)=0,"-",VLOOKUP($B$8,'taux d''occupation des fauteuils'!$B:$DE,H$19,0)) -> 16.959695 | I30: =IF(VLOOKUP($B$8,'taux d''occupation des fauteuils'!$B:$DE,I$19,0)=0,"-",VLOOKUP($B$8,'taux d''occupation des fauteuils'!$B:$DE,I$19,0)) -> 14.916778 | ... AH30: =IF(VLOOKUP($B$8,'taux d''occupation des fauteuils'!$B:$DE,AH$19,0)=0,"-",VLOOKUP($B$8,'taux d''occupation des fauteuils'!$B:$DE,AH$19,0)) -> 14.433314
A33: Résultats des établissements Art et Essai
B34: 2 | C34: 3 | D34: 4 | E34: 5 | F34: 6 | G34: 7 | H34: 8 | I34: 9 | J34: 10 | K34: 11 | L34: 12 | M34: 13 | N34: 14 | O34: 15 | P34: 16 | Q34: 17 | R34: 18 | S34: 19 | T34: 20 | U34: 21 | V34: 22 | W34: 23 | X34: 24
B35: 2002 | C35: 2003 | D35: 2004 | E35: 2005 | F35: 2006 | G35: 2007 | H35: 2008 | I35: 2009 | J35: 2010 | K35: 2011 | L35: 2012 | M35: 2013 | N35: 2014 | O35: 2015 | P35: 2016 | Q35: 2017 | R35: 2018 | S35: 2019 | T35: 2020 | U35: 2021 | V35: 2022 | W35: 2023 | X35: 2024
A36: établissements | B36: =IF(VLOOKUP($B$8,étabAE!$B:$AZ,B$34,0)=0,"-",VLOOKUP($B$8,étabAE!$B:$AZ,B$34,0)) -> 10 | C36: =IF(VLOOKUP($B$8,étabAE!$B:$AZ,C$34,0)=0,"-",VLOOKUP($B$8,étabAE!$B:$AZ,C$34,0)) -> 12 | D36: =IF(VLOOKUP($B$8,étabAE!$B:$AZ,D$34,0)=0,"-",VLOOKUP($B$8,étabAE!$B:$AZ,D$34,0)) -> 12 | E36: =IF(VLOOKUP($B$8,étabAE!$B:$AZ,E$34,0)=0,"-",VLOOKUP($B$8,étabAE!$B:$AZ,E$34,0)) -> 11 | F36: =IF(VLOOKUP($B$8,étabAE!$B:$AZ,F$34,0)=0,"-",VLOOKUP($B$8,étabAE!$B:$AZ,F$34,0)) -> 11 | G36: =IF(VLOOKUP($B$8,étabAE!$B:$AZ,G$34,0)=0,"-",VLOOKUP($B$8,étabAE!$B:$AZ,G$34,0)) -> 12 | H36: =IF(VLOOKUP($B$8,étabAE!$B:$AZ,H$34,0)=0,"-",VLOOKUP($B$8,étabAE!$B:$AZ,H$34,0)) -> 11 | I36: =IF(VLOOKUP($B$8,étabAE!$B:$AZ,I$34,0)=0,"-",VLOOKUP($B$8,étabAE!$B:$AZ,I$34,0)) -> 12 | ... X36: =IF(VLOOKUP($B$8,étabAE!$B:$AZ,X$34,0)=0,"-",VLOOKUP($B$8,étabAE!$B:$AZ,X$34,0)) -> 14
A37: écrans | B37: =IF(VLOOKUP($B$8,écransAE!$B:$AZ,B$34,0)=0,"-",VLOOKUP($B$8,écransAE!$B:$AZ,B$34,0)) -> 16 | C37: =IF(VLOOKUP($B$8,écransAE!$B:$AZ,C$34,0)=0,"-",VLOOKUP($B$8,écransAE!$B:$AZ,C$34,0)) -> 18 | D37: =IF(VLOOKUP($B$8,écransAE!$B:$AZ,D$34,0)=0,"-",VLOOKUP($B$8,écransAE!$B:$AZ,D$34,0)) -> 18 | E37: =IF(VLOOKUP($B$8,écransAE!$B:$AZ,E$34,0)=0,"-",VLOOKUP($B$8,écransAE!$B:$AZ,E$34,0)) -> 17 | F37: =IF(VLOOKUP($B$8,écransAE!$B:$AZ,F$34,0)=0,"-",VLOOKUP($B$8,écransAE!$B:$AZ,F$34,0)) -> 19 | G37: =IF(VLOOKUP($B$8,écransAE!$B:$AZ,G$34,0)=0,"-",VLOOKUP($B$8,écransAE!$B:$AZ,G$34,0)) -> 20 | H37: =IF(VLOOKUP($B$8,écransAE!$B:$AZ,H$34,0)=0,"-",VLOOKUP($B$8,écransAE!$B:$AZ,H$34,0)) -> 19 | I37: =IF(VLOOKUP($B$8,écransAE!$B:$AZ,I$34,0)=0,"-",VLOOKUP($B$8,écransAE!$B:$AZ,I$34,0)) -> 23 | ... X37: =IF(VLOOKUP($B$8,écransAE!$B:$AZ,X$34,0)=0,"-",VLOOKUP($B$8,écransAE!$B:$AZ,X$34,0)) -> 23
A38: fauteuils | B38: =IF(VLOOKUP($B$8,fauteuilsAE!$B:$BA,B$34,0)=0,"-",VLOOKUP($B$8,fauteuilsAE!$B:$BA,B$34,0)) -> 2489 | C38: =IF(VLOOKUP($B$8,fauteuilsAE!$B:$BA,C$34,0)=0,"-",VLOOKUP($B$8,fauteuilsAE!$B:$BA,C$34,0)) -> 3025 | D38: =IF(VLOOKUP($B$8,fauteuilsAE!$B:$BA,D$34,0)=0,"-",VLOOKUP($B$8,fauteuilsAE!$B:$BA,D$34,0)) -> 3025 | E38: =IF(VLOOKUP($B$8,fauteuilsAE!$B:$BA,E$34,0)=0,"-",VLOOKUP($B$8,fauteuilsAE!$B:$BA,E$34,0)) -> 2975 | F38: =IF(VLOOKUP($B$8,fauteuilsAE!$B:$BA,F$34,0)=0,"-",VLOOKUP($B$8,fauteuilsAE!$B:$BA,F$34,0)) -> 3432 | G38: =IF(VLOOKUP($B$8,fauteuilsAE!$B:$BA,G$34,0)=0,"-",VLOOKUP($B$8,fauteuilsAE!$B:$BA,G$34,0)) -> 3542 | H38: =IF(VLOOKUP($B$8,fauteuilsAE!$B:$BA,H$34,0)=0,"-",VLOOKUP($B$8,fauteuilsAE!$B:$BA,H$34,0)) -> 3332 | I38: =IF(VLOOKUP($B$8,fauteuilsAE!$B:$BA,I$34,0)=0,"-",VLOOKUP($B$8,fauteuilsAE!$B:$BA,I$34,0)) -> 3731 | ... X38: =IF(VLOOKUP($B$8,fauteuilsAE!$B:$BA,X$34,0)=0,"-",VLOOKUP($B$8,fauteuilsAE!$B:$BA,X$34,0)) -> 3713
A39: séances (milliers) | B39: =IF(VLOOKUP($B$8,'séances AE'!$B:$AZ,B$34,0)=0,"-",VLOOKUP($B$8,'séances AE'!$B:$AZ,B$34,0)) -> 12163 | C39: =IF(VLOOKUP($B$8,'séances AE'!$B:$AZ,C$34,0)=0,"-",VLOOKUP($B$8,'séances AE'!$B:$AZ,C$34,0)) -> 13613 | D39: =IF(VLOOKUP($B$8,'séances AE'!$B:$AZ,D$34,0)=0,"-",VLOOKUP($B$8,'séances AE'!$B:$AZ,D$34,0)) -> 14472 | E39: =IF(VLOOKUP($B$8,'séances AE'!$B:$AZ,E$34,0)=0,"-",VLOOKUP($B$8,'séances AE'!$B:$AZ,E$34,0)) -> 12898 | F39: =IF(VLOOKUP($B$8,'séances AE'!$B:$AZ,F$34,0)=0,"-",VLOOKUP($B$8,'séances AE'!$B:$AZ,F$34,0)) -> 15317 | G39: =IF(VLOOKUP($B$8,'séances AE'!$B:$AZ,G$34,0)=0,"-",VLOOKUP($B$8,'séances AE'!$B:$AZ,G$34,0)) -> 15437 | H39: =IF(VLOOKUP($B$8,'séances AE'!$B:$AZ,H$34,0)=0,"-",VLOOKUP($B$8,'séances AE'!$B:$AZ,H$34,0)) -> 15336 | I39: =IF(VLOOKUP($B$8,'séances AE'!$B:$AZ,I$34,0)=0,"-",VLOOKUP($B$8,'séances AE'!$B:$AZ,I$34,0)) -> 19295 | ... X39: =IF(VLOOKUP($B$8,'séances AE'!$B:$AZ,X$34,0)=0,"-",VLOOKUP($B$8,'séances AE'!$B:$AZ,X$34,0)) -> 19108
A40: entrées (millions) | B40: =IF(VLOOKUP($B$8,entréesAE!$B:$AZ,B$34,0)=0,"-",VLOOKUP($B$8,entréesAE!$B:$AZ,B$34,0)) -> 347322 | C40: =IF(VLOOKUP($B$8,entréesAE!$B:$AZ,C$34,0)=0,"-",VLOOKUP($B$8,entréesAE!$B:$AZ,C$34,0)) -> 347434 | D40: =IF(VLOOKUP($B$8,entréesAE!$B:$AZ,D$34,0)=0,"-",VLOOKUP($B$8,entréesAE!$B:$AZ,D$34,0)) -> 418011 | E40: =IF(VLOOKUP($B$8,entréesAE!$B:$AZ,E$34,0)=0,"-",VLOOKUP($B$8,entréesAE!$B:$AZ,E$34,0)) -> 308461 | F40: =IF(VLOOKUP($B$8,entréesAE!$B:$AZ,F$34,0)=0,"-",VLOOKUP($B$8,entréesAE!$B:$AZ,F$34,0)) -> 439537 | G40: =IF(VLOOKUP($B$8,entréesAE!$B:$AZ,G$34,0)=0,"-",VLOOKUP($B$8,entréesAE!$B:$AZ,G$34,0)) -> 433056 | H40: =IF(VLOOKUP($B$8,entréesAE!$B:$AZ,H$34,0)=0,"-",VLOOKUP($B$8,entréesAE!$B:$AZ,H$34,0)) -> 423932 | I40: =IF(VLOOKUP($B$8,entréesAE!$B:$AZ,I$34,0)=0,"-",VLOOKUP($B$8,entréesAE!$B:$AZ,I$34,0)) -> 465379 | ... X40: =IF(VLOOKUP($B$8,entréesAE!$B:$AZ,X$34,0)=0,"-",VLOOKUP($B$8,entréesAE!$B:$AZ,X$34,0)) -> 480492
A41: recettes (M€) | B41: =IF(VLOOKUP($B$8,recettesAE!$B:$BA,B$34,0)=0,"-",VLOOKUP($B$8,recettesAE!$B:$BA,B$34,0)) -> 1773750 | C41: =IF(VLOOKUP($B$8,recettesAE!$B:$BA,C$34,0)=0,"-",VLOOKUP($B$8,recettesAE!$B:$BA,C$34,0)) -> 1783276 | D41: =IF(VLOOKUP($B$8,recettesAE!$B:$BA,D$34,0)=0,"-",VLOOKUP($B$8,recettesAE!$B:$BA,D$34,0)) -> 2157176 | E41: =IF(VLOOKUP($B$8,recettesAE!$B:$BA,E$34,0)=0,"-",VLOOKUP($B$8,recettesAE!$B:$BA,E$34,0)) -> 1567038 | F41: =IF(VLOOKUP($B$8,recettesAE!$B:$BA,F$34,0)=0,"-",VLOOKUP($B$8,recettesAE!$B:$BA,F$34,0)) -> 2411964 | G41: =IF(VLOOKUP($B$8,recettesAE!$B:$BA,G$34,0)=0,"-",VLOOKUP($B$8,recettesAE!$B:$BA,G$34,0)) -> 2392065 | H41: =IF(VLOOKUP($B$8,recettesAE!$B:$BA,H$34,0)=0,"-",VLOOKUP($B$8,recettesAE!$B:$BA,H$34,0)) -> 2360591 | I41: =IF(VLOOKUP($B$8,recettesAE!$B:$BA,I$34,0)=0,"-",VLOOKUP($B$8,recettesAE!$B:$BA,I$34,0)) -> 2668571 | ... X41: =IF(VLOOKUP($B$8,recettesAE!$B:$BA,X$34,0)=0,"-",VLOOKUP($B$8,recettesAE!$B:$BA,X$34,0)) -> 3006753
A42: RME (€) | B42: =IF(VLOOKUP($B$8,RMEAE!$B:$AZ,B$34,0)=0,"-",VLOOKUP($B$8,RMEAE!$B:$AZ,B$34,0)) -> 5.1069325 | C42: =IF(VLOOKUP($B$8,RMEAE!$B:$AZ,C$34,0)=0,"-",VLOOKUP($B$8,RMEAE!$B:$AZ,C$34,0)) -> 5.1327043 | D42: =IF(VLOOKUP($B$8,RMEAE!$B:$AZ,D$34,0)=0,"-",VLOOKUP($B$8,RMEAE!$B:$AZ,D$34,0)) -> 5.1605723 | E42: =IF(VLOOKUP($B$8,RMEAE!$B:$AZ,E$34,0)=0,"-",VLOOKUP($B$8,RMEAE!$B:$AZ,E$34,0)) -> 5.0801819 | F42: =IF(VLOOKUP($B$8,RMEAE!$B:$AZ,F$34,0)=0,"-",VLOOKUP($B$8,RMEAE!$B:$AZ,F$34,0)) -> 5.4875107 | G42: =IF(VLOOKUP($B$8,RMEAE!$B:$AZ,G$34,0)=0,"-",VLOOKUP($B$8,RMEAE!$B:$AZ,G$34,0)) -> 5.5236852 | H42: =IF(VLOOKUP($B$8,RMEAE!$B:$AZ,H$34,0)=0,"-",VLOOKUP($B$8,RMEAE!$B:$AZ,H$34,0)) -> 5.5683246 | I42: =IF(VLOOKUP($B$8,RMEAE!$B:$AZ,I$34,0)=0,"-",VLOOKUP($B$8,RMEAE!$B:$AZ,I$34,0)) -> 5.7341887 | ... X42: =IF(VLOOKUP($B$8,RMEAE!$B:$AZ,X$34,0)=0,"-",VLOOKUP($B$8,RMEAE!$B:$AZ,X$34,0)) -> 6.2576547
A43: indice de fréquentation | B43: =IF(VLOOKUP($B$8,'indice de fréquentationAE'!$B:$AZ,B$34,0)=0,"-",VLOOKUP($B$8,'indice de fréquentationAE'!$B:$AZ,B$34,0)) -> 0.67405826 | C43: =IF(VLOOKUP($B$8,'indice de fréquentationAE'!$B:$AZ,C$34,0)=0,"-",VLOOKUP($B$8,'indice de fréquentationAE'!$B:$AZ,C$34,0)) -> 0.67427562 | D43: =IF(VLOOKUP($B$8,'indice de fréquentationAE'!$B:$AZ,D$34,0)=0,"-",VLOOKUP($B$8,'indice de fréquentationAE'!$B:$AZ,D$34,0)) -> 0.73757102 | E43: =IF(VLOOKUP($B$8,'indice de fréquentationAE'!$B:$AZ,E$34,0)=0,"-",VLOOKUP($B$8,'indice de fréquentationAE'!$B:$AZ,E$34,0)) -> 0.54427251 | F43: =IF(VLOOKUP($B$8,'indice de fréquentationAE'!$B:$AZ,F$34,0)=0,"-",VLOOKUP($B$8,'indice de fréquentationAE'!$B:$AZ,F$34,0)) -> 0.65232465 | G43: =IF(VLOOKUP($B$8,'indice de fréquentationAE'!$B:$AZ,G$34,0)=0,"-",VLOOKUP($B$8,'indice de fréquentationAE'!$B:$AZ,G$34,0)) -> 0.64270608 | H43: =IF(VLOOKUP($B$8,'indice de fréquentationAE'!$B:$AZ,H$34,0)=0,"-",VLOOKUP($B$8,'indice de fréquentationAE'!$B:$AZ,H$34,0)) -> 0.62916499 | I43: =IF(VLOOKUP($B$8,'indice de fréquentationAE'!$B:$AZ,I$34,0)=0,"-",VLOOKUP($B$8,'indice de fréquentationAE'!$B:$AZ,I$34,0)) -> 0.69067722 | ... X43: =IF(VLOOKUP($B$8,'indice de fréquentationAE'!$B:$AZ,X$34,0)=0,"-",VLOOKUP($B$8,'indice de fréquentationAE'!$B:$AZ,X$34,0)) -> 0.71310669
A44: taux d'occupation des fauteuils (%) | B44: =IF(VLOOKUP($B$8,tmofAE!$B:$AZ,B$34,0)=0,"-",VLOOKUP($B$8,tmofAE!$B:$AZ,B$34,0)) -> 16.537261 | C44: =IF(VLOOKUP($B$8,tmofAE!$B:$AZ,C$34,0)=0,"-",VLOOKUP($B$8,tmofAE!$B:$AZ,C$34,0)) -> 13.783393 | D44: =IF(VLOOKUP($B$8,tmofAE!$B:$AZ,D$34,0)=0,"-",VLOOKUP($B$8,tmofAE!$B:$AZ,D$34,0)) -> 15.584991 | E44: =IF(VLOOKUP($B$8,tmofAE!$B:$AZ,E$34,0)=0,"-",VLOOKUP($B$8,tmofAE!$B:$AZ,E$34,0)) -> 13.026866 | F44: =IF(VLOOKUP($B$8,tmofAE!$B:$AZ,F$34,0)=0,"-",VLOOKUP($B$8,tmofAE!$B:$AZ,F$34,0)) -> 15.178108 | G44: =IF(VLOOKUP($B$8,tmofAE!$B:$AZ,G$34,0)=0,"-",VLOOKUP($B$8,tmofAE!$B:$AZ,G$34,0)) -> 15.24444 | H44: =IF(VLOOKUP($B$8,tmofAE!$B:$AZ,H$34,0)=0,"-",VLOOKUP($B$8,tmofAE!$B:$AZ,H$34,0)) -> 15.320338 | I44: =IF(VLOOKUP($B$8,tmofAE!$B:$AZ,I$34,0)=0,"-",VLOOKUP($B$8,tmofAE!$B:$AZ,I$34,0)) -> 14.004827 | ... X44: =IF(VLOOKUP($B$8,tmofAE!$B:$AZ,X$34,0)=0,"-",VLOOKUP($B$8,tmofAE!$B:$AZ,X$34,0)) -> 14.930165
A47: Résultats des établissements à moins de 80 000 entrées annuelles
B48: 2 | C48: 3 | D48: 4 | E48: 5 | F48: 6 | G48: 7 | H48: 8 | I48: 9 | J48: 10 | K48: 11 | L48: 12 | M48: 13 | N48: 14 | O48: 15 | P48: 16 | Q48: 17 | R48: 18 | S48: 19 | T48: 20 | U48: 21 | V48: 22
B49: 2004 | C49: 2005 | D49: 2006 | E49: 2007 | F49: 2008 | G49: 2009 | H49: 2010 | I49: 2011 | J49: 2012 | K49: 2013 | L49: 2014 | M49: 2015 | N49: 2016 | O49: 2017 | P49: 2018 | Q49: 2019 | R49: 2020 | S49: 2021 | T49: 2022 | U49: 2023 | V49: 2024
A50: établissements | B50: =IF(VLOOKUP($B$8,étabP!$B:$BA,B$48,0)=0,"-",VLOOKUP($B$8,étabP!$B:$BA,B$48,0)) -> 15 | C50: =IF(VLOOKUP($B$8,étabP!$B:$BA,C$48,0)=0,"-",VLOOKUP($B$8,étabP!$B:$BA,C$48,0)) -> 16 | D50: =IF(VLOOKUP($B$8,étabP!$B:$BA,D$48,0)=0,"-",VLOOKUP($B$8,étabP!$B:$BA,D$48,0)) -> 16 | E50: =IF(VLOOKUP($B$8,étabP!$B:$BA,E$48,0)=0,"-",VLOOKUP($B$8,étabP!$B:$BA,E$48,0)) -> 16 | F50: =IF(VLOOKUP($B$8,étabP!$B:$BA,F$48,0)=0,"-",VLOOKUP($B$8,étabP!$B:$BA,F$48,0)) -> 18 | G50: =IF(VLOOKUP($B$8,étabP!$B:$BA,G$48,0)=0,"-",VLOOKUP($B$8,étabP!$B:$BA,G$48,0)) -> 18 | H50: =IF(VLOOKUP($B$8,étabP!$B:$BA,H$48,0)=0,"-",VLOOKUP($B$8,étabP!$B:$BA,H$48,0)) -> 17 | I50: =IF(VLOOKUP($B$8,étabP!$B:$BA,I$48,0)=0,"-",VLOOKUP($B$8,étabP!$B:$BA,I$48,0)) -> 13 | ... V50: =IF(VLOOKUP($B$8,étabP!$B:$BA,V$48,0)=0,"-",VLOOKUP($B$8,étabP!$B:$BA,V$48,0)) -> 17
...

Sheet établissements
A2: Retour au menu "Départements"
A5: Etablissements par département
C7: 1966 | D7: 1967 | E7: 1968 | F7: 1969 | G7: 1970 | H7: 1971 | I7: 1972 | J7: 1973 | K7: 1974 | L7: 1975 | M7: 1976 | N7: 1977 | O7: 1978 | P7: 1979 | Q7: 1980 | R7: 1981 | S7: 1982 | T7: 1983 | U7: 1984 | V7: 1985 | W7: 1986 | X7: 1987 | Y7: 1988 | Z7: 1989 | AA7: 1990 | AB7: 1991 | AC7: 1992 | AD7: 1993 | AE7: 1994 | AF7: 1995 | AG7: 1996 | AH7: 1997 | AI7: 1998 | AJ7: 1999 | AK7: 2000 | AL7: 2001 | AM7: 2002 | AN7: 2003 | AO7: 2004 | AP7: 2005 | AQ7: 2006 | AR7: 2007 | AS7: 2008 | AT7: 2009 | AU7: 2010 | AV7: 2011 | AW7: 2012 | AX7: 2013 | AY7: 2014 | AZ7: 2015 | BA7: 2016 | BB7: 2017 | BC7: 2018 | BD7: 2019 | BE7: 2020 | BF7: 2021 | BG7: 2022 | BH7: 2023 | BI7: 2024
A8: 01 | B8: AIN | AC8: 20 | AD8: 19 | AE8: 17 | AF8: 18 | AG8: 19 | AH8: 19 | AI8: 19 | AJ8: 21 | AK8: 21 | AL8: 21 | AM8: 20 | AN8: 20 | AO8: 20 | AP8: 20 | AQ8: 20 | AR8: 20 | AS8: 22 | AT8: 21 | AU8: 20 | AV8: 18 | AW8: 17 | AX8: 18 | AY8: 18 | AZ8: 18 | BA8: 18 | BB8: 19 | BC8: 19 | BD8: 21 | BE8: 21 | BF8: 21 | BG8: 21 | BH8: 20 | BI8: 20
A9: 02 | B9: AISNE | AC9: 15 | AD9: 15 | AE9: 15 | AF9: 16 | AG9: 17 | AH9: 15 | AI9: 15 | AJ9: 15 | AK9: 15 | AL9: 15 | AM9: 15 | AN9: 15 | AO9: 15 | AP9: 15 | AQ9: 15 | AR9: 15 | AS9: 15 | AT9: 15 | AU9: 15 | AV9: 15 | AW9: 15 | AX9: 15 | AY9: 15 | AZ9: 15 | BA9: 15 | BB9: 15 | BC9: 15 | BD9: 15 | BE9: 15 | BF9: 15 | BG9: 15 | BH9: 15 | BI9: 15
A10: 03 | B10: ALLIER | AC10: 15 | AD10: 15 | AE10: 14 | AF10: 14 | AG10: 14 | AH10: 14 | AI10: 14 | AJ10: 14 | AK10: 11 | AL10: 11 | AM10: 11 | AN10: 12 | AO10: 13 | AP10: 10 | AQ10: 10 | AR10: 10 | AS10: 10 | AT10: 10 | AU10: 10 | AV10: 9 | AW10: 8 | AX10: 8 | AY10: 7 | AZ10: 7 | BA10: 8 | BB10: 8 | BC10: 8 | BD10: 8 | BE10: 8 | BF10: 8 | BG10: 8 | BH10: 8 | BI10: 8
A11: 04 | B11: ALPES-DE-HAUTE-PROVENCE | AC11: 12 | AD11: 13 | AE11: 14 | AF11: 13 | AG11: 12 | AH11: 15 | AI11: 14 | AJ11: 14 | AK11: 14 | AL11: 15 | AM11: 15 | AN11: 15 | AO11: 15 | AP11: 15 | AQ11: 15 | AR11: 13 | AS11: 13 | AT11: 13 | AU11: 13 | AV11: 13 | AW11: 13 | AX11: 13 | AY11: 13 | AZ11: 13 | BA11: 13 | BB11: 14 | BC11: 14 | BD11: 14 | BE11: 14 | BF11: 13 | BG11: 13 | BH11: 12 | BI11: 13
A12: 05 | B12: HAUTES-ALPES | AC12: 21 | AD12: 21 | AE12: 20 | AF12: 21 | AG12: 24 | AH12: 24 | AI12: 24 | AJ12: 24 | AK12: 23 | AL12: 23 | AM12: 23 | AN12: 22 | AO12: 24 | AP12: 22 | AQ12: 22 | AR12: 22 | AS12: 22 | AT12: 22 | AU12: 22 | AV12: 22 | AW12: 22 | AX12: 23 | AY12: 22 | AZ12: 22 | BA12: 23 | BB12: 23 | BC12: 23 | BD12: 23 | BE12: 23 | BF12: 21 | BG12: 21 | BH12: 20 | BI12: 19
A13: 06 | B13: ALPES-MARITIMES | AC13: 33 | AD13: 32 | AE13: 31 | AF13: 31 | AG13: 36 | AH13: 32 | AI13: 34 | AJ13: 34 | AK13: 37 | AL13: 38 | AM13: 42 | AN13: 40 | AO13: 42 | AP13: 42 | AQ13: 42 | AR13: 41 | AS13: 41 | AT13: 42 | AU13: 41 | AV13: 40 | AW13: 39 | AX13: 42 | AY13: 43 | AZ13: 44 | BA13: 43 | BB13: 43 | BC13: 45 | BD13: 43 | BE13: 42 | BF13: 44 | BG13: 45 | BH13: 45 | BI13: 45
A14: 07 | B14: ARDECHE | AC14: 21 | AD14: 20 | AE14: 20 | AF14: 20 | AG14: 20 | AH14: 20 | AI14: 20 | AJ14: 22 | AK14: 22 | AL14: 23 | AM14: 23 | AN14: 22 | AO14: 23 | AP14: 22 | AQ14: 23 | AR14: 23 | AS14: 23 | AT14: 22 | AU14: 23 | AV14: 21 | AW14: 22 | AX14: 20 | AY14: 20 | AZ14: 21 | BA14: 20 | BB14: 19 | BC14: 19 | BD14: 19 | BE14: 18 | BF14: 19 | BG14: 19 | BH14: 19 | BI14: 19
A15: 08 | B15: ARDENNES | AC15: 6 | AD15: 6 | AE15: 7 | AF15: 7 | AG15: 7 | AH15: 7 | AI15: 7 | AJ15: 7 | AK15: 7 | AL15: 7 | AM15: 7 | AN15: 7 | AO15: 6 | AP15: 6 | AQ15: 6 | AR15: 5 | AS15: 5 | AT15: 6 | AU15: 6 | AV15: 6 | AW15: 6 | AX15: 6 | AY15: 5 | AZ15: 5 | BA15: 5 | BB15: 5 | BC15: 5 | BD15: 5 | BE15: 5 | BF15: 5 | BG15: 5 | BH15: 5 | BI15: 5
A16: 09 | B16: ARIEGE | AC16: 9 | AD16: 9 | AE16: 10 | AF16: 10 | AG16: 9 | AH16: 9 | AI16: 9 | AJ16: 10 | AK16: 10 | AL16: 10 | AM16: 10 | AN16: 10 | AO16: 10 | AP16: 11 | AQ16: 11 | AR16: 11 | AS16: 11 | AT16: 11 | AU16: 11 | AV16: 11 | AW16: 11 | AX16: 11 | AY16: 11 | AZ16: 11 | BA16: 11 | BB16: 11 | BC16: 11 | BD16: 11 | BE16: 11 | BF16: 11 | BG16: 10 | BH16: 10 | BI16: 10
A17: 10 | B17: AUBE | AC17: 6 | AD17: 6 | AE17: 6 | AF17: 6 | AG17: 6 | AH17: 6 | AI17: 6 | AJ17: 6 | AK17: 5 | AL17: 5 | AM17: 5 | AN17: 5 | AO17: 5 | AP17: 4 | AQ17: 4 | AR17: 4 | AS17: 4 | AT17: 4 | AU17: 4 | AV17: 4 | AW17: 4 | AX17: 4 | AY17: 4 | AZ17: 4 | BA17: 4 | BB17: 4 | BC17: 4 | BD17: 4 | BE17: 4 | BF17: 4 | BG17: 6 | BH17: 5 | BI17: 5
A18: 11 | B18: AUDE | AC18: 12 | AD18: 12 | AE18: 14 | AF18: 14 | AG18: 15 | AH18: 13 | AI18: 12 | AJ18: 15 | AK18: 14 | AL18: 15 | AM18: 15 | AN18: 14 | AO18: 12 | AP18: 13 | AQ18: 11 | AR18: 11 | AS18: 11 | AT18: 12 | AU18: 11 | AV18: 11 | AW18: 11 | AX18: 11 | AY18: 11 | AZ18: 11 | BA18: 11 | BB18: 11 | BC18: 11 | BD18: 11 | BE18: 11 | BF18: 11 | BG18: 11 | BH18: 11 | BI18: 11
A19: 12 | B19: AVEYRON | AC19: 13 | AD19: 13 | AE19: 12 | AF19: 12 | AG19: 12 | AH19: 14 | AI19: 14 | AJ19: 15 | AK19: 14 | AL19: 15 | AM19: 16 | AN19: 16 | AO19: 16 | AP19: 15 | AQ19: 16 | AR19: 16 | AS19: 15 | AT19: 15 | AU19: 15 | AV19: 15 | AW19: 15 | AX19: 14 | AY19: 15 | AZ19: 15 | BA19: 15 | BB19: 15 | BC19: 15 | BD19: 15 | BE19: 16 | BF19: 16 | BG19: 17 | BH19: 17 | BI19: 17
... A103: 95 | B103: VAL-D'OISE | AC103: 23 | AD103: 23 | AE103: 20 | AF103: 23 | AG103: 23 | AH103: 23 | AI103: 23 | AJ103: 23 | AK103: 22 | AL103: 23 | AM103: 22 | AN103: 22 | AO103: 23 | AP103: 22 | AQ103: 22 | AR103: 23 | AS103: 23 | AT103: 24 | AU103: 24 | AV103: 24 | AW103: 24 | AX103: 23 | AY103: 23 | AZ103: 24 | BA103: 26 | BB103: 28 | BC103: 27 | BD103: 28 | BE103: 28 | BF103: 27 | BG103: 29 | BH103: 29 | BI103: 29
B104: TOTAL | C104: =SUM(C8:C103) -> 0 | D104: =SUM(D8:D103) -> 0 | E104: =SUM(E8:E103) -> 0 | F104: =SUM(F8:F103) -> 0 | G104: =SUM(G8:G103) -> 0 | H104: =SUM(H8:H103) -> 0 | I104: =SUM(I8:I103) -> 0 | J104: =SUM(J8:J103) -> 0 | ... AF104: =SUM(AF8:AF103) -> 2119 | AG104: 2141 | AH104: 2142 | AI104: 2146 | AJ104: 2173 | AK104: 2160 | AL104: 2152 | AM104: 2143 | AN104: 2129 | AO104: 2101 | AP104: 2080 | AQ104: 2066 | AR104: 2056 | AS104: 2072 | AT104: 2073 | AU104: 2050 | AV104: 2034 | AW104: 2035 | AX104: 2027 | AY104: 2020 | AZ104: 2033 | BA104: 2044 | BB104: 2046 | BC104: 2040 | BD104: 2045 | BE104: 2041 | BF104: 2030 | BG104: 2061 | BH104: 2058 | BI104: 2053

Sheet écrans
A2: Retour au menu "Départements"
A5: Ecrans par département
C7: 1966 | D7: 1967 | E7: 1968 | F7: 1969 | G7: 1970 | H7: 1971 | I7: 1972 | J7: 1973 | K7: 1974 | L7: 1975 | M7: 1976 | N7: 1977 | O7: 1978 | P7: 1979 | Q7: 1980 | R7: 1981 | S7: 1982 | T7: 1983 | U7: 1984 | V7: 1985 | W7: 1986 | X7: 1987 | Y7: 1988 | Z7: 1989 | AA7: 1990 | AB7: 1991 | AC7: 1992 | AD7: 1993 | AE7: 1994 | AF7: 1995 | AG7: 1996 | AH7: 1997 | AI7: 1998 | AJ7: 1999 | AK7: 2000 | AL7: 2001 | AM7: 2002 | AN7: 2003 | AO7: 2004 | AP7: 2005 | AQ7: 2006 | AR7: 2007 | AS7: 2008 | AT7: 2009 | AU7: 2010 | AV7: 2011 | AW7: 2012 | AX7: 2013 | AY7: 2014 | AZ7: 2015 | BA7: 2016 | BB7: 2017 | BC7: 2018 | BD7: 2019 | BE7: 2020 | BF7: 2021 | BG7: 2022 | BH7: 2023 | BI7: 2024
A8: 01 | B8: AIN | C8: 35 | D8: 34 | E8: 33 | F8: 32 | G8: 28 | H8: 27 | I8: 26 | J8: 25 | K8: 25 | L8: 24 | M8: 23 | N8: 22 | O8: 24 | P8: 21 | Q8: 19 | R8: 26 | S8: 28 | T8: 30 | U8: 36 | V8: 37 | W8: 36 | X8: 37 | Y8: 39 | Z8: 39 | AA8: 38 | AB8: 37 | AC8: 36 | AD8: 35 | AE8: 33 | AF8: 34 | AG8: 35 | AH8: 35 | AI8: 35 | AJ8: 39 | AK8: 36 | AL8: 36 | AM8: 35 | AN8: 35 | AO8: 35 | AP8: 37 | AQ8: 37 | AR8: 37 | AS8: 47 | AT8: 42 | AU8: 41 | AV8: 39 | AW8: 38 | AX8: 39 | AY8: 38 | AZ8: 38 | BA8: 38 | BB8: 39 | BC8: 39 | BD8: 41 | BE8: 41 | BF8: 41 | BG8: 41 | BH8: 40 | BI8: 40
A9: 02 | B9: AISNE | C9: 33 | D9: 31 | E9: 29 | F9: 27 | G9: 26 | H9: 25 | I9: 30 | J9: 30 | K9: 31 | L9: 32 | M9: 31 | N9: 31 | O9: 34 | P9: 37 | Q9: 34 | R9: 32 | S9: 32 | T9: 35 | U9: 35 | V9: 37 | W9: 36 | X9: 38 | Y9: 38 | Z9: 37 | AA9: 37 | AB9: 37 | AC9: 36 | AD9: 36 | AE9: 36 | AF9: 37 | AG9: 39 | AH9: 37 | AI9: 38 | AJ9: 38 | AK9: 38 | AL9: 38 | AM9: 38 | AN9: 38 | AO9: 39 | AP9: 39 | AQ9: 38 | AR9: 43 | AS9: 44 | AT9: 43 | AU9: 43 | AV9: 43 | AW9: 43 | AX9: 43 | AY9: 43 | AZ9: 43 | BA9: 43 | BB9: 43 | BC9: 43 | BD9: 44 | BE9: 43 | BF9: 43 | BG9: 43 | BH9: 42 | BI9: 42
A10: 03 | B10: ALLIER | C10: 39 | D10: 38 | E10: 40 | F10: 39 | G10: 36 | H10: 35 | I10: 34 | J10: 35 | K10: 34 | L10: 33 | M10: 37 | N10: 36 | O10: 31 | P10: 31 | Q10: 32 | R10: 34 | S10: 34 | T10: 34 | U10: 40 | V10: 41 | W10: 43 | X10: 44 | Y10: 40 | Z10: 36 | AA10: 33 | AB10: 33 | AC10: 31 | AD10: 31 | AE10: 30 | AF10: 30 | AG10: 30 | AH10: 30 | AI10: 30 | AJ10: 29 | AK10: 28 | AL10: 28 | AM10: 28 | AN10: 29 | AO10: 36 | AP10: 27 | AQ10: 27 | AR10: 27 | AS10: 27 | AT10: 27 | AU10: 24 | AV10: 27 | AW10: 26 | AX10: 26 | AY10: 25 | AZ10: 25 | BA10: 26 | BB10: 26 | BC10: 26 | BD10: 26 | BE10: 26 | BF10: 26 | BG10: 26 | BH10: 26 | BI10: 26
A11: 04 | B11: ALPES-DE-HAUTE-PROVENCE | C11: 89 | D11: 21 | E11: 20 | F11: 18 | G11: 18 | H11: 19 | I11: 18 | J11: 17 | K11: 18 | L11: 20 | M11: 19 | N11: 20 | O11: 21 | P11: 20 | Q11: 18 | R11: 19 | S11: 21 | T11: 26 | U11: 30 | V11: 31 | W11: 34 | X11: 29 | Y11: 29 | Z11: 24 | AA11: 23 | AB11: 21 | AC11: 20 | AD11: 21 | AE11: 22 | AF11: 21 | AG11: 20 | AH11: 23 | AI11: 22 | AJ11: 22 | AK11: 22 | AL11: 23 | AM11: 23 | AN11: 23 | AO11: 23 | AP11: 23 | AQ11: 25 | AR11: 23 | AS11: 23 | AT11: 23 | AU11: 23 | AV11: 23 | AW11: 23 | AX11: 23 | AY11: 24 | AZ11: 24 | BA11: 24 | BB11: 25 | BC11: 29 | BD11: 29 | BE11: 29 | BF11: 28 | BG11: 28 | BH11: 27 | BI11: 28
A12: 05 | B12: HAUTES-ALPES | C12: 22 | D12: 16 | E12: 16 | F12: 15 | G12: 15 | H12: 16 | I12: 16 | J12: 16 | K12: 16 | L12: 16 | M12: 16 | N12: 16 | O12: 17 | P12: 19 | Q12: 18 | R12: 17 | S12: 20 | T12: 24 | U12: 27 | V12: 29 | W12: 30 | X12: 29 | Y12: 27 | Z12: 27 | AA12: 27 | AB12: 27 | AC12: 26 | AD12: 27 | AE12: 27 | AF12: 29 | AG12: 32 | AH12: 34 | AI12: 34 | AJ12: 35 | AK12: 35 | AL12: 35 | AM12: 35 | AN12: 34 | AO12: 36 | AP12: 34 | AQ12: 34 | AR12: 34 | AS12: 34 | AT12: 34 | AU12: 34 | AV12: 34 | AW12: 34 | AX12: 35 | AY12: 34 | AZ12: 34 | BA12: 35 | BB12: 35 | BC12: 35 | BD12: 38 | BE12: 38 | BF12: 34 | BG12: 34 | BH12: 33 | BI12: 32
A13: 06 | B13: ALPES-MARITIMES | C13: 16 | D13: 87 | E13: 88 | F13: 87 | G13: 84 | H13: 85 | I13: 84 | J13: 78 | K13: 78 | L13: 79 | M13: 85 | N13: 92 | O13: 101 | P13: 105 | Q13: 95 | R13: 104 | S13: 109 | T13: 113 | U13: 124 | V13: 127 | W13: 127 | X13: 120 | Y13: 113 | Z13: 108 | AA13: 95 | AB13: 88 | AC13: 74 | AD13: 74 | AE13: 72 | AF13: 72 | AG13: 77 | AH13: 72 | AI13: 75 | AJ13: 84 | AK13: 87 | AL13: 90 | AM13: 94 | AN13: 92 | AO13: 93 | AP13: 93 | AQ13: 93 | AR13: 92 | AS13: 93 | AT13: 94 | AU13: 96 | AV13: 95 | AW13: 94 | AX13: 97 | AY13: 99 | AZ13: 109 | BA13: 110 | BB13: 107 | BC13: 117 | BD13: 115 | BE13: 110 | BF13: 130 | BG13: 133 | BH13: 132 | BI13: 141
A14: 07 | B14: ARDECHE | C14: 24 | D14: 24 | E14: 24 | F14: 24 | G14: 22 | H14: 21 | I14: 21 | J14: 21 | K14: 21 | L14: 21 | M14: 21 | N14: 22 | O14: 20 | P14: 21 | Q14: 21 | R14: 28 | S14: 33 | T14: 37 | U14: 39 | V14: 42 | W14: 42 | X14: 43 | Y14: 41 | Z14: 40 | AA14: 42 | AB14: 36 | AC14: 32 | AD14: 31 | AE14: 31 | AF14: 31 | AG14: 31 | AH14: 31 | AI14: 31 | AJ14: 33 | AK14: 33 | AL14: 34 | AM14: 34 | AN14: 33 | AO14: 34 | AP14: 33 | AQ14: 34 | AR14: 34 | AS14: 34 | AT14: 33 | AU14: 34 | AV14: 32 | AW14: 34 | AX14: 32 | AY14: 32 | AZ14: 33 | BA14: 32 | BB14: 32 | BC14: 32 | BD14: 33 | BE14: 32 | BF14: 34 | BG14: 34 | BH14: 34 | BI14: 34
A15: 08 | B15: ARDENNES | C15: 23 | D15: 22 | E15: 22 | F15: 21 | G15: 22 | H15: 20 | I15: 19 | J15: 19 | K15: 22 | L15: 22 | M15: 23 | N15: 17 | O15: 18 | P15: 17 | Q15: 16 | R15: 17 | S15: 17 | T15: 17 | U15: 15 | V15: 15 | W15: 14 | X15: 13 | Y15: 15 | Z15: 14 | AA15: 14 | AB15: 14 | AC15: 13 | AD15: 13 | AE15: 15 | AF15: 15 | AG15: 15 | AH15: 15 | AI15: 15 | AJ15: 15 | AK15: 15 | AL15: 15 | AM15: 15 | AN15: 15 | AO15: 19 | AP15: 19 | AQ15: 19 | AR15: 16 | AS15: 16 | AT15: 19 | AU15: 19 | AV15: 19 | AW15: 19 | AX15: 19 | AY15: 18 | AZ15: 18 | BA15: 18 | BB15: 18 | BC15: 18 | BD15: 18 | BE15: 18 | BF15: 18 | BG15: 18 | BH15: 18 | BI15: 18
A16: 09 | B16: ARIEGE | C16: 19 | D16: 19 | E16: 18 | F16: 12 | G16: 11 | H16: 11 | I16: 11 | J16: 11 | K16: 11 | L16: 10 | M16: 10 | N16: 9 | O16: 9 | P16: 10 | Q16: 10 | R16: 11 | S16: 10 | T16: 12 | U16: 11 | V16: 10 | W16: 10 | X16: 10 | Y16: 9 | Z16: 5 | AA16: 8 | AB16: 8 | AC16: 9 | AD16: 9 | AE16: 10 | AF16: 10 | AG16: 9 | AH16: 9 | AI16: 10 | AJ16: 11 | AK16: 11 | AL16: 11 | AM16: 11 | AN16: 11 | AO16: 11 | AP16: 12 | AQ16: 12 | AR16: 12 | AS16: 12 | AT16: 12 | AU16: 12 | AV16: 12 | AW16: 12 | AX16: 12 | AY16: 12 | AZ16: 12 | BA16: 13 | BB16: 13 | BC16: 13 | BD16: 13 | BE16: 13 | BF16: 13 | BG16: 12 | BH16: 12 | BI16: 12
A17: 10 | B17: AUBE | C17: 19 | D17: 18 | E17: 17 | F17: 16 | G17: 14 | H17: 16 | I17: 17 | J17: 16 | K17: 15 | L17: 12 | M17: 12 | N17: 12 | O17: 12 | P17: 12 | Q17: 13 | R17: 13 | S17: 13 | T17: 13 | U17: 15 | V17: 17 | W17: 16 | X17: 17 | Y17: 14 | Z17: 14 | AA17: 14 | AB17: 15 | AC17: 16 | AD17: 16 | AE17: 16 | AF17: 16 | AG17: 16 | AH17: 16 | AI17: 16 | AJ17: 16 | AK17: 19 | AL17: 19 | AM17: 19 | AN17: 19 | AO17: 21 | AP17: 17 | AQ17: 17 | AR17: 17 | AS17: 17 | AT17: 17 | AU17: 17 | AV17: 17 | AW17: 17 | AX17: 17 | AY17: 17 | AZ17: 17 | BA17: 17 | BB17: 17 | BC17: 21 | BD17: 21 | BE17: 21 | BF17: 21 | BG17: 26 | BH17: 25 | BI17: 25
A18: 11 | B18: AUDE | C18: 105 | D18: 102 | E18: 89 | F18: 84 | G18: 84 | H18: 79 | I18: 75 | J18: 73 | K18: 72 | L18: 72 | M18: 66 | N18: 69 | O18: 61 | P18: 60 | Q18: 64 | R18: 63 | S18: 61 | T18: 66 | U18: 65 | V18: 59 | W18: 51 | X18: 42 | Y18: 39 | Z18: 37 | AA18: 29 | AB18: 28 | AC18: 25 | AD18: 25 | AE18: 27 | AF18: 27 | AG18: 28 | AH18: 26 | AI18: 25 | AJ18: 28 | AK18: 27 | AL18: 37 | AM18: 37 | AN18: 36 | AO18: 34 | AP18: 35 | AQ18: 29 | AR18: 34 | AS18: 33 | AT18: 34 | AU18: 32 | AV18: 32 | AW18: 32 | AX18: 31 | AY18: 31 | AZ18: 31 | BA18: 31 | BB18: 31 | BC18: 31 | BD18: 33 | BE18: 33 | BF18: 33 | BG18: 33 | BH18: 33 | BI18: 34
A19: 12 | B19: AVEYRON | C19: 33 | D19: 33 | E19: 29 | F19: 27 | G19: 25 | H19: 23 | I19: 21 | J19: 21 | K19: 21 | L19: 21 | M19: 20 | N19: 20 | O19: 20 | P19: 19 | Q19: 20 | R19: 20 | S19: 23 | T19: 26 | U19: 28 | V19: 30 | W19: 30 | X19: 28 | Y19: 26 | Z19: 25 | AA19: 26 | AB19: 26 | AC19: 23 | AD19: 23 | AE19: 22 | AF19: 22 | AG19: 22 | AH19: 24 | AI19: 24 | AJ19: 26 | AK19: 25 | AL19: 26 | AM19: 27 | AN19: 28 | AO19: 28 | AP19: 27 | AQ19: 30 | AR19: 30 | AS19: 27 | AT19: 27 | AU19: 27 | AV19: 27 | AW19: 27 | AX19: 30 | AY19: 31 | AZ19: 31 | BA19: 31 | BB19: 31 | BC19: 31 | BD19: 31 | BE19: 32 | BF19: 32 | BG19: 33 | BH19: 33 | BI19: 33
... A103: 95 | B103: VAL-D'OISE | C103: 43 | D103: 42 | E103: 38 | F103: 35 | G103: 36 | H103: 40 | I103: 39 | J103: 47 | K103: 48 | L103: 53 | M103: 53 | N103: 47 | O103: 49 | P103: 47 | Q103: 47 | R103: 46 | S103: 49 | T103: 50 | U103: 50 | V103: 49 | W103: 52 | X103: 52 | Y103: 56 | Z103: 57 | AA103: 57 | AB103: 57 | AC103: 51 | AD103: 52 | AE103: 45 | AF103: 52 | AG103: 52 | AH103: 49 | AI103: 51 | AJ103: 49 | AK103: 48 | AL103: 58 | AM103: 56 | AN103: 56 | AO103: 56 | AP103: 55 | AQ103: 53 | AR103: 55 | AS103: 56 | AT103: 59 | AU103: 59 | AV103: 59 | AW103: 57 | AX103: 57 | AY103: 57 | AZ103: 58 | BA103: 60 | BB103: 78 | BC103: 76 | BD103: 78 | BE103: 78 | BF103: 77 | BG103: 79 | BH103: 78 | BI103: 78
B104: TOTAL | C104: =SUM(C8:C103) -> 5157 | D104: =SUM(D8:D103) -> 4916 | E104: =SUM(E8:E103) -> 4678 | F104: =SUM(F8:F103) -> 4475 | G104: =SUM(G8:G103) -> 4274 | H104: =SUM(H8:H103) -> 4168 | I104: =SUM(I8:I103) -> 4147 | J104: =SUM(J8:J103) -> 4228 | ... AF104: =SUM(AF8:AF103) -> 4377 | AG104: 4520 | AH104: 4644 | AI104: 4763 | AJ104: 4985 | AK104: 5113 | AL104: 5197 | AM104: 5249 | AN104: 5275 | AO104: 5273 | AP104: 5275 | AQ104: 5283 | AR104: 5317 | AS104: 5396 | AT104: 5478 | AU104: 5468 | AV104: 5468 | AW104: 5508 | AX104: 5589 | AY104: 5647 | AZ104: 5741 | BA104: 5842 | BB104: 5913 | BC104: 5983 | BD104: 6114 | BE104: 6127 | BF104: 6192 | BG104: 6298 | BH104: 6327 | BI104: 6355

Sheet fauteuils
A2: Retour au menu "Départements"
A5: Fauteuils par département
C7: 1966 | D7: 1967 | E7: 1968 | F7: 1969 | G7: 1970 | H7: 1971 | I7: 1972 | J7: 1973 | K7: 1974 | L7: 1975 | M7: 1976 | N7: 1977 | O7: 1978 | P7: 1979 | Q7: 1980 | R7: 1981 | S7: 1982 | T7: 1983 | U7: 1984 | V7: 1985 | W7: 1986 | X7: 1987 | Y7: 1988 | Z7: 1989 | AA7: 1990 | AB7: 1991 | AC7: 1992 | AD7: 1993 | AE7: 1994 | AF7: 1995 | AG7: 1996 | AH7: 1997 | AI7: 1998 | AJ7: 1999 | AK7: 2000 | AL7: 2001 | AM7: 2002 | AN7: 2003 | AO7: 2004 | AP7: 2005 | AQ7: 2006 | AR7: 2007 | AS7: 2008 | AT7: 2009 | AU7: 2010 | AV7: 2011 | AW7: 2012 | AX7: 2013 | AY7: 2014 | AZ7: 2015 | BA7: 2016 | BB7: 2017 | BC7: 2018 | BD7: 2019 | BE7: 2020 | BF7: 2021 | BG7: 2022 | BH7: 2023 | BI7: 2024
A8: 01 | B8: AIN | C8: 12962 | D8: 12754 | E8: 12256 | F8: 11677 | G8: 10703 | H8: 10313 | I8: 9913 | J8: 9631 | K8: 9261 | L8: 8933 | M8: 8726 | N8: 8289 | O8: 8667 | P8: 7957 | Q8: 7397 | R8: 8101 | S8: 8399 | T8: 7866 | U8: 8386 | V8: 8475 | W8: 8036 | X8: 8168 | Y8: 8389 | Z8: 8231 | AA8: 7518 | AB8: 7331 | AC8: 6901 | AD8: 6761 | AE8: 6299 | AF8: 6296 | AG8: 5786 | AH8: 5777 | AI8: 5741 | AJ8: 6199 | AK8: 5832 | AL8: 5779 | AM8: 5597 | AN8: 5597 | AO8: 5597 | AP8: 6039 | AQ8: 5801 | AR8: 5801 | AS8: 7739 | AT8: 6556 | AU8: 6556 | AV8: 6556 | AW8: 6346 | AX8: 6627 | AY8: 6540 | AZ8: 6438 | BA8: 6464 | BB8: 6438 | BC8: 6438 | BD8: 6817 | BE8: 6822 | BF8: 6822 | BG8: 6822 | BH8: 6691 | BI8: 6691
A9: 02 | B9: AISNE | C9: 21056 | D9: 20358 | E9: 18724 | F9: 17899 | G9: 17328 | H9: 16728 | I9: 17321 | J9: 16968 | K9: 17071 | L9: 17133 | M9: 16626 | N9: 14710 | O9: 14251 | P9: 12675 | Q9: 10385 | R9: 9472 | S9: 9160 | T9: 9015 | U9: 9005 | V9: 8738 | W9: 7700 | X9: 7977 | Y9: 7977 | Z9: 7343 | AA9: 7531 | AB9: 7531 | AC9: 7338 | AD9: 7338 | AE9: 7338 | AF9: 7399 | AG9: 8038 | AH9: 7343 | AI9: 7424 | AJ9: 7424 | AK9: 7415 | AL9: 7303 | AM9: 7303 | AN9: 7303 | AO9: 7435 | AP9: 6975 | AQ9: 6393 | AR9: 7122 | AS9: 7704 | AT9: 7122 | AU9: 7122 | AV9: 7122 | AW9: 7122 | AX9: 7122 | AY9: 7122 | AZ9: 7041 | BA9: 7122 | BB9: 6774 | BC9: 6774 | BD9: 7356 | BE9: 6774 | BF9: 6774 | BG9: 6774 | BH9: 6501 | BI9: 6444
A10: 03 | B10: ALLIER | C10: 18968 | D10: 18702 | E10: 19608 | F10: 19050 | G10: 17340 | H10: 16650 | I10: 16209 | J10: 16369 | K10: 15002 | L10: 14350 | M10: 13166 | N10: 12568 | O10: 9437 | P10: 9437 | Q10: 8742 | R10: 7739 | S10: 7693 | T10: 7693 | U10: 7590 | V10: 7989 | W10: 8216 | X10: 7899 | Y10: 7220 | Z10: 6302 | AA10: 5668 | AB10: 5533 | AC10: 5013 | AD10: 5013 | AE10: 4713 | AF10: 4713 | AG10: 3986 | AH10: 3986 | AI10: 3904 | AJ10: 3734 | AK10: 3749 | AL10: 3749 | AM10: 3749 | AN10: 3878 | AO10: 4903 | AP10: 3712 | AQ10: 3712 | AR10: 3712 | AS10: 3712 | AT10: 3712 | AU10: 2994 | AV10: 3177 | AW10: 3177 | AX10: 3177 | AY10: 3177 | AZ10: 3177 | BA10: 3177 | BB10: 3177 | BC10: 3177 | BD10: 3177 | BE10: 3177 | BF10: 3177 | BG10: 3177 | BH10: 3177 | BI10: 3177
A11: 04 | B11: ALPES-DE-HAUTE-PROVENCE | C11: 43337 | D11: 6675 | E11: 6268 | F11: 5937 | G11: 5937 | H11: 6155 | I11: 5767 | J11: 5457 | K11: 5288 | L11: 5555 | M11: 5330 | N11: 5549 | O11: 5703 | P11: 4926 | Q11: 4010 | R11: 3990 | S11: 4126 | T11: 4935 | U11: 5337 | V11: 5220 | W11: 5622 | X11: 4091 | Y11: 3995 | Z11: 3536 | AA11: 3380 | AB11: 3327 | AC11: 3283 | AD11: 3483 | AE11: 3637 | AF11: 3437 | AG11: 3327 | AH11: 3437 | AI11: 3213 | AJ11: 3182 | AK11: 3182 | AL11: 3368 | AM11: 3368 | AN11: 3439 | AO11: 3461 | AP11: 3331 | AQ11: 3763 | AR11: 3575 | AS11: 3575 | AT11: 3575 | AU11: 3575 | AV11: 3575 | AW11: 3575 | AX11: 3735 | AY11: 4177 | AZ11: 4177 | BA11: 4177 | BB11: 4157 | BC11: 4776 | BD11: 4776 | BE11: 4766 | BF11: 4766 | BG11: 4766 | BH11: 4533 | BI11: 4533
A12: 05 | B12: HAUTES-ALPES | C12: 7354 | D12: 5603 | E12: 5631 | F12: 5217 | G12: 5199 | H12: 5519 | I12: 5581 | J12: 5745 | K12: 5708 | L12: 5708 | M12: 5649 | N12: 5535 | O12: 5607 | P12: 6095 | Q12: 4938 | R12: 4190 | S12: 5068 | T12: 5681 | U12: 5794 | V12: 6133 | W12: 5996 | X12: 5975 | Y12: 5725 | Z12: 5658 | AA12: 5592 | AB12: 5432 | AC12: 5190 | AD12: 5122 | AE12: 4984 | AF12: 5133 | AG12: 5183 | AH12: 5327 | AI12: 5327 | AJ12: 5616 | AK12: 5583 | AL12: 5583 | AM12: 5583 | AN12: 5133 | AO12: 5615 | AP12: 4776 | AQ12: 4776 | AR12: 4776 | AS12: 4776 | AT12: 4776 | AU12: 4776 | AV12: 4776 | AW12: 4776 | AX12: 4776 | AY12: 4776 | AZ12: 4725 | BA12: 4814 | BB12: 4931 | BC12: 4931 | BD12: 5108 | BE12: 5108 | BF12: 4559 | BG12: 4559 | BH12: 4559 | BI12: 4421
A13: 06 | B13: ALPES-MARITIMES | C13: 5603 | D13: 42821 | E13: 42970 | F13: 42615 | G13: 41317 | H13: 41362 | I13: 39896 | J13: 34941 | K13: 34182 | L13: 32837 | M13: 33134 | N13: 31715 | O13: 31567 | P13: 31623 | Q13: 27602 | R13: 25860 | S13: 25426 | T13: 25303 | U13: 25284 | V13: 25149 | W13: 24808 | X13: 22381 | Y13: 21246 | Z13: 19736 | AA13: 17855 | AB13: 16440 | AC13: 14182 | AD13: 13960 | AE13: 13210 | AF13: 13559 | AG13: 13403 | AH13: 11871 | AI13: 12324 | AJ13: 14017 | AK13: 14614 | AL13: 15158 | AM13: 15318 | AN13: 15218 | AO13: 15234 | AP13: 15211 | AQ13: 15211 | AR13: 15051 | AS13: 15101 | AT13: 15101 | AU13: 16175 | AV13: 16175 | AW13: 16055 | AX13: 16779 | AY13: 17151 | AZ13: 18943 | BA13: 18815 | BB13: 18273 | BC13: 20464 | BD13: 19491 | BE13: 18453 | BF13: 22110 | BG13: 22684 | BH13: 22543 | BI13: 22733
A14: 07 | B14: ARDECHE | C14: 8730 | D14: 8919 | E14: 8919 | F14: 8994 | G14: 8075 | H14: 7483 | I14: 7539 | J14: 7491 | K14: 7749 | L14: 7749 | M14: 7728 | N14: 7985 | O14: 7275 | P14: 6811 | Q14: 5816 | R14: 6236 | S14: 6951 | T14: 7203 | U14: 6615 | V14: 7006 | W14: 6767 | X14: 6862 | Y14: 6748 | Z14: 6611 | AA14: 7087 | AB14: 6534 | AC14: 5591 | AD14: 5491 | AE14: 5491 | AF14: 5491 | AG14: 4741 | AH14: 4731 | AI14: 4374 | AJ14: 4678 | AK14: 4622 | AL14: 4714 | AM14: 4714 | AN14: 4714 | AO14: 4714 | AP14: 4496 | AQ14: 4686 | AR14: 4686 | AS14: 4686 | AT14: 4496 | AU14: 4686 | AV14: 4346 | AW14: 4596 | AX14: 4296 | AY14: 4296 | AZ14: 4462 | BA14: 4265 | BB14: 4473 | BC14: 4473 | BD14: 4533 | BE14: 4533 | BF14: 4587 | BG14: 4587 | BH14: 4587 | BI14: 4587
A15: 08 | B15: ARDENNES | C15: 12911 | D15: 12463 | E15: 12463 | F15: 12263 | G15: 12462 | H15: 11597 | I15: 11217 | J15: 11217 | K15: 11386 | L15: 11386 | M15: 11484 | N15: 8553 | O15: 7015 | P15: 6655 | Q15: 5966 | R15: 6056 | S15: 6056 | T15: 5677 | U15: 4944 | V15: 4944 | W15: 4164 | X15: 3460 | Y15: 3842 | Z15: 3417 | AA15: 3417 | AB15: 3417 | AC15: 2783 | AD15: 2783 | AE15: 3247 | AF15: 3247 | AG15: 3014 | AH15: 3014 | AI15: 3014 | AJ15: 3014 | AK15: 3014 | AL15: 3014 | AM15: 3014 | AN15: 3014 | AO15: 3593 | AP15: 3468 | AQ15: 3468 | AR15: 3018 | AS15: 3018 | AT15: 3468 | AU15: 3468 | AV15: 3468 | AW15: 3468 | AX15: 3468 | AY15: 3276 | AZ15: 3301 | BA15: 3276 | BB15: 3301 | BC15: 3276 | BD15: 3276 | BE15: 3276 | BF15: 3330 | BG15: 3330 | BH15: 3330 | BI15: 3330
A16: 09 | B16: ARIEGE | C16: 7121 | D16: 7202 | E16: 6802 | F16: 5375 | G16: 4625 | H16: 4625 | I16: 4482 | J16: 4482 | K16: 4652 | L16: 4312 | M16: 4029 | N16: 3582 | O16: 3590 | P16: 3670 | Q16: 3449 | R16: 3760 | S16: 3448 | T16: 3738 | U16: 3711 | V16: 3631 | W16: 3309 | X16: 3309 | Y16: 3129 | Z16: 2119 | AA16: 2641 | AB16: 2641 | AC16: 2680 | AD16: 2680 | AE16: 2869 | AF16: 2896 | AG16: 2596 | AH16: 2410 | AI16: 2454 | AJ16: 2596 | AK16: 2573 | AL16: 2759 | AM16: 2759 | AN16: 2595 | AO16: 2593 | AP16: 2580 | AQ16: 2580 | AR16: 2580 | AS16: 2580 | AT16: 2580 | AU16: 2580 | AV16: 2580 | AW16: 2580 | AX16: 2580 | AY16: 2580 | AZ16: 2580 | BA16: 2691 | BB16: 2670 | BC16: 2670 | BD16: 2670 | BE16: 2670 | BF16: 2793 | BG16: 2611 | BH16: 2611 | BI16: 2611
A17: 10 | B17: AUBE | C17: 9814 | D17: 9321 | E17: 9074 | F17: 8563 | G17: 7404 | H17: 7374 | I17: 6860 | J17: 6450 | K17: 6250 | L17: 4601 | M17: 4596 | N17: 4596 | O17: 4004 | P17: 4004 | Q17: 4746 | R17: 4746 | S17: 4751 | T17: 4751 | U17: 4597 | V17: 4416 | W17: 4316 | X17: 4570 | Y17: 3237 | Z17: 3237 | AA17: 3237 | AB17: 2990 | AC17: 3044 | AD17: 3044 | AE17: 3044 | AF17: 3044 | AG17: 3029 | AH17: 3029 | AI17: 3029 | AJ17: 3029 | AK17: 4125 | AL17: 4077 | AM17: 4077 | AN17: 4077 | AO17: 4303 | AP17: 3491 | AQ17: 3491 | AR17: 3491 | AS17: 3491 | AT17: 3491 | AU17: 3491 | AV17: 3491 | AW17: 3491 | AX17: 3491 | AY17: 3491 | AZ17: 3491 | BA17: 3491 | BB17: 3491 | BC17: 3803 | BD17: 3717 | BE17: 3717 | BF17: 3717 | BG17: 4014 | BH17: 4014 | BI17: 4014
A18: 11 | B18: AUDE | C18: 32989 | D18: 31866 | E18: 29877 | F18: 28656 | G18: 28311 | H18: 25979 | I18: 25183 | J18: 24365 | K18: 24235 | L18: 23317 | M18: 21997 | N18: 22063 | O18: 20441 | P18: 19690 | Q18: 19619 | R18: 18651 | S18: 18701 | T18: 19053 | U18: 17983 | V18: 16571 | W18: 14045 | X18: 11524 | Y18: 10211 | Z18: 9429 | AA18: 7093 | AB18: 6456 | AC18: 5456 | AD18: 5456 | AE18: 6085 | AF18: 5765 | AG18: 5284 | AH18: 4651 | AI18: 4651 | AJ18: 5645 | AK18: 5007 | AL18: 6865 | AM18: 6865 | AN18: 6865 | AO18: 6511 | AP18: 6464 | AQ18: 5261 | AR18: 6178 | AS18: 6082 | AT18: 6358 | AU18: 6158 | AV18: 5510 | AW18: 5510 | AX18: 5242 | AY18: 5242 | AZ18: 5242 | BA18: 5242 | BB18: 5242 | BC18: 5242 | BD18: 5548 | BE18: 5548 | BF18: 5474 | BG18: 5474 | BH18: 5474 | BI18: 5605
A19: 12 | B19: AVEYRON | C19: 12480 | D19: 12494 | E19: 11805 | F19: 11204 | G19: 10246 | H19: 9786 | I19: 8944 | J19: 8341 | K19: 8341 | L19: 8161 | M19: 7757 | N19: 7757 | O19: 7550 | P19: 7025 | Q19: 7078 | R19: 6251 | S19: 6605 | T19: 6450 | U19: 6536 | V19: 6608 | W19: 6591 | X19: 6037 | Y19: 5211 | Z19: 4904 | AA19: 5154 | AB19: 5304 | AC19: 4544 | AD19: 4544 | AE19: 3899 | AF19: 3899 | AG19: 3649 | AH19: 4051 | AI19: 4082 | AJ19: 4119 | AK19: 4034 | AL19: 4277 | AM19: 4277 | AN19: 4334 | AO19: 4359 | AP19: 4400 | AQ19: 4630 | AR19: 4630 | AS19: 4241 | AT19: 4241 | AU19: 4241 | AV19: 4329 | AW19: 4329 | AX19: 4689 | AY19: 4783 | AZ19: 4783 | BA19: 4783 | BB19: 4783 | BC19: 4783 | BD19: 4783 | BE19: 4881 | BF19: 4852 | BG19: 4934 | BH19: 4934 | BI19: 4934
... A103: 95 | B103: VAL-D'OISE | C103: 20381 | D103: 19867 | E103: 18270 | F103: 17166 | G103: 16138 | H103: 16415 | I103: 15700 | J103: 16061 | K103: 16263 | L103: 16804 | M103: 16883 | N103: 14005 | O103: 13712 | P103: 12677 | Q103: 12377 | R103: 12057 | S103: 12590 | T103: 12701 | U103: 12826 | V103: 12520 | W103: 12963 | X103: 12713 | Y103: 12773 | Z103: 12907 | AA103: 12876 | AB103: 12766 | AC103: 12229 | AD103: 12319 | AE103: 10352 | AF103: 12441 | AG103: 12316 | AH103: 11657 | AI103: 12169 | AJ103: 11673 | AK103: 11438 | AL103: 13419 | AM103: 12939 | AN103: 12939 | AO103: 12936 | AP103: 12305 | AQ103: 11747 | AR103: 11964 | AS103: 12161 | AT103: 12987 | AU103: 12987 | AV103: 12987 | AW103: 12557 | AX103: 12082 | AY103: 12082 | AZ103: 12427 | BA103: 12962 | BB103: 16640 | BC103: 16312 | BD103: 16532 | BE103: 16532 | BF103: 15949 | BG103: 16511 | BH103: 16427 | BI103: 16423
B104: TOTAL | C104: =SUM(C8:C103) -> 2482883 | D104: =SUM(D8:D103) -> 2364691 | E104: =SUM(E8:E103) -> 2269674 | F104: =SUM(F8:F103) -> 2176484 | G104: =SUM(G8:G103) -> 2071815 | H104: =SUM(H8:H103) -> 1974647 | I104: =SUM(I8:I103) -> 1902292 | J104: =SUM(J8:J103) -> 1844213 | ... AF104: =SUM(AF8:AF103) -> 921975 | AG104: 920177 | AH104: 938179 | AI104: 956746 | AJ104: 993307 | AK104: 1020102 | AL104: 1030938 | AM104: 1044298 | AN104: 1047703 | AO104: 1038608 | AP104: 1009515 | AQ104: 1008887 | AR104: 1012600 | AS104: 1026237 | AT104: 1043468 | AU104: 1038960 | AV104: 1038632 | AW104: 1045783 | AX104: 1059685 | AY104: 1065535 | AZ104: 1081588 | BA104: 1098281 | BB104: 1106167 | BC104: 1113563 | BD104: 1128422 | BE104: 1121514 | BF104: 1123669 | BG104: 1136960 | BH104: 1136752 | BI104: 1128689

Sheet multiplexes
A2: Retour au menu "Départements"
A5: Multiplexes (8 écrans et plus) par département
C7: 1966 | D7: 1967 | E7: 1968 | F7: 1969 | G7: 1970 | H7: 1971 | I7: 1972 | J7: 1973 | K7: 1974 | L7: 1975 | M7: 1976 | N7: 1977 | O7: 1978 | P7: 1979 | Q7: 1980 | R7: 1981 | S7: 1982 | T7: 1983 | U7: 1984 | V7: 1985 | W7: 1986 | X7: 1987 | Y7: 1988 | Z7: 1989 | AA7: 1990 | AB7: 1991 | AC7: 1992 | AD7: 1993 | AE7: 1994 | AF7: 1995 | AG7: 1996 | AH7: 1997 | AI7: 1998 | AJ7: 1999 | AK7: 2000 | AL7: 2001 | AM7: 2002 | AN7: 2003 | AO7: 2004 | AP7: 2005 | AQ7: 2006 | AR7: 2007 | AS7: 2008 | AT7: 2009 | AU7: 2010 | AV7: 2011 | AW7: 2012 | AX7: 2013 | AY7: 2014 | AZ7: 2015 | BA7: 2016 | BB7: 2017 | BC7: 2018 | BD7: 2019 | BE7: 2020 | BF7: 2021 | BG7: 2022 | BH7: 2023 | BI7: 2024
A8: 01 | B8: AIN | AS8: 1 | AT8: 1 | AU8: 1 | AV8: 1 | AW8: 1 | AX8: 1 | AY8: 1 | AZ8: 1 | BA8: 1 | BB8: 1 | BC8: 1 | BD8: 1 | BE8: 1 | BF8: 1 | BG8: 1 | BH8: 1 | BI8: 1
A9: 02 | B9: AISNE | AR9: 1 | AS9: 1 | AT9: 1 | AU9: 1 | AV9: 1 | AW9: 1 | AX9: 1 | AY9: 1 | AZ9: 1 | BA9: 1 | BB9: 1 | BC9: 1 | BD9: 1 | BE9: 1 | BF9: 1 | BG9: 1 | BH9: 1 | BI9: 1
A10: 03 | B10: ALLIER | AV10: 1 | AW10: 1 | AX10: 1 | AY10: 1 | AZ10: 1 | BA10: 1 | BB10: 1 | BC10: 1 | BD10: 1 | BE10: 1 | BF10: 1 | BG10: 1 | BH10: 1 | BI10: 1
A11: 04 | B11: ALPES-DE-HAUTE-PROVENCE | BC11: 1 | BD11: 1 | BE11: 1 | BF11: 1 | BG11: 1 | BH11: 1 | BI11: 1
A12: 05 | B12: HAUTES-ALPES
A13: 06 | B13: ALPES-MARITIMES | AC13: 1 | AD13: 1 | AE13: 1 | AF13: 1 | AG13: 1 | AH13: 1 | AI13: 1 | AJ13: 2 | AK13: 2 | AL13: 2 | AM13: 2 | AN13: 2 | AO13: 1 | AP13: 1 | AQ13: 1 | AR13: 1 | AS13: 1 | AT13: 1 | AU13: 1 | AV13: 1 | AW13: 1 | AX13: 1 | AY13: 1 | AZ13: 2 | BA13: 2 | BB13: 2 | BC13: 3 | BD13: 3 | BE13: 3 | BF13: 5 | BG13: 5 | BH13: 5 | BI13: 6
A14: 07 | B14: ARDECHE
A15: 08 | B15: ARDENNES | AO15: 1 | AP15: 1 | AQ15: 1 | AR15: 1 | AS15: 1 | AT15: 1 | AU15: 1 | AV15: 1 | AW15: 1 | AX15: 1 | AY15: 1 | AZ15: 1 | BA15: 1 | BB15: 1 | BC15: 1 | BD15: 1 | BE15: 1 | BF15: 1 | BG15: 1 | BH15: 1 | BI15: 1
A16: 09 | B16: ARIEGE
A17: 10 | B17: AUBE | AK17: 1 | AL17: 1 | AM17: 1 | AN17: 1 | AO17: 1 | AP17: 1 | AQ17: 1 | AR17: 1 | AS17: 1 | AT17: 1 | AU17: 1 | AV17: 1 | AW17: 1 | AX17: 1 | AY17: 1 | AZ17: 1 | BA17: 1 | BB17: 1 | BC17: 1 | BD17: 1 | BE17: 1 | BF17: 1 | BG17: 1 | BH17: 1 | BI17: 1
