Workbook
Name Departements: [1]établissements!$B$8:$B$103

Sheet Sommaire
A5: EQUIPEMENT ET RESULTATS DES REGIONS
A8: Mis à jour le 22 septembre 2025
B10: Définitions et sources
B11: Fiche récapitulative
A13: Ensemble du parc
B14: Etablissements
B15: Ecrans
B16: Fauteuils
B17: Multiplexes (établissements de 8 écrans et plus)
B18: Séances
B19: Entrées
B20: Recettes
B21: Recette moyenne par entrée
B22: Indice de fréquentation
B23: Taux moyen d'occupation des fauteuils
A25: Etablissements Art et Essai
B26: Etablissements
B27: Ecrans
B28: Fauteuils
B29: Séances
B30: Entrées
B31: Recettes
B32: Recette moyenne par entrée
B33: Indice de fréquentation
B34: Taux moyen d'occupation des fauteuils
A36: Etablissements de la petite exploitation
B37: Etablissements
B38: Ecrans
B39: Fauteuils
B40: Séances
B41: Entrées
B42: Recettes
B43: Recette moyenne par entrée
B44: Indice de fréquentation
B45: Taux moyen d'occupation des fauteuils
A47: Etablissements de la moyenne exploitation
B48: Etablissements
B49: Ecrans
B50: Fauteuils
B51: Séances
...

Sheet Définitions
A2: Retour au menu "Régions"
A5: Réglementation
A24: Définitions
A40: Sources

Sheet Fiche
A2: Retour au menu "Régions"
A5: Rechercher la région dans la liste suivante | E5: AUVERGNE-RHONE-ALPES
A8: REGION | B8: =E5 -> AUVERGNE-RHONE-ALPES
A10: Résultats totaux
B11: 2 | C11: 3 | D11: 4 | E11: 5 | F11: 6 | G11: 7 | H11: 8 | I11: 9 | J11: 10 | K11: 11 | L11: 12 | M11: 13 | N11: 14 | O11: 15 | P11: 16 | Q11: 17 | R11: 18 | S11: 19 | T11: 20 | U11: 21 | V11: 22 | W11: 23 | X11: 24 | Y11: 25 | Z11: 26 | AA11: 27
B12: 1966 | C12: 1967 | D12: 1968 | E12: 1969 | F12: 1970 | G12: 1971 | H12: 1972 | I12: 1973 | J12: 1974 | K12: 1975 | L12: 1976 | M12: 1977 | N12: 1978 | O12: 1979 | P12: 1980 | Q12: 1981 | R12: 1982 | S12: 1983 | T12: 1984 | U12: 1985 | V12: 1986 | W12: 1987 | X12: 1988 | Y12: 1989 | Z12: 1990 | AA12: 1991
A13: écrans | B13: =IF(VLOOKUP($B$8,écrans!$A:$CA,B$11,0)=0,"-",VLOOKUP($B$8,écrans!$A:$CA,B$11,0)) -> 586 | C13: =IF(VLOOKUP($B$8,écrans!$A:$CA,C$11,0)=0,"-",VLOOKUP($B$8,écrans!$A:$CA,C$11,0)) -> 563 | D13: =IF(VLOOKUP($B$8,écrans!$A:$CA,D$11,0)=0,"-",VLOOKUP($B$8,écrans!$A:$CA,D$11,0)) -> 543 | E13: =IF(VLOOKUP($B$8,écrans!$A:$CA,E$11,0)=0,"-",VLOOKUP($B$8,écrans!$A:$CA,E$11,0)) -> 532 | F13: =IF(VLOOKUP($B$8,écrans!$A:$CA,F$11,0)=0,"-",VLOOKUP($B$8,écrans!$A:$CA,F$11,0)) -> 506 | G13: =IF(VLOOKUP($B$8,écrans!$A:$CA,G$11,0)=0,"-",VLOOKUP($B$8,écrans!$A:$CA,G$11,0)) -> 482 | H13: =IF(VLOOKUP($B$8,écrans!$A:$CA,H$11,0)=0,"-",VLOOKUP($B$8,écrans!$A:$CA,H$11,0)) -> 472 | I13: =IF(VLOOKUP($B$8,écrans!$A:$CA,I$11,0)=0,"-",VLOOKUP($B$8,écrans!$A:$CA,I$11,0)) -> 496 | ... AA13: =IF(VLOOKUP($B$8,écrans!$A:$CA,AA$11,0)=0,"-",VLOOKUP($B$8,écrans!$A:$CA,AA$11,0)) -> 657
A14: fauteuils | B14: =IF(VLOOKUP($B$8,fauteuils!$A:$CA,B$11,0)=0,"-",VLOOKUP($B$8,fauteuils!$A:$CA,B$11,0)) -> 252759 | C14: =IF(VLOOKUP($B$8,fauteuils!$A:$CA,C$11,0)=0,"-",VLOOKUP($B$8,fauteuils!$A:$CA,C$11,0)) -> 244198 | D14: =IF(VLOOKUP($B$8,fauteuils!$A:$CA,D$11,0)=0,"-",VLOOKUP($B$8,fauteuils!$A:$CA,D$11,0)) -> 237316 | E14: =IF(VLOOKUP($B$8,fauteuils!$A:$CA,E$11,0)=0,"-",VLOOKUP($B$8,fauteuils!$A:$CA,E$11,0)) -> 232259 | F14: =IF(VLOOKUP($B$8,fauteuils!$A:$CA,F$11,0)=0,"-",VLOOKUP($B$8,fauteuils!$A:$CA,F$11,0)) -> 220107 | G14: =IF(VLOOKUP($B$8,fauteuils!$A:$CA,G$11,0)=0,"-",VLOOKUP($B$8,fauteuils!$A:$CA,G$11,0)) -> 207457 | H14: =IF(VLOOKUP($B$8,fauteuils!$A:$CA,H$11,0)=0,"-",VLOOKUP($B$8,fauteuils!$A:$CA,H$11,0)) -> 199148 | I14: =IF(VLOOKUP($B$8,fauteuils!$A:$CA,I$11,0)=0,"-",VLOOKUP($B$8,fauteuils!$A:$CA,I$11,0)) -> 197696 | ... AA14: =IF(VLOOKUP($B$8,fauteuils!$A:$CA,AA$11,0)=0,"-",VLOOKUP($B$8,fauteuils!$A:$CA,AA$11,0)) -> 131002
A15: entrées (millions) | B15: =IF(VLOOKUP($B$8,entrées!$A:$CB,B$11,0)=0,"-",VLOOKUP($B$8,entrées!$A:$CB,B$11,0)) -> 21911664 | C15: =IF(VLOOKUP($B$8,entrées!$A:$CB,C$11,0)=0,"-",VLOOKUP($B$8,entrées!$A:$CB,C$11,0)) -> 20066356 | D15: =IF(VLOOKUP($B$8,entrées!$A:$CB,D$11,0)=0,"-",VLOOKUP($B$8,entrées!$A:$CB,D$11,0)) -> 19271896 | E15: =IF(VLOOKUP($B$8,entrées!$A:$CB,E$11,0)=0,"-",VLOOKUP($B$8,entrées!$A:$CB,E$11,0)) -> 17968172 | F15: =IF(VLOOKUP($B$8,entrées!$A:$CB,F$11,0)=0,"-",VLOOKUP($B$8,entrées!$A:$CB,F$11,0)) -> 18166206 | G15: =IF(VLOOKUP($B$8,entrées!$A:$CB,G$11,0)=0,"-",VLOOKUP($B$8,entrées!$A:$CB,G$11,0)) -> 17492467 | H15: =IF(VLOOKUP($B$8,entrées!$A:$CB,H$11,0)=0,"-",VLOOKUP($B$8,entrées!$A:$CB,H$11,0)) -> 18196735 | I15: =IF(VLOOKUP($B$8,entrées!$A:$CB,I$11,0)=0,"-",VLOOKUP($B$8,entrées!$A:$CB,I$11,0)) -> 17775071 | ... AA15: =IF(VLOOKUP($B$8,entrées!$A:$CB,AA$11,0)=0,"-",VLOOKUP($B$8,entrées!$A:$CB,AA$11,0)) -> 14062986
A16: recettes (M€) | B16: =IF(VLOOKUP($B$8,recettes!$A:$CB,B$11,0)=0,"-",VLOOKUP($B$8,recettes!$A:$CB,B$11,0)) -> 11430226 | C16: =IF(VLOOKUP($B$8,recettes!$A:$CB,C$11,0)=0,"-",VLOOKUP($B$8,recettes!$A:$CB,C$11,0)) -> 11478893 | D16: =IF(VLOOKUP($B$8,recettes!$A:$CB,D$11,0)=0,"-",VLOOKUP($B$8,recettes!$A:$CB,D$11,0)) -> 11365514 | E16: =IF(VLOOKUP($B$8,recettes!$A:$CB,E$11,0)=0,"-",VLOOKUP($B$8,recettes!$A:$CB,E$11,0)) -> 11956259 | F16: =IF(VLOOKUP($B$8,recettes!$A:$CB,F$11,0)=0,"-",VLOOKUP($B$8,recettes!$A:$CB,F$11,0)) -> 13135298 | G16: =IF(VLOOKUP($B$8,recettes!$A:$CB,G$11,0)=0,"-",VLOOKUP($B$8,recettes!$A:$CB,G$11,0)) -> 14105633 | H16: =IF(VLOOKUP($B$8,recettes!$A:$CB,H$11,0)=0,"-",VLOOKUP($B$8,recettes!$A:$CB,H$11,0)) -> 16212012 | I16: =IF(VLOOKUP($B$8,recettes!$A:$CB,I$11,0)=0,"-",VLOOKUP($B$8,recettes!$A:$CB,I$11,0)) -> 17734351 | ... AA16: =IF(VLOOKUP($B$8,recettes!$A:$CB,AA$11,0)=0,"-",VLOOKUP($B$8,recettes!$A:$CB,AA$11,0)) -> 69716322
A17: RME (€) | B17: =IF(VLOOKUP($B$8,RME!$A:$CB,B$11,0)=0,"-",VLOOKUP($B$8,RME!$A:$CB,B$11,0)) -> 0.52165028 | C17: =IF(VLOOKUP($B$8,RME!$A:$CB,C$11,0)=0,"-",VLOOKUP($B$8,RME!$A:$CB,C$11,0)) -> 0.57204672 | D17: =IF(VLOOKUP($B$8,RME!$A:$CB,D$11,0)=0,"-",VLOOKUP($B$8,RME!$A:$CB,D$11,0)) -> 0.58974551 | E17: =IF(VLOOKUP($B$8,RME!$A:$CB,E$11,0)=0,"-",VLOOKUP($B$8,RME!$A:$CB,E$11,0)) -> 0.66541321 | F17: =IF(VLOOKUP($B$8,RME!$A:$CB,F$11,0)=0,"-",VLOOKUP($B$8,RME!$A:$CB,F$11,0)) -> 0.72306226 | G17: =IF(VLOOKUP($B$8,RME!$A:$CB,G$11,0)=0,"-",VLOOKUP($B$8,RME!$A:$CB,G$11,0)) -> 0.80638326 | H17: =IF(VLOOKUP($B$8,RME!$A:$CB,H$11,0)=0,"-",VLOOKUP($B$8,RME!$A:$CB,H$11,0)) -> 0.89092971 | I17: =IF(VLOOKUP($B$8,RME!$A:$CB,I$11,0)=0,"-",VLOOKUP($B$8,RME!$A:$CB,I$11,0)) -> 0.99770917 | ... AA17: =IF(VLOOKUP($B$8,RME!$A:$CB,AA$11,0)=0,"-",VLOOKUP($B$8,RME!$A:$CB,AA$11,0)) -> 4.957434
A18: indice de fréquentation | B18: =IF(VLOOKUP($B$8,'indice de fréquentation'!$A:$CB,B$11,0)=0,"-",VLOOKUP($B$8,'indice de fréquentation'!$A:$CB,B$11,0)) -> 3.8407838 | C18: =IF(VLOOKUP($B$8,'indice de fréquentation'!$A:$CB,C$11,0)=0,"-",VLOOKUP($B$8,'indice de fréquentation'!$A:$CB,C$11,0)) -> 3.5173292 | D18: =IF(VLOOKUP($B$8,'indice de fréquentation'!$A:$CB,D$11,0)=0,"-",VLOOKUP($B$8,'indice de fréquentation'!$A:$CB,D$11,0)) -> 3.3780723 | E18: =IF(VLOOKUP($B$8,'indice de fréquentation'!$A:$CB,E$11,0)=0,"-",VLOOKUP($B$8,'indice de fréquentation'!$A:$CB,E$11,0)) -> 3.1495492 | F18: =IF(VLOOKUP($B$8,'indice de fréquentation'!$A:$CB,F$11,0)=0,"-",VLOOKUP($B$8,'indice de fréquentation'!$A:$CB,F$11,0)) -> 3.1842616 | G18: =IF(VLOOKUP($B$8,'indice de fréquentation'!$A:$CB,G$11,0)=0,"-",VLOOKUP($B$8,'indice de fréquentation'!$A:$CB,G$11,0)) -> 3.0661653 | H18: =IF(VLOOKUP($B$8,'indice de fréquentation'!$A:$CB,H$11,0)=0,"-",VLOOKUP($B$8,'indice de fréquentation'!$A:$CB,H$11,0)) -> 2.9776223 | I18: =IF(VLOOKUP($B$8,'indice de fréquentation'!$A:$CB,I$11,0)=0,"-",VLOOKUP($B$8,'indice de fréquentation'!$A:$CB,I$11,0)) -> 2.9086233 | ... AA18: =IF(VLOOKUP($B$8,'indice de fréquentation'!$A:$CB,AA$11,0)=0,"-",VLOOKUP($B$8,'indice de fréquentation'!$A:$CB,AA$11,0)) -> 2.1077885
B19: 28 | C19: 29 | D19: 30 | E19: 31 | F19: 32 | G19: 33 | H19: 34 | I19: 35 | J19: 36 | K19: 37 | L19: 38 | M19: 39 | N19: 40 | O19: 41 | P19: 42 | Q19: 43 | R19: 44 | S19: 45 | T19: 46 | U19: 47 | V19: 48 | W19: 49 | X19: 50 | Y19: 51 | Z19: 52 | AA19: 53 | AB19: 54 | AC19: 55 | AD19: 56 | AE19: 57 | AF19: 58 | AG19: 59
B20: 1992 | C20: 1993 | D20: 1994 | E20: 1995 | F20: 1996 | G20: 1997 | H20: 1998 | I20: 1999 | J20: 2000 | K20: 2001 | L20: 2002 | M20: 2003 | N20: 2004 | O20: 2005 | P20: 2006 | Q20: 2007 | R20: 2008 | S20: 2009 | T20: 2010 | U20: 2011 | V20: 2012 | W20: 2013 | X20: 2014 | Y20: 2015 | Z20: 2016 | AA20: 2017 | AB20: 2018 | AC20: 2019 | AD20: 2020 | AE20: 2021 | AF20: 2022 | AG20: 2023
A21: établissements | B21: =IF(VLOOKUP($B$8,établissements!$A:$CA,B$19,0)=0,"-",VLOOKUP($B$8,établissements!$A:$CA,B$19,0)) -> 343 | C21: =IF(VLOOKUP($B$8,établissements!$A:$CA,C$19,0)=0,"-",VLOOKUP($B$8,établissements!$A:$CA,C$19,0)) -> 336 | D21: =IF(VLOOKUP($B$8,établissements!$A:$CA,D$19,0)=0,"-",VLOOKUP($B$8,établissements!$A:$CA,D$19,0)) -> 335 | E21: =IF(VLOOKUP($B$8,établissements!$A:$CA,E$19,0)=0,"-",VLOOKUP($B$8,établissements!$A:$CA,E$19,0)) -> 342 | F21: =IF(VLOOKUP($B$8,établissements!$A:$CA,F$19,0)=0,"-",VLOOKUP($B$8,établissements!$A:$CA,F$19,0)) -> 343 | G21: =IF(VLOOKUP($B$8,établissements!$A:$CA,G$19,0)=0,"-",VLOOKUP($B$8,établissements!$A:$CA,G$19,0)) -> 347 | H21: =IF(VLOOKUP($B$8,établissements!$A:$CA,H$19,0)=0,"-",VLOOKUP($B$8,établissements!$A:$CA,H$19,0)) -> 349 | I21: =IF(VLOOKUP($B$8,établissements!$A:$CA,I$19,0)=0,"-",VLOOKUP($B$8,établissements!$A:$CA,I$19,0)) -> 359 | ... AG21: =IF(VLOOKUP($B$8,établissements!$A:$CA,AG$19,0)=0,"-",VLOOKUP($B$8,établissements!$A:$CA,AG$19,0)) -> 322
A22: écrans | B22: =IF(VLOOKUP($B$8,écrans!$A:$CA,B$19,0)=0,"-",VLOOKUP($B$8,écrans!$A:$CA,B$19,0)) -> 630 | C22: =IF(VLOOKUP($B$8,écrans!$A:$CA,C$19,0)=0,"-",VLOOKUP($B$8,écrans!$A:$CA,C$19,0)) -> 624 | D22: =IF(VLOOKUP($B$8,écrans!$A:$CA,D$19,0)=0,"-",VLOOKUP($B$8,écrans!$A:$CA,D$19,0)) -> 630 | E22: =IF(VLOOKUP($B$8,écrans!$A:$CA,E$19,0)=0,"-",VLOOKUP($B$8,écrans!$A:$CA,E$19,0)) -> 637 | F22: =IF(VLOOKUP($B$8,écrans!$A:$CA,F$19,0)=0,"-",VLOOKUP($B$8,écrans!$A:$CA,F$19,0)) -> 640 | G22: =IF(VLOOKUP($B$8,écrans!$A:$CA,G$19,0)=0,"-",VLOOKUP($B$8,écrans!$A:$CA,G$19,0)) -> 677 | H22: =IF(VLOOKUP($B$8,écrans!$A:$CA,H$19,0)=0,"-",VLOOKUP($B$8,écrans!$A:$CA,H$19,0)) -> 680 | I22: =IF(VLOOKUP($B$8,écrans!$A:$CA,I$19,0)=0,"-",VLOOKUP($B$8,écrans!$A:$CA,I$19,0)) -> 692 | ... AG22: =IF(VLOOKUP($B$8,écrans!$A:$CA,AG$19,0)=0,"-",VLOOKUP($B$8,écrans!$A:$CA,AG$19,0)) -> 864
A23: fauteuils | B23: =IF(VLOOKUP($B$8,fauteuils!$A:$CA,B$19,0)=0,"-",VLOOKUP($B$8,fauteuils!$A:$CA,B$19,0)) -> 122219 | C23: =IF(VLOOKUP($B$8,fauteuils!$A:$CA,C$19,0)=0,"-",VLOOKUP($B$8,fauteuils!$A:$CA,C$19,0)) -> 120906 | D23: =IF(VLOOKUP($B$8,fauteuils!$A:$CA,D$19,0)=0,"-",VLOOKUP($B$8,fauteuils!$A:$CA,D$19,0)) -> 119541 | E23: =IF(VLOOKUP($B$8,fauteuils!$A:$CA,E$19,0)=0,"-",VLOOKUP($B$8,fauteuils!$A:$CA,E$19,0)) -> 121694 | F23: =IF(VLOOKUP($B$8,fauteuils!$A:$CA,F$19,0)=0,"-",VLOOKUP($B$8,fauteuils!$A:$CA,F$19,0)) -> 115060 | G23: =IF(VLOOKUP($B$8,fauteuils!$A:$CA,G$19,0)=0,"-",VLOOKUP($B$8,fauteuils!$A:$CA,G$19,0)) -> 123633 | H23: =IF(VLOOKUP($B$8,fauteuils!$A:$CA,H$19,0)=0,"-",VLOOKUP($B$8,fauteuils!$A:$CA,H$19,0)) -> 121874 | I23: =IF(VLOOKUP($B$8,fauteuils!$A:$CA,I$19,0)=0,"-",VLOOKUP($B$8,fauteuils!$A:$CA,I$19,0)) -> 123578 | ... AG23: =IF(VLOOKUP($B$8,fauteuils!$A:$CA,AG$19,0)=0,"-",VLOOKUP($B$8,fauteuils!$A:$CA,AG$19,0)) -> 147116
A24: multiplexes (8 écrans et plus) | B24: =IF(VLOOKUP($B$8,multiplexes!$A:$CA,B$19,0)=0,"-",VLOOKUP($B$8,multiplexes!$A:$CA,B$19,0)) -> 4 | C24: =IF(VLOOKUP($B$8,multiplexes!$A:$CA,C$19,0)=0,"-",VLOOKUP($B$8,multiplexes!$A:$CA,C$19,0)) -> 4 | D24: =IF(VLOOKUP($B$8,multiplexes!$A:$CA,D$19,0)=0,"-",VLOOKUP($B$8,multiplexes!$A:$CA,D$19,0)) -> 4 | E24: =IF(VLOOKUP($B$8,multiplexes!$A:$CA,E$19,0)=0,"-",VLOOKUP($B$8,multiplexes!$A:$CA,E$19,0)) -> 4 | F24: =IF(VLOOKUP($B$8,multiplexes!$A:$CA,F$19,0)=0,"-",VLOOKUP($B$8,multiplexes!$A:$CA,F$19,0)) -> 4 | G24: =IF(VLOOKUP($B$8,multiplexes!$A:$CA,G$19,0)=0,"-",VLOOKUP($B$8,multiplexes!$A:$CA,G$19,0)) -> 7 | H24: =IF(VLOOKUP($B$8,multiplexes!$A:$CA,H$19,0)=0,"-",VLOOKUP($B$8,multiplexes!$A:$CA,H$19,0)) -> 7 | I24: =IF(VLOOKUP($B$8,multiplexes!$A:$CA,I$19,0)=0,"-",VLOOKUP($B$8,multiplexes!$A:$CA,I$19,0)) -> 7 | ... AG24: =IF(VLOOKUP($B$8,multiplexes!$A:$CA,AG$19,0)=0,"-",VLOOKUP($B$8,multiplexes!$A:$CA,AG$19,0)) -> 30
A25: séances (milliers) | B25: =IF(VLOOKUP($B$8,séances!$A:$CA,B$19,0)=0,"-",VLOOKUP($B$8,séances!$A:$CA,B$19,0)) -> 476935 | C25: =IF(VLOOKUP($B$8,séances!$A:$CA,C$19,0)=0,"-",VLOOKUP($B$8,séances!$A:$CA,C$19,0)) -> 486367 | D25: =IF(VLOOKUP($B$8,séances!$A:$CA,D$19,0)=0,"-",VLOOKUP($B$8,séances!$A:$CA,D$19,0)) -> 493463 | E25: =IF(VLOOKUP($B$8,séances!$A:$CA,E$19,0)=0,"-",VLOOKUP($B$8,séances!$A:$CA,E$19,0)) -> 486970 | F25: =IF(VLOOKUP($B$8,séances!$A:$CA,F$19,0)=0,"-",VLOOKUP($B$8,séances!$A:$CA,F$19,0)) -> 520139 | G25: =IF(VLOOKUP($B$8,séances!$A:$CA,G$19,0)=0,"-",VLOOKUP($B$8,séances!$A:$CA,G$19,0)) -> 553251 | H25: =IF(VLOOKUP($B$8,séances!$A:$CA,H$19,0)=0,"-",VLOOKUP($B$8,séances!$A:$CA,H$19,0)) -> 587411 | I25: =IF(VLOOKUP($B$8,séances!$A:$CA,I$19,0)=0,"-",VLOOKUP($B$8,séances!$A:$CA,I$19,0)) -> 594707 | ... AG25: =IF(VLOOKUP($B$8,séances!$A:$CA,AG$19,0)=0,"-",VLOOKUP($B$8,séances!$A:$CA,AG$19,0)) -> 1001529
A26: entrées (millions) | B26: =IF(VLOOKUP($B$8,entrées!$A:$CB,B$19,0)=0,"-",VLOOKUP($B$8,entrées!$A:$CB,B$19,0)) -> 13724983 | C26: =IF(VLOOKUP($B$8,entrées!$A:$CB,C$19,0)=0,"-",VLOOKUP($B$8,entrées!$A:$CB,C$19,0)) -> 15757406 | D26: =IF(VLOOKUP($B$8,entrées!$A:$CB,D$19,0)=0,"-",VLOOKUP($B$8,entrées!$A:$CB,D$19,0)) -> 14609116 | E26: =IF(VLOOKUP($B$8,entrées!$A:$CB,E$19,0)=0,"-",VLOOKUP($B$8,entrées!$A:$CB,E$19,0)) -> 15480249 | F26: =IF(VLOOKUP($B$8,entrées!$A:$CB,F$19,0)=0,"-",VLOOKUP($B$8,entrées!$A:$CB,F$19,0)) -> 16451686 | G26: =IF(VLOOKUP($B$8,entrées!$A:$CB,G$19,0)=0,"-",VLOOKUP($B$8,entrées!$A:$CB,G$19,0)) -> 17725886 | H26: =IF(VLOOKUP($B$8,entrées!$A:$CB,H$19,0)=0,"-",VLOOKUP($B$8,entrées!$A:$CB,H$19,0)) -> 20856788 | I26: =IF(VLOOKUP($B$8,entrées!$A:$CB,I$19,0)=0,"-",VLOOKUP($B$8,entrées!$A:$CB,I$19,0)) -> 18401197 | ... AG26: =IF(VLOOKUP($B$8,entrées!$A:$CB,AG$19,0)=0,"-",VLOOKUP($B$8,entrées!$A:$CB,AG$19,0)) -> 21902929
A27: recettes (M€) | B27: =IF(VLOOKUP($B$8,recettes!$A:$CB,B$19,0)=0,"-",VLOOKUP($B$8,recettes!$A:$CB,B$19,0)) -> 69573632 | C27: =IF(VLOOKUP($B$8,recettes!$A:$CB,C$19,0)=0,"-",VLOOKUP($B$8,recettes!$A:$CB,C$19,0)) -> 79332115 | D27: =IF(VLOOKUP($B$8,recettes!$A:$CB,D$19,0)=0,"-",VLOOKUP($B$8,recettes!$A:$CB,D$19,0)) -> 73424213 | E27: =IF(VLOOKUP($B$8,recettes!$A:$CB,E$19,0)=0,"-",VLOOKUP($B$8,recettes!$A:$CB,E$19,0)) -> 77613595 | F27: =IF(VLOOKUP($B$8,recettes!$A:$CB,F$19,0)=0,"-",VLOOKUP($B$8,recettes!$A:$CB,F$19,0)) -> 82934199 | G27: =IF(VLOOKUP($B$8,recettes!$A:$CB,G$19,0)=0,"-",VLOOKUP($B$8,recettes!$A:$CB,G$19,0)) -> 89786369 | H27: =IF(VLOOKUP($B$8,recettes!$A:$CB,H$19,0)=0,"-",VLOOKUP($B$8,recettes!$A:$CB,H$19,0)) -> 1.0945098e+08 | I27: =IF(VLOOKUP($B$8,recettes!$A:$CB,I$19,0)=0,"-",VLOOKUP($B$8,recettes!$A:$CB,I$19,0)) -> 96202321 | ... AG27: =IF(VLOOKUP($B$8,recettes!$A:$CB,AG$19,0)=0,"-",VLOOKUP($B$8,recettes!$A:$CB,AG$19,0)) -> 1.6231314e+08
A28: RME (€) | B28: =IF(VLOOKUP($B$8,RME!$A:$CB,B$19,0)=0,"-",VLOOKUP($B$8,RME!$A:$CB,B$19,0)) -> 5.0691233 | C28: =IF(VLOOKUP($B$8,RME!$A:$CB,C$19,0)=0,"-",VLOOKUP($B$8,RME!$A:$CB,C$19,0)) -> 5.0345923 | D28: =IF(VLOOKUP($B$8,RME!$A:$CB,D$19,0)=0,"-",VLOOKUP($B$8,RME!$A:$CB,D$19,0)) -> 5.0259176 | E28: =IF(VLOOKUP($B$8,RME!$A:$CB,E$19,0)=0,"-",VLOOKUP($B$8,RME!$A:$CB,E$19,0)) -> 5.0137175 | F28: =IF(VLOOKUP($B$8,RME!$A:$CB,F$19,0)=0,"-",VLOOKUP($B$8,RME!$A:$CB,F$19,0)) -> 5.0410759 | G28: =IF(VLOOKUP($B$8,RME!$A:$CB,G$19,0)=0,"-",VLOOKUP($B$8,RME!$A:$CB,G$19,0)) -> 5.0652684 | H28: =IF(VLOOKUP($B$8,RME!$A:$CB,H$19,0)=0,"-",VLOOKUP($B$8,RME!$A:$CB,H$19,0)) -> 5.247739 | I28: =IF(VLOOKUP($B$8,RME!$A:$CB,I$19,0)=0,"-",VLOOKUP($B$8,RME!$A:$CB,I$19,0)) -> 5.2280469 | ... AG28: =IF(VLOOKUP($B$8,RME!$A:$CB,AG$19,0)=0,"-",VLOOKUP($B$8,RME!$A:$CB,AG$19,0)) -> 7.4105677
A29: indice de fréquentation | B29: =IF(VLOOKUP($B$8,'indice de fréquentation'!$A:$CB,B$19,0)=0,"-",VLOOKUP($B$8,'indice de fréquentation'!$A:$CB,B$19,0)) -> 2.057128 | C29: =IF(VLOOKUP($B$8,'indice de fréquentation'!$A:$CB,C$19,0)=0,"-",VLOOKUP($B$8,'indice de fréquentation'!$A:$CB,C$19,0)) -> 2.3617516 | D29: =IF(VLOOKUP($B$8,'indice de fréquentation'!$A:$CB,D$19,0)=0,"-",VLOOKUP($B$8,'indice de fréquentation'!$A:$CB,D$19,0)) -> 2.1896436 | E29: =IF(VLOOKUP($B$8,'indice de fréquentation'!$A:$CB,E$19,0)=0,"-",VLOOKUP($B$8,'indice de fréquentation'!$A:$CB,E$19,0)) -> 2.2260015 | F29: =IF(VLOOKUP($B$8,'indice de fréquentation'!$A:$CB,F$19,0)=0,"-",VLOOKUP($B$8,'indice de fréquentation'!$A:$CB,F$19,0)) -> 2.3656905 | G29: =IF(VLOOKUP($B$8,'indice de fréquentation'!$A:$CB,G$19,0)=0,"-",VLOOKUP($B$8,'indice de fréquentation'!$A:$CB,G$19,0)) -> 2.5489157 | H29: =IF(VLOOKUP($B$8,'indice de fréquentation'!$A:$CB,H$19,0)=0,"-",VLOOKUP($B$8,'indice de fréquentation'!$A:$CB,H$19,0)) -> 2.9991276 | I29: =IF(VLOOKUP($B$8,'indice de fréquentation'!$A:$CB,I$19,0)=0,"-",VLOOKUP($B$8,'indice de fréquentation'!$A:$CB,I$19,0)) -> 2.6460228 | ... AG29: =IF(VLOOKUP($B$8,'indice de fréquentation'!$A:$CB,AG$19,0)=0,"-",VLOOKUP($B$8,'indice de fréquentation'!$A:$CB,AG$19,0)) -> 2.6547377
A30: taux d'occupation des fauteuils (%) | B30: =IF(VLOOKUP($B$8,'taux d''occupation des fauteuils'!$A:$CA,B$19,0)=0,"-",VLOOKUP($B$8,'taux d''occupation des fauteuils'!$A:$CA,B$19,0)) -> 16.170276 | C30: =IF(VLOOKUP($B$8,'taux d''occupation des fauteuils'!$A:$CA,C$19,0)=0,"-",VLOOKUP($B$8,'taux d''occupation des fauteuils'!$A:$CA,C$19,0)) -> 17.955469 | D30: =IF(VLOOKUP($B$8,'taux d''occupation des fauteuils'!$A:$CA,D$19,0)=0,"-",VLOOKUP($B$8,'taux d''occupation des fauteuils'!$A:$CA,D$19,0)) -> 16.668852 | E30: =IF(VLOOKUP($B$8,'taux d''occupation des fauteuils'!$A:$CA,E$19,0)=0,"-",VLOOKUP($B$8,'taux d''occupation des fauteuils'!$A:$CA,E$19,0)) -> 17.958504 | F30: =IF(VLOOKUP($B$8,'taux d''occupation des fauteuils'!$A:$CA,F$19,0)=0,"-",VLOOKUP($B$8,'taux d''occupation des fauteuils'!$A:$CA,F$19,0)) -> 17.874886 | G30: =IF(VLOOKUP($B$8,'taux d''occupation des fauteuils'!$A:$CA,G$19,0)=0,"-",VLOOKUP($B$8,'taux d''occupation des fauteuils'!$A:$CA,G$19,0)) -> 17.867771 | H30: =IF(VLOOKUP($B$8,'taux d''occupation des fauteuils'!$A:$CA,H$19,0)=0,"-",VLOOKUP($B$8,'taux d''occupation des fauteuils'!$A:$CA,H$19,0)) -> 19.769925 | I30: =IF(VLOOKUP($B$8,'taux d''occupation des fauteuils'!$A:$CA,I$19,0)=0,"-",VLOOKUP($B$8,'taux d''occupation des fauteuils'!$A:$CA,I$19,0)) -> 17.028203 | ... AG30: =IF(VLOOKUP($B$8,'taux d''occupation des fauteuils'!$A:$CA,AG$19,0)=0,"-",VLOOKUP($B$8,'taux d''occupation des fauteuils'!$A:$CA,AG$19,0)) -> 12.61859
A33: Résultats des établissements Art et Essai
B34: 2 | C34: 3 | D34: 4 | E34: 5 | F34: 6 | G34: 7 | H34: 8 | I34: 9 | J34: 10 | K34: 11 | L34: 12 | M34: 13 | N34: 14 | O34: 15 | P34: 16 | Q34: 17 | R34: 18 | S34: 19 | T34: 20 | U34: 21 | V34: 22 | W34: 23
B35: 2002 | C35: 2003 | D35: 2004 | E35: 2005 | F35: 2006 | G35: 2007 | H35: 2008 | I35: 2009 | J35: 2010 | K35: 2011 | L35: 2012 | M35: 2013 | N35: 2014 | O35: 2015 | P35: 2016 | Q35: 2017 | R35: 2018 | S35: 2019 | T35: 2020 | U35: 2021 | V35: 2022 | W35: 2023
A36: établissements | B36: =IF(VLOOKUP($B$8,étabAE!$A:$BA,B$34,0)=0,"-",VLOOKUP($B$8,étabAE!$A:$BA,B$34,0)) -> 143 | C36: =IF(VLOOKUP($B$8,étabAE!$A:$BA,C$34,0)=0,"-",VLOOKUP($B$8,étabAE!$A:$BA,C$34,0)) -> 146 | D36: =IF(VLOOKUP($B$8,étabAE!$A:$BA,D$34,0)=0,"-",VLOOKUP($B$8,étabAE!$A:$BA,D$34,0)) -> 154 | E36: =IF(VLOOKUP($B$8,étabAE!$A:$BA,E$34,0)=0,"-",VLOOKUP($B$8,étabAE!$A:$BA,E$34,0)) -> 152 | F36: =IF(VLOOKUP($B$8,étabAE!$A:$BA,F$34,0)=0,"-",VLOOKUP($B$8,étabAE!$A:$BA,F$34,0)) -> 154 | G36: =IF(VLOOKUP($B$8,étabAE!$A:$BA,G$34,0)=0,"-",VLOOKUP($B$8,étabAE!$A:$BA,G$34,0)) -> 157 | H36: =IF(VLOOKUP($B$8,étabAE!$A:$BA,H$34,0)=0,"-",VLOOKUP($B$8,étabAE!$A:$BA,H$34,0)) -> 161 | I36: =IF(VLOOKUP($B$8,étabAE!$A:$BA,I$34,0)=0,"-",VLOOKUP($B$8,étabAE!$A:$BA,I$34,0)) -> 156 | ... W36: =IF(VLOOKUP($B$8,étabAE!$A:$BA,W$34,0)=0,"-",VLOOKUP($B$8,étabAE!$A:$BA,W$34,0)) -> 185
A37: écrans | B37: =IF(VLOOKUP($B$8,écransAE!$A:$BA,B$34,0)=0,"-",VLOOKUP($B$8,écransAE!$A:$BA,B$34,0)) -> 262 | C37: =IF(VLOOKUP($B$8,écransAE!$A:$BA,C$34,0)=0,"-",VLOOKUP($B$8,écransAE!$A:$BA,C$34,0)) -> 264 | D37: =IF(VLOOKUP($B$8,écransAE!$A:$BA,D$34,0)=0,"-",VLOOKUP($B$8,écransAE!$A:$BA,D$34,0)) -> 289 | E37: =IF(VLOOKUP($B$8,écransAE!$A:$BA,E$34,0)=0,"-",VLOOKUP($B$8,écransAE!$A:$BA,E$34,0)) -> 286 | F37: =IF(VLOOKUP($B$8,écransAE!$A:$BA,F$34,0)=0,"-",VLOOKUP($B$8,écransAE!$A:$BA,F$34,0)) -> 292 | G37: =IF(VLOOKUP($B$8,écransAE!$A:$BA,G$34,0)=0,"-",VLOOKUP($B$8,écransAE!$A:$BA,G$34,0)) -> 296 | H37: =IF(VLOOKUP($B$8,écransAE!$A:$BA,H$34,0)=0,"-",VLOOKUP($B$8,écransAE!$A:$BA,H$34,0)) -> 290 | I37: =IF(VLOOKUP($B$8,écransAE!$A:$BA,I$34,0)=0,"-",VLOOKUP($B$8,écransAE!$A:$BA,I$34,0)) -> 297 | ... W37: =IF(VLOOKUP($B$8,écransAE!$A:$BA,W$34,0)=0,"-",VLOOKUP($B$8,écransAE!$A:$BA,W$34,0)) -> 406
A38: fauteuils | B38: =IF(VLOOKUP($B$8,fauteuilsAE!$A:$BB,B$34,0)=0,"-",VLOOKUP($B$8,fauteuilsAE!$A:$BB,B$34,0)) -> 43983 | C38: =IF(VLOOKUP($B$8,fauteuilsAE!$A:$BB,C$34,0)=0,"-",VLOOKUP($B$8,fauteuilsAE!$A:$BB,C$34,0)) -> 45223 | D38: =IF(VLOOKUP($B$8,fauteuilsAE!$A:$BB,D$34,0)=0,"-",VLOOKUP($B$8,fauteuilsAE!$A:$BB,D$34,0)) -> 49000 | E38: =IF(VLOOKUP($B$8,fauteuilsAE!$A:$BB,E$34,0)=0,"-",VLOOKUP($B$8,fauteuilsAE!$A:$BB,E$34,0)) -> 45947 | F38: =IF(VLOOKUP($B$8,fauteuilsAE!$A:$BB,F$34,0)=0,"-",VLOOKUP($B$8,fauteuilsAE!$A:$BB,F$34,0)) -> 48347 | G38: =IF(VLOOKUP($B$8,fauteuilsAE!$A:$BB,G$34,0)=0,"-",VLOOKUP($B$8,fauteuilsAE!$A:$BB,G$34,0)) -> 48032 | H38: =IF(VLOOKUP($B$8,fauteuilsAE!$A:$BB,H$34,0)=0,"-",VLOOKUP($B$8,fauteuilsAE!$A:$BB,H$34,0)) -> 47336 | I38: =IF(VLOOKUP($B$8,fauteuilsAE!$A:$BB,I$34,0)=0,"-",VLOOKUP($B$8,fauteuilsAE!$A:$BB,I$34,0)) -> 48498 | ... W38: =IF(VLOOKUP($B$8,fauteuilsAE!$A:$BB,W$34,0)=0,"-",VLOOKUP($B$8,fauteuilsAE!$A:$BB,W$34,0)) -> 63176
A39: séances (milliers) | B39: =IF(VLOOKUP($B$8,'séances AE'!$A:$BB,B$34,0)=0,"-",VLOOKUP($B$8,'séances AE'!$A:$BB,B$34,0)) -> 219005 | C39: =IF(VLOOKUP($B$8,'séances AE'!$A:$BB,C$34,0)=0,"-",VLOOKUP($B$8,'séances AE'!$A:$BB,C$34,0)) -> 218719 | D39: =IF(VLOOKUP($B$8,'séances AE'!$A:$BB,D$34,0)=0,"-",VLOOKUP($B$8,'séances AE'!$A:$BB,D$34,0)) -> 245659 | E39: =IF(VLOOKUP($B$8,'séances AE'!$A:$BB,E$34,0)=0,"-",VLOOKUP($B$8,'séances AE'!$A:$BB,E$34,0)) -> 245246 | F39: =IF(VLOOKUP($B$8,'séances AE'!$A:$BB,F$34,0)=0,"-",VLOOKUP($B$8,'séances AE'!$A:$BB,F$34,0)) -> 255577 | G39: =IF(VLOOKUP($B$8,'séances AE'!$A:$BB,G$34,0)=0,"-",VLOOKUP($B$8,'séances AE'!$A:$BB,G$34,0)) -> 255434 | H39: =IF(VLOOKUP($B$8,'séances AE'!$A:$BB,H$34,0)=0,"-",VLOOKUP($B$8,'séances AE'!$A:$BB,H$34,0)) -> 245404 | I39: =IF(VLOOKUP($B$8,'séances AE'!$A:$BB,I$34,0)=0,"-",VLOOKUP($B$8,'séances AE'!$A:$BB,I$34,0)) -> 265398 | ... W39: =IF(VLOOKUP($B$8,'séances AE'!$A:$BB,W$34,0)=0,"-",VLOOKUP($B$8,'séances AE'!$A:$BB,W$34,0)) -> 438720
A40: entrées (millions) | B40: =IF(VLOOKUP($B$8,entréesAE!$A:$BB,B$34,0)=0,"-",VLOOKUP($B$8,entréesAE!$A:$BB,B$34,0)) -> 6212021 | C40: =IF(VLOOKUP($B$8,entréesAE!$A:$BB,C$34,0)=0,"-",VLOOKUP($B$8,entréesAE!$A:$BB,C$34,0)) -> 5885761 | D40: =IF(VLOOKUP($B$8,entréesAE!$A:$BB,D$34,0)=0,"-",VLOOKUP($B$8,entréesAE!$A:$BB,D$34,0)) -> 7507173 | E40: =IF(VLOOKUP($B$8,entréesAE!$A:$BB,E$34,0)=0,"-",VLOOKUP($B$8,entréesAE!$A:$BB,E$34,0)) -> 6319761 | F40: =IF(VLOOKUP($B$8,entréesAE!$A:$BB,F$34,0)=0,"-",VLOOKUP($B$8,entréesAE!$A:$BB,F$34,0)) -> 7249463 | G40: =IF(VLOOKUP($B$8,entréesAE!$A:$BB,G$34,0)=0,"-",VLOOKUP($B$8,entréesAE!$A:$BB,G$34,0)) -> 6820146 | H40: =IF(VLOOKUP($B$8,entréesAE!$A:$BB,H$34,0)=0,"-",VLOOKUP($B$8,entréesAE!$A:$BB,H$34,0)) -> 6312534 | I40: =IF(VLOOKUP($B$8,entréesAE!$A:$BB,I$34,0)=0,"-",VLOOKUP($B$8,entréesAE!$A:$BB,I$34,0)) -> 6830222 | ... W40: =IF(VLOOKUP($B$8,entréesAE!$A:$BB,W$34,0)=0,"-",VLOOKUP($B$8,entréesAE!$A:$BB,W$34,0)) -> 9569897
A41: recettes (M€) | B41: =IF(VLOOKUP($B$8,recettesAE!$A:$BB,B$34,0)=0,"-",VLOOKUP($B$8,recettesAE!$A:$BB,B$34,0)) -> 30500300 | C41: =IF(VLOOKUP($B$8,recettesAE!$A:$BB,C$34,0)=0,"-",VLOOKUP($B$8,recettesAE!$A:$BB,C$34,0)) -> 29114928 | D41: =IF(VLOOKUP($B$8,recettesAE!$A:$BB,D$34,0)=0,"-",VLOOKUP($B$8,recettesAE!$A:$BB,D$34,0)) -> 38250058 | E41: =IF(VLOOKUP($B$8,recettesAE!$A:$BB,E$34,0)=0,"-",VLOOKUP($B$8,recettesAE!$A:$BB,E$34,0)) -> 32208680 | F41: =IF(VLOOKUP($B$8,recettesAE!$A:$BB,F$34,0)=0,"-",VLOOKUP($B$8,recettesAE!$A:$BB,F$34,0)) -> 37582187 | G41: =IF(VLOOKUP($B$8,recettesAE!$A:$BB,G$34,0)=0,"-",VLOOKUP($B$8,recettesAE!$A:$BB,G$34,0)) -> 35741167 | H41: =IF(VLOOKUP($B$8,recettesAE!$A:$BB,H$34,0)=0,"-",VLOOKUP($B$8,recettesAE!$A:$BB,H$34,0)) -> 32816361 | I41: =IF(VLOOKUP($B$8,recettesAE!$A:$BB,I$34,0)=0,"-",VLOOKUP($B$8,recettesAE!$A:$BB,I$34,0)) -> 36490896 | ... W41: =IF(VLOOKUP($B$8,recettesAE!$A:$BB,W$34,0)=0,"-",VLOOKUP($B$8,recettesAE!$A:$BB,W$34,0)) -> 57922442
A42: RME (€) | B42: =IF(VLOOKUP($B$8,RMEAE!$A:$BB,B$34,0)=0,"-",VLOOKUP($B$8,RMEAE!$A:$BB,B$34,0)) -> 4.9098836 | C42: =IF(VLOOKUP($B$8,RMEAE!$A:$BB,C$34,0)=0,"-",VLOOKUP($B$8,RMEAE!$A:$BB,C$34,0)) -> 4.9466718 | D42: =IF(VLOOKUP($B$8,RMEAE!$A:$BB,D$34,0)=0,"-",VLOOKUP($B$8,RMEAE!$A:$BB,D$34,0)) -> 5.0951347 | E42: =IF(VLOOKUP($B$8,RMEAE!$A:$BB,E$34,0)=0,"-",VLOOKUP($B$8,RMEAE!$A:$BB,E$34,0)) -> 5.0965029 | F42: =IF(VLOOKUP($B$8,RMEAE!$A:$BB,F$34,0)=0,"-",VLOOKUP($B$8,RMEAE!$A:$BB,F$34,0)) -> 5.1841339 | G42: =IF(VLOOKUP($B$8,RMEAE!$A:$BB,G$34,0)=0,"-",VLOOKUP($B$8,RMEAE!$A:$BB,G$34,0)) -> 5.2405281 | H42: =IF(VLOOKUP($B$8,RMEAE!$A:$BB,H$34,0)=0,"-",VLOOKUP($B$8,RMEAE!$A:$BB,H$34,0)) -> 5.1986034 | I42: =IF(VLOOKUP($B$8,RMEAE!$A:$BB,I$34,0)=0,"-",VLOOKUP($B$8,RMEAE!$A:$BB,I$34,0)) -> 5.3425637 | ... W42: =IF(VLOOKUP($B$8,RMEAE!$A:$BB,W$34,0)=0,"-",VLOOKUP($B$8,RMEAE!$A:$BB,W$34,0)) -> 6.0525669
A43: indice de fréquentation | B43: =IF(VLOOKUP($B$8,'indice de fréquentationAE'!$A:$BB,B$34,0)=0,"-",VLOOKUP($B$8,'indice de fréquentationAE'!$A:$BB,B$34,0)) -> 0.89326523 | C43: =IF(VLOOKUP($B$8,'indice de fréquentationAE'!$A:$BB,C$34,0)=0,"-",VLOOKUP($B$8,'indice de fréquentationAE'!$A:$BB,C$34,0)) -> 0.84635027 | D43: =IF(VLOOKUP($B$8,'indice de fréquentationAE'!$A:$BB,D$34,0)=0,"-",VLOOKUP($B$8,'indice de fréquentationAE'!$A:$BB,D$34,0)) -> 1.0203802 | E43: =IF(VLOOKUP($B$8,'indice de fréquentationAE'!$A:$BB,E$34,0)=0,"-",VLOOKUP($B$8,'indice de fréquentationAE'!$A:$BB,E$34,0)) -> 0.85898635 | F43: =IF(VLOOKUP($B$8,'indice de fréquentationAE'!$A:$BB,F$34,0)=0,"-",VLOOKUP($B$8,'indice de fréquentationAE'!$A:$BB,F$34,0)) -> 0.8786689 | G43: =IF(VLOOKUP($B$8,'indice de fréquentationAE'!$A:$BB,G$34,0)=0,"-",VLOOKUP($B$8,'indice de fréquentationAE'!$A:$BB,G$34,0)) -> 0.82663366 | H43: =IF(VLOOKUP($B$8,'indice de fréquentationAE'!$A:$BB,H$34,0)=0,"-",VLOOKUP($B$8,'indice de fréquentationAE'!$A:$BB,H$34,0)) -> 0.76510871 | I43: =IF(VLOOKUP($B$8,'indice de fréquentationAE'!$A:$BB,I$34,0)=0,"-",VLOOKUP($B$8,'indice de fréquentationAE'!$A:$BB,I$34,0)) -> 0.82785492 | ... W43: =IF(VLOOKUP($B$8,'indice de fréquentationAE'!$A:$BB,W$34,0)=0,"-",VLOOKUP($B$8,'indice de fréquentationAE'!$A:$BB,W$34,0)) -> 1.1599164
A44: taux d'occupation des fauteuils (%) | B44: =IF(VLOOKUP($B$8,tmofAE!$A:$BB,B$34,0)=0,"-",VLOOKUP($B$8,tmofAE!$A:$BB,B$34,0)) -> 17.430645 | C44: =IF(VLOOKUP($B$8,tmofAE!$A:$BB,C$34,0)=0,"-",VLOOKUP($B$8,tmofAE!$A:$BB,C$34,0)) -> 15.964701 | D44: =IF(VLOOKUP($B$8,tmofAE!$A:$BB,D$34,0)=0,"-",VLOOKUP($B$8,tmofAE!$A:$BB,D$34,0)) -> 18.353814 | E44: =IF(VLOOKUP($B$8,tmofAE!$A:$BB,E$34,0)=0,"-",VLOOKUP($B$8,tmofAE!$A:$BB,E$34,0)) -> 16.048051 | F44: =IF(VLOOKUP($B$8,tmofAE!$A:$BB,F$34,0)=0,"-",VLOOKUP($B$8,tmofAE!$A:$BB,F$34,0)) -> 17.067429 | G44: =IF(VLOOKUP($B$8,tmofAE!$A:$BB,G$34,0)=0,"-",VLOOKUP($B$8,tmofAE!$A:$BB,G$34,0)) -> 16.374702 | H44: =IF(VLOOKUP($B$8,tmofAE!$A:$BB,H$34,0)=0,"-",VLOOKUP($B$8,tmofAE!$A:$BB,H$34,0)) -> 15.722567 | I44: =IF(VLOOKUP($B$8,tmofAE!$A:$BB,I$34,0)=0,"-",VLOOKUP($B$8,tmofAE!$A:$BB,I$34,0)) -> 15.829398 | ... W44: =IF(VLOOKUP($B$8,tmofAE!$A:$BB,W$34,0)=0,"-",VLOOKUP($B$8,tmofAE!$A:$BB,W$34,0)) -> 13.988221
A47: Résultats des établissements à moins de 80 000 entrées annuelles
B48: 2 | C48: 3 | D48: 4 | E48: 5 | F48: 6 | G48: 7 | H48: 8 | I48: 9 | J48: 10 | K48: 11 | L48: 12 | M48: 13 | N48: 14 | O48: 15 | P48: 16 | Q48: 17 | R48: 18 | S48: 19 | T48: 20 | U48: 21
B49: 2004 | C49: 2005 | D49: 2006 | E49: 2007 | F49: 2008 | G49: 2009 | H49: 2010 | I49: 2011 | J49: 2012 | K49: 2013 | L49: 2014 | M49: 2015 | N49: 2016 | O49: 2017 | P49: 2018 | Q49: 2019 | R49: 2020 | S49: 2021 | T49: 2022 | U49: 2023
A50: établissements | B50: =IF(VLOOKUP($B$8,étabP!$A:$BB,B$48,0)=0,"-",VLOOKUP($B$8,étabP!$A:$BB,B$48,0)) -> 258 | C50: =IF(VLOOKUP($B$8,étabP!$A:$BB,C$48,0)=0,"-",VLOOKUP($B$8,étabP!$A:$BB,C$48,0)) -> 262 | D50: =IF(VLOOKUP($B$8,étabP!$A:$BB,D$48,0)=0,"-",VLOOKUP($B$8,étabP!$A:$BB,D$48,0)) -> 263 | E50: =IF(VLOOKUP($B$8,étabP!$A:$BB,E$48,0)=0,"-",VLOOKUP($B$8,étabP!$A:$BB,E$48,0)) -> 259 | F50: =IF(VLOOKUP($B$8,étabP!$A:$BB,F$48,0)=0,"-",VLOOKUP($B$8,étabP!$A:$BB,F$48,0)) -> 268 | G50: =IF(VLOOKUP($B$8,étabP!$A:$BB,G$48,0)=0,"-",VLOOKUP($B$8,étabP!$A:$BB,G$48,0)) -> 271 | H50: =IF(VLOOKUP($B$8,étabP!$A:$BB,H$48,0)=0,"-",VLOOKUP($B$8,étabP!$A:$BB,H$48,0)) -> 266 | I50: =IF(VLOOKUP($B$8,étabP!$A:$BB,I$48,0)=0,"-",VLOOKUP($B$8,étabP!$A:$BB,I$48,0)) -> 263 | ... U50: =IF(VLOOKUP($B$8,étabP!$A:$BB,U$48,0)=0,"-",VLOOKUP($B$8,étabP!$A:$BB,U$48,0)) -> 243
...

Sheet établissements
A2: Retour au menu "Régions"
A5: Etablissements par région
B7: 1966 | C7: 1967 | D7: 1968 | E7: 1969 | F7: 1970 | G7: 1971 | H7: 1972 | I7: 1973 | J7: 1974 | K7: 1975 | L7: 1976 | M7: 1977 | N7: 1978 | O7: 1979 | P7: 1980 | Q7: 1981 | R7: 1982 | S7: 1983 | T7: 1984 | U7: 1985 | V7: 1986 | W7: 1987 | X7: 1988 | Y7: 1989 | Z7: 1990 | AA7: 1991 | AB7: 1992 | AC7: 1993 | AD7: 1994 | AE7: 1995 | AF7: 1996 | AG7: 1997 | AH7: 1998 | AI7: 1999 | AJ7: 2000 | AK7: 2001 | AL7: 2002 | AM7: 2003 | AN7: 2004 | AO7: 2005 | AP7: 2006 | AQ7: 2007 | AR7: 2008 | AS7: 2009 | AT7: 2010 | AU7: 2011 | AV7: 2012 | AW7: 2013 | AX7: 2014 | AY7: 2015 | AZ7: 2016 | BA7: 2017 | BB7: 2018 | BC7: 2019 | BD7: 2020 | BE7: 2021 | BF7: 2022 | BG7: 2023 | BH7: 2024
A8: AUVERGNE-RHONE-ALPES | AB8: 343 | AC8: 336 | AD8: 335 | AE8: 342 | AF8: 343 | AG8: 347 | AH8: 349 | AI8: 359 | AJ8: 353 | AK8: 352 | AL8: 350 | AM8: 349 | AN8: 346 | AO8: 339 | AP8: 343 | AQ8: 345 | AR8: 350 | AS8: 349 | AT8: 344 | AU8: 339 | AV8: 334 | AW8: 321 | AX8: 316 | AY8: 324 | AZ8: 324 | BA8: 325 | BB8: 324 | BC8: 323 | BD8: 322 | BE8: 320 | BF8: 323 | BG8: 322 | BH8: 320
A9: BOURGOGNE-FRANCHE-COMTE | AB9: 106 | AC9: 105 | AD9: 103 | AE9: 106 | AF9: 103 | AG9: 102 | AH9: 103 | AI9: 107 | AJ9: 108 | AK9: 107 | AL9: 108 | AM9: 101 | AN9: 100 | AO9: 100 | AP9: 96 | AQ9: 97 | AR9: 100 | AS9: 100 | AT9: 98 | AU9: 98 | AV9: 97 | AW9: 98 | AX9: 94 | AY9: 91 | AZ9: 91 | BA9: 92 | BB9: 92 | BC9: 91 | BD9: 92 | BE9: 90 | BF9: 92 | BG9: 91 | BH9: 91
A10: BRETAGNE | AB10: 136 | AC10: 135 | AD10: 137 | AE10: 136 | AF10: 137 | AG10: 134 | AH10: 131 | AI10: 135 | AJ10: 134 | AK10: 133 | AL10: 128 | AM10: 127 | AN10: 127 | AO10: 131 | AP10: 126 | AQ10: 125 | AR10: 127 | AS10: 127 | AT10: 124 | AU10: 125 | AV10: 123 | AW10: 123 | AX10: 122 | AY10: 123 | AZ10: 122 | BA10: 119 | BB10: 119 | BC10: 121 | BD10: 121 | BE10: 118 | BF10: 120 | BG10: 120 | BH10: 120
A11: CENTRE-VAL DE LOIRE | AB11: 64 | AC11: 64 | AD11: 64 | AE11: 64 | AF11: 67 | AG11: 66 | AH11: 70 | AI11: 68 | AJ11: 67 | AK11: 68 | AL11: 67 | AM11: 67 | AN11: 64 | AO11: 67 | AP11: 68 | AQ11: 67 | AR11: 70 | AS11: 67 | AT11: 68 | AU11: 69 | AV11: 69 | AW11: 69 | AX11: 67 | AY11: 68 | AZ11: 68 | BA11: 68 | BB11: 69 | BC11: 70 | BD11: 70 | BE11: 73 | BF11: 73 | BG11: 74 | BH11: 73
A12: CORSE | AB12: 21 | AC12: 20 | AD12: 20 | AE12: 22 | AF12: 23 | AG12: 25 | AH12: 24 | AI12: 25 | AJ12: 23 | AK12: 22 | AL12: 22 | AM12: 22 | AN12: 22 | AO12: 19 | AP12: 19 | AQ12: 20 | AR12: 20 | AS12: 21 | AT12: 21 | AU12: 21 | AV12: 19 | AW12: 18 | AX12: 20 | AY12: 21 | AZ12: 22 | BA12: 21 | BB12: 19 | BC12: 20 | BD12: 17 | BE12: 18 | BF12: 19 | BG12: 20 | BH12: 19
A13: GRAND EST | AB13: 140 | AC13: 130 | AD13: 131 | AE13: 132 | AF13: 134 | AG13: 134 | AH13: 131 | AI13: 133 | AJ13: 130 | AK13: 127 | AL13: 124 | AM13: 125 | AN13: 121 | AO13: 119 | AP13: 117 | AQ13: 117 | AR13: 117 | AS13: 118 | AT13: 118 | AU13: 118 | AV13: 118 | AW13: 119 | AX13: 121 | AY13: 122 | AZ13: 122 | BA13: 121 | BB13: 120 | BC13: 119 | BD13: 121 | BE13: 122 | BF13: 127 | BG13: 126 | BH13: 124
A14: HAUTS-DE-FRANCE | AB14: 130 | AC14: 128 | AD14: 131 | AE14: 131 | AF14: 135 | AG14: 133 | AH14: 136 | AI14: 133 | AJ14: 132 | AK14: 128 | AL14: 129 | AM14: 126 | AN14: 122 | AO14: 119 | AP14: 117 | AQ14: 114 | AR14: 114 | AS14: 114 | AT14: 110 | AU14: 111 | AV14: 111 | AW14: 113 | AX14: 113 | AY14: 116 | AZ14: 117 | BA14: 119 | BB14: 118 | BC14: 119 | BD14: 120 | BE14: 120 | BF14: 121 | BG14: 122 | BH14: 120
A15: ILE-DE-FRANCE | AB15: 314 | AC15: 316 | AD15: 311 | AE15: 313 | AF15: 315 | AG15: 313 | AH15: 316 | AI15: 315 | AJ15: 313 | AK15: 318 | AL15: 320 | AM15: 318 | AN15: 315 | AO15: 311 | AP15: 307 | AQ15: 304 | AR15: 307 | AS15: 305 | AT15: 304 | AU15: 304 | AV15: 309 | AW15: 310 | AX15: 308 | AY15: 307 | AZ15: 311 | BA15: 311 | BB15: 311 | BC15: 312 | BD15: 310 | BE15: 304 | BF15: 311 | BG15: 312 | BH15: 314
A16: NORMANDIE | AB16: 108 | AC16: 106 | AD16: 105 | AE16: 103 | AF16: 104 | AG16: 105 | AH16: 107 | AI16: 110 | AJ16: 112 | AK16: 107 | AL16: 106 | AM16: 107 | AN16: 107 | AO16: 105 | AP16: 105 | AQ16: 104 | AR16: 105 | AS16: 109 | AT16: 105 | AU16: 105 | AV16: 106 | AW16: 103 | AX16: 103 | AY16: 102 | AZ16: 102 | BA16: 102 | BB16: 103 | BC16: 103 | BD16: 104 | BE16: 103 | BF16: 104 | BG16: 104 | BH16: 103
A17: NOUVELLE AQUITAINE | AB17: 250 | AC17: 240 | AD17: 238 | AE17: 236 | AF17: 238 | AG17: 235 | AH17: 238 | AI17: 242 | AJ17: 244 | AK17: 242 | AL17: 242 | AM17: 242 | AN17: 239 | AO17: 239 | AP17: 236 | AQ17: 236 | AR17: 232 | AS17: 232 | AT17: 232 | AU17: 225 | AV17: 225 | AW17: 221 | AX17: 223 | AY17: 226 | AZ17: 232 | BA17: 233 | BB17: 229 | BC17: 229 | BD17: 229 | BE17: 228 | BF17: 230 | BG17: 229 | BH17: 230
A18: OCCITANIE | AB18: 212 | AC18: 211 | AD18: 218 | AE18: 217 | AF18: 216 | AG18: 220 | AH18: 215 | AI18: 222 | AJ18: 220 | AK18: 223 | AL18: 222 | AM18: 222 | AN18: 216 | AO18: 215 | AP18: 216 | AQ18: 217 | AR18: 216 | AS18: 214 | AT18: 213 | AU18: 212 | AV18: 215 | AW18: 214 | AX18: 210 | AY18: 209 | AZ18: 209 | BA18: 212 | BB18: 213 | BC18: 216 | BD18: 216 | BE18: 215 | BF18: 218 | BG18: 218 | BH18: 217
A19: PAYS DE LA LOIRE | AB19: 136 | AC19: 134 | AD19: 134 | AE19: 134 | AF19: 138 | AG19: 139 | AH19: 136 | AI19: 135 | AJ19: 135 | AK19: 134 | AL19: 134 | AM19: 134 | AN19: 131 | AO19: 128 | AP19: 129 | AQ19: 128 | AR19: 128 | AS19: 129 | AT19: 128 | AU19: 128 | AV19: 127 | AW19: 126 | AX19: 126 | AY19: 127 | AZ19: 127 | BA19: 126 | BB19: 125 | BC19: 126 | BD19: 125 | BE19: 124 | BF19: 124 | BG19: 124 | BH19: 125
A20: PROVENCE-ALPES-COTE D'AZUR | AB20: 180 | AC20: 185 | AD20: 179 | AE20: 183 | AF20: 188 | AG20: 189 | AH20: 190 | AI20: 189 | AJ20: 189 | AK20: 191 | AL20: 191 | AM20: 189 | AN20: 191 | AO20: 188 | AP20: 187 | AQ20: 182 | AR20: 186 | AS20: 188 | AT20: 185 | AU20: 179 | AV20: 182 | AW20: 192 | AX20: 197 | AY20: 197 | AZ20: 197 | BA20: 197 | BB20: 198 | BC20: 196 | BD20: 194 | BE20: 195 | BF20: 199 | BG20: 196 | BH20: 197
A21: TOTAL | B21: =SUM(B8:B20) -> 0 | C21: =SUM(C8:C20) -> 0 | D21: =SUM(D8:D20) -> 0 | E21: =SUM(E8:E20) -> 0 | F21: =SUM(F8:F20) -> 0 | G21: =SUM(G8:G20) -> 0 | H21: =SUM(H8:H20) -> 0 | I21: =SUM(I8:I20) -> 0 | ... AA21: =SUM(AA8:AA20) -> 0 | AB21: 2140 | AC21: 2110 | AD21: 2106 | AE21: 2119 | AF21: 2141 | AG21: 2142 | AH21: 2146 | AI21: 2173 | AJ21: 2160 | AK21: 2152 | AL21: 2143 | AM21: 2129 | AN21: 2101 | AO21: 2080 | AP21: 2066 | AQ21: 2056 | AR21: 2072 | AS21: 2073 | AT21: 2050 | AU21: 2034 | AV21: 2035 | AW21: 2027 | AX21: 2020 | AY21: 2033 | AZ21: 2044 | BA21: 2046 | BB21: 2040 | BC21: 2045 | BD21: 2041 | BE21: 2030 | BF21: 2061 | BG21: 2058 | BH21: 2053

Sheet écrans
A2: Retour au menu "Régions"
A5: Ecrans par région
B7: 1966 | C7: 1967 | D7: 1968 | E7: 1969 | F7: 1970 | G7: 1971 | H7: 1972 | I7: 1973 | J7: 1974 | K7: 1975 | L7: 1976 | M7: 1977 | N7: 1978 | O7: 1979 | P7: 1980 | Q7: 1981 | R7: 1982 | S7: 1983 | T7: 1984 | U7: 1985 | V7: 1986 | W7: 1987 | X7: 1988 | Y7: 1989 | Z7: 1990 | AA7: 1991 | AB7: 1992 | AC7: 1993 | AD7: 1994 | AE7: 1995 | AF7: 1996 | AG7: 1997 | AH7: 1998 | AI7: 1999 | AJ7: 2000 | AK7: 2001 | AL7: 2002 | AM7: 2003 | AN7: 2004 | AO7: 2005 | AP7: 2006 | AQ7: 2007 | AR7: 2008 | AS7: 2009 | AT7: 2010 | AU7: 2011 | AV7: 2012 | AW7: 2013 | AX7: 2014 | AY7: 2015 | AZ7: 2016 | BA7: 2017 | BB7: 2018 | BC7: 2019 | BD7: 2020 | BE7: 2021 | BF7: 2022 | BG7: 2023 | BH7: 2024
A8: AUVERGNE-RHONE-ALPES | B8: 586 | C8: 563 | D8: 543 | E8: 532 | F8: 506 | G8: 482 | H8: 472 | I8: 496 | J8: 498 | K8: 517 | L8: 540 | M8: 545 | N8: 547 | O8: 548 | P8: 573 | Q8: 624 | R8: 669 | S8: 693 | T8: 736 | U8: 742 | V8: 743 | W8: 728 | X8: 706 | Y8: 692 | Z8: 674 | AA8: 657 | AB8: 630 | AC8: 624 | AD8: 630 | AE8: 637 | AF8: 640 | AG8: 677 | AH8: 680 | AI8: 692 | AJ8: 733 | AK8: 750 | AL8: 758 | AM8: 758 | AN8: 742 | AO8: 728 | AP8: 746 | AQ8: 752 | AR8: 773 | AS8: 782 | AT8: 773 | AU8: 780 | AV8: 797 | AW8: 784 | AX8: 777 | AY8: 796 | AZ8: 802 | BA8: 827 | BB8: 833 | BC8: 830 | BD8: 831 | BE8: 840 | BF8: 852 | BG8: 864 | BH8: 860
A9: BOURGOGNE-FRANCHE-COMTE | B9: 245 | C9: 235 | D9: 227 | E9: 217 | F9: 214 | G9: 208 | H9: 211 | I9: 205 | J9: 203 | K9: 205 | L9: 215 | M9: 208 | N9: 208 | O9: 206 | P9: 211 | Q9: 241 | R9: 250 | S9: 269 | T9: 284 | U9: 289 | V9: 281 | W9: 272 | X9: 255 | Y9: 247 | Z9: 240 | AA9: 230 | AB9: 219 | AC9: 218 | AD9: 217 | AE9: 223 | AF9: 222 | AG9: 222 | AH9: 225 | AI9: 245 | AJ9: 254 | AK9: 253 | AL9: 267 | AM9: 250 | AN9: 247 | AO9: 256 | AP9: 249 | AQ9: 255 | AR9: 259 | AS9: 259 | AT9: 256 | AU9: 257 | AV9: 255 | AW9: 265 | AX9: 262 | AY9: 267 | AZ9: 266 | BA9: 268 | BB9: 278 | BC9: 280 | BD9: 280 | BE9: 272 | BF9: 283 | BG9: 281 | BH9: 277
A10: BRETAGNE | B10: 215 | C10: 214 | D10: 206 | E10: 205 | F10: 205 | G10: 192 | H10: 190 | I10: 190 | J10: 190 | K10: 192 | L10: 189 | M10: 189 | N10: 194 | O10: 201 | P10: 200 | Q10: 206 | R10: 226 | S10: 233 | T10: 247 | U10: 248 | V10: 250 | W10: 240 | X10: 241 | Y10: 236 | Z10: 231 | AA10: 231 | AB10: 221 | AC10: 219 | AD10: 224 | AE10: 225 | AF10: 230 | AG10: 227 | AH10: 225 | AI10: 252 | AJ10: 247 | AK10: 246 | AL10: 232 | AM10: 244 | AN10: 253 | AO10: 280 | AP10: 274 | AQ10: 276 | AR10: 291 | AS10: 290 | AT10: 287 | AU10: 291 | AV10: 294 | AW10: 293 | AX10: 294 | AY10: 299 | AZ10: 299 | BA10: 298 | BB10: 302 | BC10: 318 | BD10: 327 | BE10: 326 | BF10: 328 | BG10: 335 | BH10: 338
A11: CENTRE-VAL DE LOIRE | B11: 166 | C11: 153 | D11: 152 | E11: 147 | F11: 136 | G11: 133 | H11: 132 | I11: 131 | J11: 127 | K11: 128 | L11: 126 | M11: 137 | N11: 144 | O11: 142 | P11: 151 | Q11: 150 | R11: 147 | S11: 164 | T11: 167 | U11: 177 | V11: 172 | W11: 163 | X11: 167 | Y11: 160 | Z11: 152 | AA11: 144 | AB11: 136 | AC11: 136 | AD11: 138 | AE11: 141 | AF11: 152 | AG11: 147 | AH11: 163 | AI11: 156 | AJ11: 169 | AK11: 168 | AL11: 165 | AM11: 171 | AN11: 157 | AO11: 167 | AP11: 167 | AQ11: 167 | AR11: 196 | AS11: 188 | AT11: 191 | AU11: 192 | AV11: 192 | AW11: 195 | AX11: 193 | AY11: 194 | AZ11: 196 | BA11: 193 | BB11: 202 | BC11: 204 | BD11: 205 | BE11: 211 | BF11: 211 | BG11: 214 | BH11: 213
A12: CORSE | B12: 13 | C12: 13 | D12: 14 | E12: 14 | F12: 14 | G12: 14 | H12: 17 | I12: 16 | J12: 16 | K12: 19 | L12: 21 | M12: 23 | N12: 23 | O12: 24 | P12: 23 | Q12: 28 | R12: 32 | S12: 36 | T12: 36 | U12: 37 | V12: 39 | W12: 39 | X12: 36 | Y12: 35 | Z12: 34 | AA12: 35 | AB12: 31 | AC12: 30 | AD12: 29 | AE12: 31 | AF12: 32 | AG12: 34 | AH12: 33 | AI12: 34 | AJ12: 32 | AK12: 31 | AL12: 32 | AM12: 31 | AN12: 31 | AO12: 28 | AP12: 28 | AQ12: 29 | AR12: 28 | AS12: 29 | AT12: 29 | AU12: 28 | AV12: 23 | AW12: 22 | AX12: 29 | AY12: 32 | AZ12: 33 | BA12: 32 | BB12: 29 | BC12: 33 | BD12: 30 | BE12: 31 | BF12: 34 | BG12: 35 | BH12: 34
A13: GRAND EST | B13: 543 | C13: 514 | D13: 482 | E13: 451 | F13: 407 | G13: 376 | H13: 358 | I13: 366 | J13: 359 | K13: 353 | L13: 358 | M13: 340 | N13: 339 | O13: 339 | P13: 335 | Q13: 351 | R13: 349 | S13: 362 | T13: 392 | U13: 403 | V13: 393 | W13: 366 | X13: 349 | Y13: 343 | Z13: 327 | AA13: 321 | AB13: 308 | AC13: 287 | AD13: 293 | AE13: 311 | AF13: 312 | AG13: 322 | AH13: 321 | AI13: 362 | AJ13: 397 | AK13: 391 | AL13: 389 | AM13: 391 | AN13: 397 | AO13: 405 | AP13: 414 | AQ13: 416 | AR13: 413 | AS13: 416 | AT13: 415 | AU13: 424 | AV13: 431 | AW13: 432 | AX13: 434 | AY13: 440 | AZ13: 445 | BA13: 449 | BB13: 448 | BC13: 456 | BD13: 460 | BE13: 471 | BF13: 488 | BG13: 487 | BH13: 485
A14: HAUTS-DE-FRANCE | B14: 544 | C14: 481 | D14: 425 | E14: 391 | F14: 362 | G14: 342 | H14: 343 | I14: 342 | J14: 339 | K14: 342 | L14: 352 | M14: 334 | N14: 330 | O14: 337 | P14: 328 | Q14: 325 | R14: 320 | S14: 325 | T14: 345 | U14: 353 | V14: 353 | W14: 363 | X14: 338 | Y14: 325 | Z14: 300 | AA14: 297 | AB14: 300 | AC14: 296 | AD14: 304 | AE14: 311 | AF14: 353 | AG14: 348 | AH14: 352 | AI14: 382 | AJ14: 392 | AK14: 395 | AL14: 398 | AM14: 390 | AN14: 393 | AO14: 383 | AP14: 386 | AQ14: 388 | AR14: 387 | AS14: 395 | AT14: 388 | AU14: 393 | AV14: 388 | AW14: 398 | AX14: 411 | AY14: 420 | AZ14: 421 | BA14: 431 | BB14: 431 | BC14: 435 | BD14: 443 | BE14: 450 | BF14: 454 | BG14: 455 | BH14: 460
A15: ILE-DE-FRANCE | B15: 669 | C15: 641 | D15: 627 | E15: 612 | F15: 613 | G15: 638 | H15: 683 | I15: 732 | J15: 747 | K15: 781 | L15: 808 | M15: 815 | N15: 827 | O15: 856 | P15: 851 | Q15: 888 | R15: 892 | S15: 913 | T15: 923 | U15: 911 | V15: 895 | W15: 877 | X15: 857 | Y15: 815 | Z15: 787 | AA15: 773 | AB15: 765 | AC15: 772 | AD15: 774 | AE15: 786 | AF15: 809 | AG15: 833 | AH15: 874 | AI15: 888 | AJ15: 884 | AK15: 921 | AL15: 959 | AM15: 971 | AN15: 999 | AO15: 995 | AP15: 991 | AQ15: 988 | AR15: 996 | AS15: 1005 | AT15: 1005 | AU15: 1005 | AV15: 1015 | AW15: 1054 | AX15: 1076 | AY15: 1073 | AZ15: 1106 | BA15: 1124 | BB15: 1147 | BC15: 1185 | BD15: 1182 | BE15: 1167 | BF15: 1195 | BG15: 1196 | BH15: 1202
A16: NORMANDIE | B16: 271 | C16: 264 | D16: 261 | E16: 243 | F16: 233 | G16: 229 | H16: 220 | I16: 213 | J16: 210 | K16: 211 | L16: 219 | M16: 231 | N16: 229 | O16: 244 | P16: 231 | Q16: 228 | R16: 233 | S16: 242 | T16: 257 | U16: 269 | V16: 268 | W16: 257 | X16: 242 | Y16: 230 | Z16: 230 | AA16: 223 | AB16: 218 | AC16: 216 | AD16: 215 | AE16: 220 | AF16: 222 | AG16: 223 | AH16: 236 | AI16: 264 | AJ16: 274 | AK16: 274 | AL16: 270 | AM16: 273 | AN16: 275 | AO16: 262 | AP16: 263 | AQ16: 264 | AR16: 265 | AS16: 298 | AT16: 284 | AU16: 284 | AV16: 280 | AW16: 280 | AX16: 280 | AY16: 277 | AZ16: 278 | BA16: 284 | BB16: 288 | BC16: 292 | BD16: 293 | BE16: 291 | BF16: 300 | BG16: 303 | BH16: 302
A17: NOUVELLE AQUITAINE | B17: 525 | C17: 508 | D17: 479 | E17: 459 | F17: 445 | G17: 436 | H17: 428 | I17: 438 | J17: 428 | K17: 420 | L17: 417 | M17: 434 | N17: 433 | O17: 434 | P17: 449 | Q17: 474 | R17: 496 | S17: 522 | T17: 557 | U17: 563 | V17: 575 | W17: 578 | X17: 535 | Y17: 516 | Z17: 494 | AA17: 498 | AB17: 467 | AC17: 453 | AD17: 448 | AE17: 457 | AF17: 478 | AG17: 488 | AH17: 507 | AI17: 529 | AJ17: 534 | AK17: 550 | AL17: 559 | AM17: 556 | AN17: 547 | AO17: 555 | AP17: 548 | AQ17: 553 | AR17: 551 | AS17: 553 | AT17: 569 | AU17: 562 | AV17: 578 | AW17: 581 | AX17: 589 | AY17: 611 | AZ17: 634 | BA17: 637 | BB17: 638 | BC17: 660 | BD17: 664 | BE17: 675 | BF17: 681 | BG17: 680 | BH17: 682
A18: OCCITANIE | B18: 617 | C18: 592 | D18: 548 | E18: 520 | F18: 494 | G18: 491 | H18: 471 | I18: 478 | J18: 472 | K18: 462 | L18: 469 | M18: 485 | N18: 469 | O18: 468 | P18: 465 | Q18: 486 | R18: 508 | S18: 540 | T18: 574 | U18: 571 | V18: 564 | W18: 530 | X18: 494 | Y18: 459 | Z18: 442 | AA18: 428 | AB18: 393 | AC18: 391 | AD18: 399 | AE18: 396 | AF18: 404 | AG18: 418 | AH18: 441 | AI18: 457 | AJ18: 468 | AK18: 485 | AL18: 485 | AM18: 491 | AN18: 496 | AO18: 488 | AP18: 486 | AQ18: 498 | AR18: 502 | AS18: 503 | AT18: 511 | AU18: 504 | AV18: 504 | AW18: 518 | AX18: 518 | AY18: 519 | AZ18: 528 | BA18: 549 | BB18: 552 | BC18: 566 | BD18: 556 | BE18: 566 | BF18: 570 | BG18: 580 | BH18: 579
A19: PAYS DE LA LOIRE | B19: 307 | C19: 307 | D19: 299 | E19: 284 | F19: 261 | G19: 244 | H19: 235 | I19: 222 | J19: 226 | K19: 218 | L19: 235 | M19: 239 | N19: 240 | O19: 239 | P19: 246 | Q19: 243 | R19: 247 | S19: 255 | T19: 269 | U19: 272 | V19: 269 | W19: 266 | X19: 255 | Y19: 251 | Z19: 244 | AA19: 240 | AB19: 234 | AC19: 231 | AD19: 231 | AE19: 237 | AF19: 265 | AG19: 266 | AH19: 264 | AI19: 274 | AJ19: 291 | AK19: 293 | AL19: 295 | AM19: 303 | AN19: 285 | AO19: 282 | AP19: 284 | AQ19: 293 | AR19: 299 | AS19: 314 | AT19: 310 | AU19: 310 | AV19: 308 | AW19: 308 | AX19: 314 | AY19: 325 | AZ19: 325 | BA19: 327 | BB19: 327 | BC19: 332 | BD19: 342 | BE19: 345 | BF19: 347 | BG19: 346 | BH19: 359
... A21: TOTAL | B21: 5157 | C21: 4916 | D21: 4678 | E21: 4475 | F21: 4274 | G21: 4168 | H21: 4147 | I21: 4228 | J21: 4218 | K21: 4269 | L21: 4379 | M21: 4410 | N21: 4426 | O21: 4484 | P21: 4500 | Q21: 4695 | R21: 4835 | S21: 5050 | T21: 5320 | U21: 5369 | V21: 5337 | W21: 5201 | X21: 4966 | Y21: 4761 | Z21: 4590 | AA21: 4490 | AB21: 4297 | AC21: 4272 | AD21: 4291 | AE21: 4377 | AF21: 4520 | AG21: 4644 | AH21: 4763 | AI21: 4985 | AJ21: 5113 | AK21: 5197 | AL21: 5249 | AM21: 5275 | AN21: 5273 | AO21: 5275 | AP21: 5283 | AQ21: 5317 | AR21: 5396 | AS21: 5478 | AT21: 5468 | AU21: 5468 | AV21: 5508 | AW21: 5589 | AX21: 5647 | AY21: 5741 | AZ21: 5842 | BA21: 5913 | BB21: 5983 | BC21: 6114 | BD21: 6127 | BE21: 6192 | BF21: 6298 | BG21: 6327 | BH21: 6355

Sheet fauteuils
A2: Retour au menu "Régions"
A5: Fauteuils par région
B7: 1966 | C7: 1967 | D7: 1968 | E7: 1969 | F7: 1970 | G7: 1971 | H7: 1972 | I7: 1973 | J7: 1974 | K7: 1975 | L7: 1976 | M7: 1977 | N7: 1978 | O7: 1979 | P7: 1980 | Q7: 1981 | R7: 1982 | S7: 1983 | T7: 1984 | U7: 1985 | V7: 1986 | W7: 1987 | X7: 1988 | Y7: 1989 | Z7: 1990 | AA7: 1991 | AB7: 1992 | AC7: 1993 | AD7: 1994 | AE7: 1995 | AF7: 1996 | AG7: 1997 | AH7: 1998 | AI7: 1999 | AJ7: 2000 | AK7: 2001 | AL7: 2002 | AM7: 2003 | AN7: 2004 | AO7: 2005 | AP7: 2006 | AQ7: 2007 | AR7: 2008 | AS7: 2009 | AT7: 2010 | AU7: 2011 | AV7: 2012 | AW7: 2013 | AX7: 2014 | AY7: 2015 | AZ7: 2016 | BA7: 2017 | BB7: 2018 | BC7: 2019 | BD7: 2020 | BE7: 2021 | BF7: 2022 | BG7: 2023 | BH7: 2024
A8: AUVERGNE-RHONE-ALPES | B8: 252759 | C8: 244198 | D8: 237316 | E8: 232259 | F8: 220107 | G8: 207457 | H8: 199148 | I8: 197696 | J8: 194290 | K8: 194004 | L8: 185883 | M8: 178148 | N8: 169086 | O8: 162140 | P8: 159098 | Q8: 159281 | R8: 163698 | S8: 164113 | T8: 163647 | U8: 161368 | V8: 157166 | W8: 150376 | X8: 144649 | Y8: 139992 | Z8: 134699 | AA8: 131002 | AB8: 122219 | AC8: 120906 | AD8: 119541 | AE8: 121694 | AF8: 115060 | AG8: 123633 | AH8: 121874 | AI8: 123578 | AJ8: 133234 | AK8: 136517 | AL8: 137481 | AM8: 136981 | AN8: 131679 | AO8: 126989 | AP8: 131042 | AQ8: 132149 | AR8: 135117 | AS8: 138124 | AT8: 136512 | AU8: 137796 | AV8: 140756 | AW8: 139280 | AX8: 138815 | AY8: 140718 | AZ8: 141183 | BA8: 145660 | BB8: 145523 | BC8: 144645 | BD8: 144025 | BE8: 144296 | BF8: 146365 | BG8: 147116 | BH8: 145885
A9: BOURGOGNE-FRANCHE-COMTE | B9: 105681 | C9: 100547 | D9: 97213 | E9: 93126 | F9: 92150 | G9: 88840 | H9: 89972 | I9: 85494 | J9: 83116 | K9: 81105 | L9: 79192 | M9: 74900 | N9: 71477 | O9: 68724 | P9: 66552 | Q9: 67640 | R9: 67599 | S9: 68190 | T9: 67659 | U9: 65821 | V9: 64881 | W9: 60213 | X9: 56026 | Y9: 53205 | Z9: 50649 | AA9: 48300 | AB9: 43434 | AC9: 43016 | AD9: 42329 | AE9: 42845 | AF9: 39961 | AG9: 39742 | AH9: 39413 | AI9: 43156 | AJ9: 45585 | AK9: 44718 | AL9: 47696 | AM9: 44920 | AN9: 44651 | AO9: 46466 | AP9: 43689 | AQ9: 44900 | AR9: 45505 | AS9: 45505 | AT9: 44756 | AU9: 45560 | AV9: 45799 | AW9: 47136 | AX9: 45130 | AY9: 46931 | AZ9: 46006 | BA9: 46160 | BB9: 47857 | BC9: 48107 | BD9: 47933 | BE9: 46418 | BF9: 47722 | BG9: 48081 | BH9: 47131
A10: BRETAGNE | B10: 104157 | C10: 102237 | D10: 97493 | E10: 97085 | F10: 96149 | G10: 89585 | H10: 87683 | I10: 87302 | J10: 86159 | K10: 86280 | L10: 81789 | M10: 80588 | N10: 77936 | O10: 76601 | P10: 74656 | Q10: 71051 | R10: 72748 | S10: 70935 | T10: 71176 | U10: 64632 | V10: 68888 | W10: 63620 | X10: 61521 | Y10: 58075 | Z10: 54383 | AA10: 53513 | AB10: 50768 | AC10: 50429 | AD10: 51069 | AE10: 51064 | AF10: 51249 | AG10: 50372 | AH10: 50365 | AI10: 55031 | AJ10: 54528 | AK10: 54528 | AL10: 51410 | AM10: 53294 | AN10: 54676 | AO10: 55762 | AP10: 54264 | AQ10: 54377 | AR10: 56801 | AS10: 56587 | AT10: 55876 | AU10: 56528 | AV10: 56678 | AW10: 56545 | AX10: 56757 | AY10: 57670 | AZ10: 57979 | BA10: 57635 | BB10: 58228 | BC10: 60887 | BD10: 60743 | BE10: 59722 | BF10: 60466 | BG10: 60585 | BH10: 60644
A11: CENTRE-VAL DE LOIRE | B11: 74674 | C11: 71278 | D11: 70768 | E11: 69226 | F11: 66585 | G11: 64308 | H11: 63730 | I11: 62010 | J11: 59100 | K11: 57819 | L11: 57342 | M11: 56380 | N11: 55842 | O11: 53417 | P11: 54116 | Q11: 49305 | R11: 45573 | S11: 47429 | T11: 47405 | U11: 47049 | V11: 43667 | W11: 40460 | X11: 40570 | Y11: 38595 | Z11: 34869 | AA11: 32656 | AB11: 30498 | AC11: 30498 | AD11: 30485 | AE11: 30879 | AF11: 31906 | AG11: 30599 | AH11: 33570 | AI11: 30920 | AJ11: 33261 | AK11: 32801 | AL11: 32847 | AM11: 34360 | AN11: 30983 | AO11: 31873 | AP11: 32246 | AQ11: 32215 | AR11: 37953 | AS11: 36732 | AT11: 37235 | AU11: 37414 | AV11: 37414 | AW11: 37801 | AX11: 37333 | AY11: 37653 | AZ11: 37847 | BA11: 37284 | BB11: 39295 | BC11: 39603 | BD11: 39497 | BE11: 40747 | BF11: 40742 | BG11: 41099 | BH11: 40651
A12: CORSE | B12: 6661 | C12: 6667 | D12: 7002 | E12: 7002 | F12: 7012 | G12: 6958 | H12: 7906 | I12: 7211 | J12: 7211 | K12: 7298 | L12: 7925 | M12: 8118 | N12: 8028 | O12: 8478 | P12: 7814 | Q12: 8487 | R12: 9207 | S12: 9886 | T12: 9418 | U12: 9467 | V12: 9867 | W12: 9982 | X12: 9535 | Y12: 9305 | Z12: 9225 | AA12: 9625 | AB12: 8352 | AC12: 8252 | AD12: 8050 | AE12: 8344 | AF12: 7666 | AG12: 7840 | AH12: 7840 | AI12: 7666 | AJ12: 7369 | AK12: 6619 | AL12: 7192 | AM12: 6892 | AN12: 7316 | AO12: 6497 | AP12: 6497 | AQ12: 6497 | AR12: 6725 | AS12: 7023 | AT12: 7023 | AU12: 6952 | AV12: 6208 | AW12: 6140 | AX12: 7587 | AY12: 7915 | AZ12: 8012 | BA12: 7276 | BB12: 6682 | BC12: 7301 | BD12: 6137 | BE12: 6682 | BF12: 6987 | BG12: 7384 | BH12: 7085
A13: GRAND EST | B13: 250941 | C13: 239578 | D13: 232074 | E13: 217185 | F13: 199334 | G13: 184742 | H13: 171694 | I13: 165021 | J13: 158698 | K13: 152137 | L13: 147035 | M13: 136245 | N13: 126938 | O13: 122264 | P13: 117541 | Q13: 113894 | R13: 109296 | S13: 110339 | T13: 109695 | U13: 107426 | V13: 98727 | W13: 88932 | X13: 82457 | Y13: 79269 | Z13: 75010 | AA13: 72271 | AB13: 66754 | AC13: 61048 | AD13: 61402 | AE13: 66324 | AF13: 64651 | AG13: 66004 | AH13: 65812 | AI13: 76050 | AJ13: 83885 | AK13: 82317 | AL13: 82657 | AM13: 83180 | AN13: 82495 | AO13: 83859 | AP13: 85450 | AQ13: 85474 | AR13: 84856 | AS13: 85337 | AT13: 85045 | AU13: 86404 | AV13: 87458 | AW13: 87267 | AX13: 88003 | AY13: 88673 | AZ13: 89319 | BA13: 89646 | BB13: 88182 | BC13: 88088 | BD13: 88239 | BE13: 89823 | BF13: 91735 | BG13: 91926 | BH13: 91003
A14: HAUTS-DE-FRANCE | B14: 316575 | C14: 289194 | D14: 260535 | E14: 243074 | F14: 227105 | G14: 213904 | H14: 205049 | I14: 197109 | J14: 190566 | K14: 185797 | L14: 177972 | M14: 159229 | N14: 144595 | O14: 131547 | P14: 120609 | Q14: 108377 | R14: 100871 | S14: 97916 | T14: 99314 | U14: 96276 | V14: 89807 | W14: 89467 | X14: 80723 | Y14: 76756 | Z14: 69931 | AA14: 67346 | AB14: 67500 | AC14: 67310 | AD14: 67410 | AE14: 68814 | AF14: 79512 | AG14: 77906 | AH14: 77229 | AI14: 82914 | AJ14: 85237 | AK14: 85848 | AL14: 85327 | AM14: 83742 | AN14: 82878 | AO14: 79007 | AP14: 79210 | AQ14: 79319 | AR14: 79472 | AS14: 80882 | AT14: 79089 | AU14: 79727 | AV14: 78775 | AW14: 80330 | AX14: 81867 | AY14: 83890 | AZ14: 84170 | BA14: 85488 | BB14: 84174 | BC14: 85040 | BD14: 85773 | BE14: 85806 | BF14: 86566 | BG14: 86288 | BH14: 85216
A15: ILE-DE-FRANCE | B15: 421603 | C15: 392675 | D15: 382227 | E15: 365283 | F15: 351743 | G15: 332926 | H15: 319185 | I15: 310334 | J15: 301870 | K15: 292290 | L15: 274066 | M15: 258107 | N15: 247852 | O15: 244673 | P15: 233346 | Q15: 231151 | R15: 223690 | S15: 224257 | T15: 221700 | U15: 217968 | V15: 211337 | W15: 202314 | X15: 197381 | Y15: 189089 | Z15: 184365 | AA15: 181468 | AB15: 178963 | AC15: 175227 | AD15: 173319 | AE15: 172324 | AF15: 175463 | AG15: 178820 | AH15: 187708 | AI15: 190288 | AJ15: 187324 | AK15: 194197 | AL15: 202833 | AM15: 204390 | AN15: 209508 | AO15: 203580 | AP15: 202174 | AQ15: 200495 | AR15: 202343 | AS15: 204042 | AT15: 203630 | AU15: 203618 | AV15: 205414 | AW15: 212729 | AX15: 214842 | AY15: 214566 | AZ15: 221675 | BA15: 224123 | BB15: 227207 | BC15: 233359 | BD15: 230713 | BE15: 226749 | BF15: 229838 | BG15: 228385 | BH15: 223897
A16: NORMANDIE | B16: 129003 | C16: 126281 | D16: 124011 | E16: 116689 | F16: 110839 | G16: 108064 | H16: 102693 | I16: 98299 | J16: 95424 | K16: 93838 | L16: 93300 | M16: 88181 | N16: 83812 | O16: 84114 | P16: 77537 | Q16: 73921 | R16: 72911 | S16: 72110 | T16: 72219 | U16: 71378 | V16: 69543 | W16: 65708 | X16: 59274 | Y16: 55520 | Z16: 55367 | AA16: 53678 | AB16: 51726 | AC16: 50121 | AD16: 49558 | AE16: 50874 | AF16: 49605 | AG16: 49321 | AH16: 50801 | AI16: 57268 | AJ16: 59930 | AK16: 58368 | AL16: 58700 | AM16: 59016 | AN16: 59824 | AO16: 55417 | AP16: 55475 | AQ16: 55317 | AR16: 55517 | AS16: 61972 | AT16: 58603 | AU16: 58646 | AV16: 58199 | AW16: 57764 | AX16: 58014 | AY16: 58181 | AZ16: 57249 | BA16: 58950 | BB16: 59254 | BC16: 59448 | BD16: 59512 | BE16: 58507 | BF16: 59387 | BG16: 59120 | BH16: 58951
A17: NOUVELLE AQUITAINE | B17: 229946 | C17: 222368 | D17: 211250 | E17: 204343 | F17: 196909 | G17: 191310 | H17: 185603 | I17: 182815 | J17: 176127 | K17: 168397 | L17: 158913 | M17: 158637 | N17: 153450 | O17: 149540 | P17: 145334 | Q17: 140366 | R17: 138064 | S17: 138190 | T17: 140159 | U17: 135368 | V17: 132185 | W17: 130667 | X17: 119247 | Y17: 112630 | Z17: 107236 | AA17: 108697 | AB17: 100965 | AC17: 97221 | AD17: 96253 | AE17: 97127 | AF17: 98015 | AG17: 98271 | AH17: 100301 | AI17: 103538 | AJ17: 104500 | AK17: 107796 | AL17: 110106 | AM17: 109683 | AN17: 106909 | AO17: 104391 | AP17: 103355 | AQ17: 103226 | AR17: 103828 | AS17: 104369 | AT17: 106272 | AU17: 104705 | AV17: 106869 | AW17: 106719 | AX17: 107647 | AY17: 111410 | AZ17: 114567 | BA17: 115061 | BB17: 114925 | BC17: 117133 | BD17: 116785 | BE17: 117924 | BF17: 118216 | BG17: 117809 | BH17: 118083
A18: OCCITANIE | B18: 250675 | C18: 243371 | D18: 231492 | E18: 223342 | F18: 211438 | G18: 207807 | H18: 197954 | I18: 193657 | J18: 189617 | K18: 181604 | L18: 176527 | M18: 174090 | N18: 164699 | O18: 159067 | P18: 152100 | Q18: 148117 | R18: 144664 | S18: 142487 | T18: 143417 | U18: 139402 | V18: 134982 | W18: 123871 | X18: 115232 | Y18: 104713 | Z18: 97781 | AA18: 93295 | AB18: 81551 | AC18: 80084 | AD18: 81183 | AE18: 80133 | AF18: 78872 | AG18: 79569 | AH18: 84498 | AI18: 85766 | AJ18: 86851 | AK18: 89202 | AL18: 89530 | AM18: 90918 | AN18: 91055 | AO18: 86766 | AP18: 86399 | AQ18: 89282 | AR18: 89645 | AS18: 89966 | AT18: 91368 | AU18: 89643 | AV18: 90304 | AW18: 92142 | AX18: 91759 | AY18: 91016 | AZ18: 92963 | BA18: 95441 | BB18: 96166 | BC18: 97701 | BD18: 95216 | BE18: 96167 | BF18: 96932 | BG18: 97909 | BH18: 97498
A19: PAYS DE LA LOIRE | B19: 129435 | C19: 128727 | D19: 126057 | E19: 120749 | F19: 112569 | G19: 105285 | H19: 101798 | I19: 95806 | J19: 95687 | K19: 91906 | L19: 91100 | M19: 88031 | N19: 84590 | O19: 81029 | P19: 80558 | Q19: 77604 | R19: 75500 | S19: 76086 | T19: 75326 | U19: 72290 | V19: 70281 | W19: 68087 | X19: 63899 | Y19: 60920 | Z19: 58860 | AA19: 57921 | AB19: 55716 | AC19: 54091 | AD19: 53496 | AE19: 54540 | AF19: 57896 | AG19: 58138 | AH19: 56785 | AI19: 57501 | AJ19: 61296 | AK19: 62210 | AL19: 63042 | AM19: 63563 | AN19: 59716 | AO19: 56123 | AP19: 56232 | AQ19: 58070 | AR19: 58145 | AS19: 60400 | AT19: 59220 | AU19: 59220 | AV19: 58769 | AW19: 59156 | AX19: 59350 | AY19: 60802 | AZ19: 60985 | BA19: 60820 | BB19: 60819 | BC19: 61536 | BD19: 62986 | BE19: 62068 | BF19: 62386 | BG19: 61962 | BH19: 62987
... A21: TOTAL | B21: 2482883 | C21: 2364691 | D21: 2269674 | E21: 2176484 | F21: 2071815 | G21: 1974647 | H21: 1902292 | I21: 1844213 | J21: 1795087 | K21: 1744409 | L21: 1676801 | M21: 1600066 | N21: 1522792 | O21: 1472389 | P21: 1408834 | Q21: 1363090 | R21: 1336310 | S21: 1335041 | T21: 1335013 | U21: 1298928 | V21: 1259594 | W21: 1194229 | X21: 1124147 | Y21: 1065039 | Z21: 1016298 | AA21: 989613 | AB21: 931206 | AC21: 916642 | AD21: 908619 | AE21: 921975 | AF21: 920177 | AG21: 938179 | AH21: 956746 | AI21: 993307 | AJ21: 1020102 | AK21: 1030938 | AL21: 1044298 | AM21: 1047703 | AN21: 1038608 | AO21: 1009515 | AP21: 1008887 | AQ21: 1012600 | AR21: 1026237 | AS21: 1043468 | AT21: 1038960 | AU21: 1038632 | AV21: 1045783 | AW21: 1059685 | AX21: 1065535 | AY21: 1081588 | AZ21: 1098281 | BA21: 1106167 | BB21: 1113563 | BC21: 1128422 | BD21: 1121514 | BE21: 1123669 | BF21: 1136960 | BG21: 1136752 | BH21: 1128689

Sheet multiplexes
A2: Retour au menu "Régions"
A5: Multiplexes (8 écrans et plus) par région
B7: 1966 | C7: 1967 | D7: 1968 | E7: 1969 | F7: 1970 | G7: 1971 | H7: 1972 | I7: 1973 | J7: 1974 | K7: 1975 | L7: 1976 | M7: 1977 | N7: 1978 | O7: 1979 | P7: 1980 | Q7: 1981 | R7: 1982 | S7: 1983 | T7: 1984 | U7: 1985 | V7: 1986 | W7: 1987 | X7: 1988 | Y7: 1989 | Z7: 1990 | AA7: 1991 | AB7: 1992 | AC7: 1993 | AD7: 1994 | AE7: 1995 | AF7: 1996 | AG7: 1997 | AH7: 1998 | AI7: 1999 | AJ7: 2000 | AK7: 2001 | AL7: 2002 | AM7: 2003 | AN7: 2004 | AO7: 2005 | AP7: 2006 | AQ7: 2007 | AR7: 2008 | AS7: 2009 | AT7: 2010 | AU7: 2011 | AV7: 2012 | AW7: 2013 | AX7: 2014 | AY7: 2015 | AZ7: 2016 | BA7: 2017 | BB7: 2018 | BC7: 2019 | BD7: 2020 | BE7: 2021 | BF7: 2022 | BG7: 2023 | BH7: 2024
A8: AUVERGNE-RHONE-ALPES | AB8: 4 | AC8: 4 | AD8: 4 | AE8: 4 | AF8: 4 | AG8: 7 | AH8: 7 | AI8: 7 | AJ8: 11 | AK8: 13 | AL8: 15 | AM8: 15 | AN8: 15 | AO8: 15 | AP8: 16 | AQ8: 17 | AR8: 19 | AS8: 19 | AT8: 19 | AU8: 21 | AV8: 23 | AW8: 23 | AX8: 23 | AY8: 25 | AZ8: 25 | BA8: 28 | BB8: 28 | BC8: 28 | BD8: 28 | BE8: 28 | BF8: 29 | BG8: 30 | BH8: 30
A9: BOURGOGNE-FRANCHE-COMTE | AB9: 0 | AC9: 0 | AD9: 0 | AE9: 1 | AF9: 1 | AG9: 1 | AH9: 1 | AI9: 3 | AJ9: 4 | AK9: 4 | AL9: 5 | AM9: 6 | AN9: 6 | AO9: 8 | AP9: 8 | AQ9: 9 | AR9: 9 | AS9: 9 | AT9: 9 | AU9: 9 | AV9: 9 | AW9: 10 | AX9: 10 | AY9: 10 | AZ9: 10 | BA9: 10 | BB9: 11 | BC9: 11 | BD9: 11 | BE9: 11 | BF9: 12 | BG9: 12 | BH9: 12
A10: BRETAGNE | AB10: 2 | AC10: 2 | AD10: 2 | AE10: 2 | AF10: 2 | AG10: 2 | AH10: 2 | AI10: 4 | AJ10: 4 | AK10: 4 | AL10: 4 | AM10: 5 | AN10: 6 | AO10: 7 | AP10: 7 | AQ10: 7 | AR10: 7 | AS10: 7 | AT10: 7 | AU10: 7 | AV10: 8 | AW10: 8 | AX10: 8 | AY10: 9 | AZ10: 9 | BA10: 9 | BB10: 9 | BC10: 9 | BD10: 10 | BE10: 10 | BF10: 10 | BG10: 10 | BH10: 10
A11: CENTRE-VAL DE LOIRE | AB11: 0 | AC11: 0 | AD11: 0 | AE11: 1 | AF11: 2 | AG11: 2 | AH11: 3 | AI11: 3 | AJ11: 5 | AK11: 5 | AL11: 5 | AM11: 6 | AN11: 6 | AO11: 6 | AP11: 6 | AQ11: 6 | AR11: 10 | AS11: 10 | AT11: 10 | AU11: 10 | AV11: 10 | AW11: 10 | AX11: 10 | AY11: 10 | AZ11: 10 | BA11: 10 | BB11: 11 | BC11: 11 | BD11: 11 | BE11: 11 | BF11: 11 | BG11: 11 | BH11: 11
